INFO 2018-12-27 10:18:02,781 basehttp 124 "GET / HTTP/1.1" 200 1714
WARNING 2018-12-27 10:18:05,540 base 152 Not Found: /favicon.ico
WARNING 2018-12-27 10:18:05,545 basehttp 124 "GET /favicon.ico HTTP/1.1" 404 1967
WARNING 2018-12-27 19:54:37,002 base 152 Not Found: /sms_codes/
WARNING 2018-12-27 19:54:37,046 basehttp 124 "GET /sms_codes/?177775309063 HTTP/1.1" 404 2167
WARNING 2018-12-27 19:56:42,261 base 152 Not Found: /sms_codes/
WARNING 2018-12-27 19:56:42,265 basehttp 124 "GET /sms_codes/?177775309063 HTTP/1.1" 404 2079
WARNING 2018-12-27 19:59:33,236 base 152 Not Found: /sms_codes/177775309063/
WARNING 2018-12-27 19:59:33,239 basehttp 124 "GET /sms_codes/177775309063/ HTTP/1.1" 404 2105
WARNING 2018-12-27 20:00:50,285 base 152 Not Found: /sms_codes/177775309063/
WARNING 2018-12-27 20:00:50,288 basehttp 124 "GET /sms_codes/177775309063/ HTTP/1.1" 404 2105
WARNING 2018-12-27 20:02:10,983 base 152 Not Found: /sms_codes/177775309063/
WARNING 2018-12-27 20:02:10,993 basehttp 124 "GET /sms_codes/177775309063/ HTTP/1.1" 404 2193
WARNING 2018-12-27 20:03:24,685 base 152 Not Found: /sms_codes/177775309063/
WARNING 2018-12-27 20:03:24,687 basehttp 124 "GET /sms_codes/177775309063/ HTTP/1.1" 404 2193
WARNING 2018-12-27 20:03:57,076 base 152 Not Found: /sms_codes/177775309063/
WARNING 2018-12-27 20:03:57,079 basehttp 124 "GET /sms_codes/177775309063/ HTTP/1.1" 404 2086
WARNING 2018-12-27 20:11:56,770 base 152 Not Found: /sms_codes/177775309063/
WARNING 2018-12-27 20:11:56,772 basehttp 124 "GET /sms_codes/177775309063/ HTTP/1.1" 404 2193
WARNING 2018-12-27 20:15:54,874 base 152 Not Found: /sms_codes/177775309063/
WARNING 2018-12-27 20:15:54,892 basehttp 124 "GET /sms_codes/177775309063/ HTTP/1.1" 404 2193
WARNING 2018-12-27 20:16:19,687 base 152 Not Found: /sms_codes/177775309063/
WARNING 2018-12-27 20:16:19,689 basehttp 124 "GET /sms_codes/177775309063/ HTTP/1.1" 404 2192
WARNING 2018-12-27 20:16:48,660 base 152 Not Found: /sms_codes/177775309063/
WARNING 2018-12-27 20:16:48,663 basehttp 124 "GET /sms_codes/177775309063/ HTTP/1.1" 404 2191
WARNING 2018-12-27 20:16:49,900 base 152 Not Found: /sms_codes/177775309063/
WARNING 2018-12-27 20:16:49,900 basehttp 124 "GET /sms_codes/177775309063/ HTTP/1.1" 404 2191
WARNING 2018-12-27 20:17:27,923 base 152 Not Found: /sms_codes/177775309063/
WARNING 2018-12-27 20:17:27,924 basehttp 124 "GET /sms_codes/177775309063/ HTTP/1.1" 404 2192
ERROR 2018-12-27 20:17:57,058 exception 135 Internal Server Error: /sms_codes/17777530903/
Traceback (most recent call last):
  File "/home/python/.virtualenvs/django_py3_11/lib/python3.5/site-packages/rest_framework/views.py", line 480, in dispatch
    response = handler(request, *args, **kwargs)
  File "/home/python/Desktop/meiduo_test1/meiduo_test/meiduo_test/apps/verifications/views.py", line 33, in get
    redis_conn = get_redis_connection("verify_codes")  # StrictRedis 对象
  File "/home/python/.virtualenvs/django_py3_11/lib/python3.5/site-packages/django_redis/__init__.py", line 14, in get_redis_connection
    cache = caches[alias]
  File "/home/python/.virtualenvs/django_py3_11/lib/python3.5/site-packages/django/core/cache/__init__.py", line 77, in __getitem__
    "Could not find config for '%s' in settings.CACHES" % alias
django.core.cache.backends.base.InvalidCacheBackendError: Could not find config for 'verify_codes' in settings.CACHES

During handling of the above exception, another exception occurred:

Traceback (most recent call last):
  File "/home/python/.virtualenvs/django_py3_11/lib/python3.5/site-packages/rest_framework/settings.py", line 183, in import_from_string
    module = import_module(module_path)
  File "/home/python/.virtualenvs/django_py3_11/lib/python3.5/importlib/__init__.py", line 126, in import_module
    return _bootstrap._gcd_import(name[level:], package, level)
  File "<frozen importlib._bootstrap>", line 986, in _gcd_import
  File "<frozen importlib._bootstrap>", line 969, in _find_and_load
  File "<frozen importlib._bootstrap>", line 944, in _find_and_load_unlocked
  File "<frozen importlib._bootstrap>", line 222, in _call_with_frames_removed
  File "<frozen importlib._bootstrap>", line 986, in _gcd_import
  File "<frozen importlib._bootstrap>", line 969, in _find_and_load
  File "<frozen importlib._bootstrap>", line 944, in _find_and_load_unlocked
  File "<frozen importlib._bootstrap>", line 222, in _call_with_frames_removed
  File "<frozen importlib._bootstrap>", line 986, in _gcd_import
  File "<frozen importlib._bootstrap>", line 969, in _find_and_load
  File "<frozen importlib._bootstrap>", line 956, in _find_and_load_unlocked
ImportError: No module named 'meiduo_mall'

During handling of the above exception, another exception occurred:

Traceback (most recent call last):
  File "/home/python/.virtualenvs/django_py3_11/lib/python3.5/site-packages/django/core/handlers/exception.py", line 41, in inner
    response = get_response(request)
  File "/home/python/.virtualenvs/django_py3_11/lib/python3.5/site-packages/django/core/handlers/base.py", line 187, in _get_response
    response = self.process_exception_by_middleware(e, request)
  File "/home/python/.virtualenvs/django_py3_11/lib/python3.5/site-packages/django/core/handlers/base.py", line 185, in _get_response
    response = wrapped_callback(request, *callback_args, **callback_kwargs)
  File "/home/python/.virtualenvs/django_py3_11/lib/python3.5/site-packages/django/views/decorators/csrf.py", line 58, in wrapped_view
    return view_func(*args, **kwargs)
  File "/home/python/.virtualenvs/django_py3_11/lib/python3.5/site-packages/django/views/generic/base.py", line 68, in view
    return self.dispatch(request, *args, **kwargs)
  File "/home/python/.virtualenvs/django_py3_11/lib/python3.5/site-packages/rest_framework/views.py", line 483, in dispatch
    response = self.handle_exception(exc)
  File "/home/python/.virtualenvs/django_py3_11/lib/python3.5/site-packages/rest_framework/views.py", line 437, in handle_exception
    exception_handler = self.get_exception_handler()
  File "/home/python/.virtualenvs/django_py3_11/lib/python3.5/site-packages/rest_framework/views.py", line 288, in get_exception_handler
    return self.settings.EXCEPTION_HANDLER
  File "/home/python/.virtualenvs/django_py3_11/lib/python3.5/site-packages/rest_framework/settings.py", line 227, in __getattr__
    val = perform_import(val, attr)
  File "/home/python/.virtualenvs/django_py3_11/lib/python3.5/site-packages/rest_framework/settings.py", line 170, in perform_import
    return import_from_string(val, setting_name)
  File "/home/python/.virtualenvs/django_py3_11/lib/python3.5/site-packages/rest_framework/settings.py", line 187, in import_from_string
    raise ImportError(msg)
ImportError: Could not import 'meiduo_mall.utils.exceptions.exception_handler' for API setting 'EXCEPTION_HANDLER'. ImportError: No module named 'meiduo_mall'.
ERROR 2018-12-27 20:17:57,749 basehttp 124 "GET /sms_codes/17777530903/ HTTP/1.1" 500 128353
WARNING 2018-12-27 20:18:07,467 base 152 Not Found: /sms_codes/1777530903/
WARNING 2018-12-27 20:18:07,471 basehttp 124 "GET /sms_codes/1777530903/ HTTP/1.1" 404 2186
WARNING 2018-12-27 20:18:16,139 base 152 Not Found: /sms_codes/1777530903/
WARNING 2018-12-27 20:18:16,140 basehttp 124 "GET /sms_codes/1777530903/ HTTP/1.1" 404 2186
ERROR 2018-12-27 20:18:27,268 exception 135 Internal Server Error: /sms_codes/17775309063/
Traceback (most recent call last):
  File "/home/python/.virtualenvs/django_py3_11/lib/python3.5/site-packages/rest_framework/views.py", line 480, in dispatch
    response = handler(request, *args, **kwargs)
  File "/home/python/Desktop/meiduo_test1/meiduo_test/meiduo_test/apps/verifications/views.py", line 33, in get
    redis_conn = get_redis_connection("verify_codes")  # StrictRedis 对象
  File "/home/python/.virtualenvs/django_py3_11/lib/python3.5/site-packages/django_redis/__init__.py", line 14, in get_redis_connection
    cache = caches[alias]
  File "/home/python/.virtualenvs/django_py3_11/lib/python3.5/site-packages/django/core/cache/__init__.py", line 77, in __getitem__
    "Could not find config for '%s' in settings.CACHES" % alias
django.core.cache.backends.base.InvalidCacheBackendError: Could not find config for 'verify_codes' in settings.CACHES

During handling of the above exception, another exception occurred:

Traceback (most recent call last):
  File "/home/python/.virtualenvs/django_py3_11/lib/python3.5/site-packages/rest_framework/settings.py", line 183, in import_from_string
    module = import_module(module_path)
  File "/home/python/.virtualenvs/django_py3_11/lib/python3.5/importlib/__init__.py", line 126, in import_module
    return _bootstrap._gcd_import(name[level:], package, level)
  File "<frozen importlib._bootstrap>", line 986, in _gcd_import
  File "<frozen importlib._bootstrap>", line 969, in _find_and_load
  File "<frozen importlib._bootstrap>", line 944, in _find_and_load_unlocked
  File "<frozen importlib._bootstrap>", line 222, in _call_with_frames_removed
  File "<frozen importlib._bootstrap>", line 986, in _gcd_import
  File "<frozen importlib._bootstrap>", line 969, in _find_and_load
  File "<frozen importlib._bootstrap>", line 944, in _find_and_load_unlocked
  File "<frozen importlib._bootstrap>", line 222, in _call_with_frames_removed
  File "<frozen importlib._bootstrap>", line 986, in _gcd_import
  File "<frozen importlib._bootstrap>", line 969, in _find_and_load
  File "<frozen importlib._bootstrap>", line 956, in _find_and_load_unlocked
ImportError: No module named 'meiduo_mall'

During handling of the above exception, another exception occurred:

Traceback (most recent call last):
  File "/home/python/.virtualenvs/django_py3_11/lib/python3.5/site-packages/django/core/handlers/exception.py", line 41, in inner
    response = get_response(request)
  File "/home/python/.virtualenvs/django_py3_11/lib/python3.5/site-packages/django/core/handlers/base.py", line 187, in _get_response
    response = self.process_exception_by_middleware(e, request)
  File "/home/python/.virtualenvs/django_py3_11/lib/python3.5/site-packages/django/core/handlers/base.py", line 185, in _get_response
    response = wrapped_callback(request, *callback_args, **callback_kwargs)
  File "/home/python/.virtualenvs/django_py3_11/lib/python3.5/site-packages/django/views/decorators/csrf.py", line 58, in wrapped_view
    return view_func(*args, **kwargs)
  File "/home/python/.virtualenvs/django_py3_11/lib/python3.5/site-packages/django/views/generic/base.py", line 68, in view
    return self.dispatch(request, *args, **kwargs)
  File "/home/python/.virtualenvs/django_py3_11/lib/python3.5/site-packages/rest_framework/views.py", line 483, in dispatch
    response = self.handle_exception(exc)
  File "/home/python/.virtualenvs/django_py3_11/lib/python3.5/site-packages/rest_framework/views.py", line 437, in handle_exception
    exception_handler = self.get_exception_handler()
  File "/home/python/.virtualenvs/django_py3_11/lib/python3.5/site-packages/rest_framework/views.py", line 288, in get_exception_handler
    return self.settings.EXCEPTION_HANDLER
  File "/home/python/.virtualenvs/django_py3_11/lib/python3.5/site-packages/rest_framework/settings.py", line 227, in __getattr__
    val = perform_import(val, attr)
  File "/home/python/.virtualenvs/django_py3_11/lib/python3.5/site-packages/rest_framework/settings.py", line 170, in perform_import
    return import_from_string(val, setting_name)
  File "/home/python/.virtualenvs/django_py3_11/lib/python3.5/site-packages/rest_framework/settings.py", line 187, in import_from_string
    raise ImportError(msg)
ImportError: Could not import 'meiduo_mall.utils.exceptions.exception_handler' for API setting 'EXCEPTION_HANDLER'. ImportError: No module named 'meiduo_mall'.
ERROR 2018-12-27 20:18:27,408 basehttp 124 "GET /sms_codes/17775309063/ HTTP/1.1" 500 128353
ERROR 2018-12-27 20:24:19,808 exception 135 Internal Server Error: /sms_codes/17775309063/
Traceback (most recent call last):
  File "/home/python/.virtualenvs/django_py3_11/lib/python3.5/site-packages/rest_framework/views.py", line 480, in dispatch
    response = handler(request, *args, **kwargs)
  File "/home/python/Desktop/meiduo_test1/meiduo_test/meiduo_test/apps/verifications/views.py", line 33, in get
    redis_conn = get_redis_connection('verify_codes')  # StrictRedis 对象
  File "/home/python/.virtualenvs/django_py3_11/lib/python3.5/site-packages/django_redis/__init__.py", line 14, in get_redis_connection
    cache = caches[alias]
  File "/home/python/.virtualenvs/django_py3_11/lib/python3.5/site-packages/django/core/cache/__init__.py", line 77, in __getitem__
    "Could not find config for '%s' in settings.CACHES" % alias
django.core.cache.backends.base.InvalidCacheBackendError: Could not find config for 'verify_codes' in settings.CACHES

During handling of the above exception, another exception occurred:

Traceback (most recent call last):
  File "/home/python/.virtualenvs/django_py3_11/lib/python3.5/site-packages/rest_framework/settings.py", line 183, in import_from_string
    module = import_module(module_path)
  File "/home/python/.virtualenvs/django_py3_11/lib/python3.5/importlib/__init__.py", line 126, in import_module
    return _bootstrap._gcd_import(name[level:], package, level)
  File "<frozen importlib._bootstrap>", line 986, in _gcd_import
  File "<frozen importlib._bootstrap>", line 969, in _find_and_load
  File "<frozen importlib._bootstrap>", line 944, in _find_and_load_unlocked
  File "<frozen importlib._bootstrap>", line 222, in _call_with_frames_removed
  File "<frozen importlib._bootstrap>", line 986, in _gcd_import
  File "<frozen importlib._bootstrap>", line 969, in _find_and_load
  File "<frozen importlib._bootstrap>", line 944, in _find_and_load_unlocked
  File "<frozen importlib._bootstrap>", line 222, in _call_with_frames_removed
  File "<frozen importlib._bootstrap>", line 986, in _gcd_import
  File "<frozen importlib._bootstrap>", line 969, in _find_and_load
  File "<frozen importlib._bootstrap>", line 956, in _find_and_load_unlocked
ImportError: No module named 'meiduo_mall'

During handling of the above exception, another exception occurred:

Traceback (most recent call last):
  File "/home/python/.virtualenvs/django_py3_11/lib/python3.5/site-packages/django/core/handlers/exception.py", line 41, in inner
    response = get_response(request)
  File "/home/python/.virtualenvs/django_py3_11/lib/python3.5/site-packages/django/core/handlers/base.py", line 187, in _get_response
    response = self.process_exception_by_middleware(e, request)
  File "/home/python/.virtualenvs/django_py3_11/lib/python3.5/site-packages/django/core/handlers/base.py", line 185, in _get_response
    response = wrapped_callback(request, *callback_args, **callback_kwargs)
  File "/home/python/.virtualenvs/django_py3_11/lib/python3.5/site-packages/django/views/decorators/csrf.py", line 58, in wrapped_view
    return view_func(*args, **kwargs)
  File "/home/python/.virtualenvs/django_py3_11/lib/python3.5/site-packages/django/views/generic/base.py", line 68, in view
    return self.dispatch(request, *args, **kwargs)
  File "/home/python/.virtualenvs/django_py3_11/lib/python3.5/site-packages/rest_framework/views.py", line 483, in dispatch
    response = self.handle_exception(exc)
  File "/home/python/.virtualenvs/django_py3_11/lib/python3.5/site-packages/rest_framework/views.py", line 437, in handle_exception
    exception_handler = self.get_exception_handler()
  File "/home/python/.virtualenvs/django_py3_11/lib/python3.5/site-packages/rest_framework/views.py", line 288, in get_exception_handler
    return self.settings.EXCEPTION_HANDLER
  File "/home/python/.virtualenvs/django_py3_11/lib/python3.5/site-packages/rest_framework/settings.py", line 227, in __getattr__
    val = perform_import(val, attr)
  File "/home/python/.virtualenvs/django_py3_11/lib/python3.5/site-packages/rest_framework/settings.py", line 170, in perform_import
    return import_from_string(val, setting_name)
  File "/home/python/.virtualenvs/django_py3_11/lib/python3.5/site-packages/rest_framework/settings.py", line 187, in import_from_string
    raise ImportError(msg)
ImportError: Could not import 'meiduo_mall.utils.exceptions.exception_handler' for API setting 'EXCEPTION_HANDLER'. ImportError: No module named 'meiduo_mall'.
ERROR 2018-12-27 20:24:19,937 basehttp 124 "GET /sms_codes/17775309063/ HTTP/1.1" 500 128350
ERROR 2018-12-27 20:26:02,460 exception 135 Internal Server Error: /sms_codes/17775309063/
Traceback (most recent call last):
  File "/home/python/.virtualenvs/django_py3_11/lib/python3.5/site-packages/rest_framework/views.py", line 480, in dispatch
    response = handler(request, *args, **kwargs)
  File "/home/python/Desktop/meiduo_test1/meiduo_test/meiduo_test/apps/verifications/views.py", line 37, in get
    redis_conn = get_redis_connection('verify_codes')  # StrictRedis对象
  File "/home/python/.virtualenvs/django_py3_11/lib/python3.5/site-packages/django_redis/__init__.py", line 14, in get_redis_connection
    cache = caches[alias]
  File "/home/python/.virtualenvs/django_py3_11/lib/python3.5/site-packages/django/core/cache/__init__.py", line 77, in __getitem__
    "Could not find config for '%s' in settings.CACHES" % alias
django.core.cache.backends.base.InvalidCacheBackendError: Could not find config for 'verify_codes' in settings.CACHES

During handling of the above exception, another exception occurred:

Traceback (most recent call last):
  File "/home/python/.virtualenvs/django_py3_11/lib/python3.5/site-packages/rest_framework/settings.py", line 183, in import_from_string
    module = import_module(module_path)
  File "/home/python/.virtualenvs/django_py3_11/lib/python3.5/importlib/__init__.py", line 126, in import_module
    return _bootstrap._gcd_import(name[level:], package, level)
  File "<frozen importlib._bootstrap>", line 986, in _gcd_import
  File "<frozen importlib._bootstrap>", line 969, in _find_and_load
  File "<frozen importlib._bootstrap>", line 944, in _find_and_load_unlocked
  File "<frozen importlib._bootstrap>", line 222, in _call_with_frames_removed
  File "<frozen importlib._bootstrap>", line 986, in _gcd_import
  File "<frozen importlib._bootstrap>", line 969, in _find_and_load
  File "<frozen importlib._bootstrap>", line 944, in _find_and_load_unlocked
  File "<frozen importlib._bootstrap>", line 222, in _call_with_frames_removed
  File "<frozen importlib._bootstrap>", line 986, in _gcd_import
  File "<frozen importlib._bootstrap>", line 969, in _find_and_load
  File "<frozen importlib._bootstrap>", line 956, in _find_and_load_unlocked
ImportError: No module named 'meiduo_mall'

During handling of the above exception, another exception occurred:

Traceback (most recent call last):
  File "/home/python/.virtualenvs/django_py3_11/lib/python3.5/site-packages/django/core/handlers/exception.py", line 41, in inner
    response = get_response(request)
  File "/home/python/.virtualenvs/django_py3_11/lib/python3.5/site-packages/django/core/handlers/base.py", line 187, in _get_response
    response = self.process_exception_by_middleware(e, request)
  File "/home/python/.virtualenvs/django_py3_11/lib/python3.5/site-packages/django/core/handlers/base.py", line 185, in _get_response
    response = wrapped_callback(request, *callback_args, **callback_kwargs)
  File "/home/python/.virtualenvs/django_py3_11/lib/python3.5/site-packages/django/views/decorators/csrf.py", line 58, in wrapped_view
    return view_func(*args, **kwargs)
  File "/home/python/.virtualenvs/django_py3_11/lib/python3.5/site-packages/django/views/generic/base.py", line 68, in view
    return self.dispatch(request, *args, **kwargs)
  File "/home/python/.virtualenvs/django_py3_11/lib/python3.5/site-packages/rest_framework/views.py", line 483, in dispatch
    response = self.handle_exception(exc)
  File "/home/python/.virtualenvs/django_py3_11/lib/python3.5/site-packages/rest_framework/views.py", line 437, in handle_exception
    exception_handler = self.get_exception_handler()
  File "/home/python/.virtualenvs/django_py3_11/lib/python3.5/site-packages/rest_framework/views.py", line 288, in get_exception_handler
    return self.settings.EXCEPTION_HANDLER
  File "/home/python/.virtualenvs/django_py3_11/lib/python3.5/site-packages/rest_framework/settings.py", line 227, in __getattr__
    val = perform_import(val, attr)
  File "/home/python/.virtualenvs/django_py3_11/lib/python3.5/site-packages/rest_framework/settings.py", line 170, in perform_import
    return import_from_string(val, setting_name)
  File "/home/python/.virtualenvs/django_py3_11/lib/python3.5/site-packages/rest_framework/settings.py", line 187, in import_from_string
    raise ImportError(msg)
ImportError: Could not import 'meiduo_mall.utils.exceptions.exception_handler' for API setting 'EXCEPTION_HANDLER'. ImportError: No module named 'meiduo_mall'.
ERROR 2018-12-27 20:26:02,653 basehttp 124 "GET /sms_codes/17775309063/ HTTP/1.1" 500 128404
ERROR 2018-12-27 20:32:00,925 exception 135 Internal Server Error: /sms_codes/17775309063/
Traceback (most recent call last):
  File "/home/python/.virtualenvs/django_py3_11/lib/python3.5/site-packages/rest_framework/views.py", line 480, in dispatch
    response = handler(request, *args, **kwargs)
  File "/home/python/Desktop/meiduo_test1/meiduo_test/meiduo_test/apps/verifications/views.py", line 37, in get
    redis_conn = get_redis_connection('verify_codes')  # StrictRedis对象
  File "/home/python/.virtualenvs/django_py3_11/lib/python3.5/site-packages/django_redis/__init__.py", line 14, in get_redis_connection
    cache = caches[alias]
  File "/home/python/.virtualenvs/django_py3_11/lib/python3.5/site-packages/django/core/cache/__init__.py", line 77, in __getitem__
    "Could not find config for '%s' in settings.CACHES" % alias
django.core.cache.backends.base.InvalidCacheBackendError: Could not find config for 'verify_codes' in settings.CACHES

During handling of the above exception, another exception occurred:

Traceback (most recent call last):
  File "/home/python/.virtualenvs/django_py3_11/lib/python3.5/site-packages/rest_framework/settings.py", line 183, in import_from_string
    module = import_module(module_path)
  File "/home/python/.virtualenvs/django_py3_11/lib/python3.5/importlib/__init__.py", line 126, in import_module
    return _bootstrap._gcd_import(name[level:], package, level)
  File "<frozen importlib._bootstrap>", line 986, in _gcd_import
  File "<frozen importlib._bootstrap>", line 969, in _find_and_load
  File "<frozen importlib._bootstrap>", line 944, in _find_and_load_unlocked
  File "<frozen importlib._bootstrap>", line 222, in _call_with_frames_removed
  File "<frozen importlib._bootstrap>", line 986, in _gcd_import
  File "<frozen importlib._bootstrap>", line 969, in _find_and_load
  File "<frozen importlib._bootstrap>", line 944, in _find_and_load_unlocked
  File "<frozen importlib._bootstrap>", line 222, in _call_with_frames_removed
  File "<frozen importlib._bootstrap>", line 986, in _gcd_import
  File "<frozen importlib._bootstrap>", line 969, in _find_and_load
  File "<frozen importlib._bootstrap>", line 956, in _find_and_load_unlocked
ImportError: No module named 'meiduo_mall'

During handling of the above exception, another exception occurred:

Traceback (most recent call last):
  File "/home/python/.virtualenvs/django_py3_11/lib/python3.5/site-packages/django/core/handlers/exception.py", line 41, in inner
    response = get_response(request)
  File "/home/python/.virtualenvs/django_py3_11/lib/python3.5/site-packages/django/core/handlers/base.py", line 187, in _get_response
    response = self.process_exception_by_middleware(e, request)
  File "/home/python/.virtualenvs/django_py3_11/lib/python3.5/site-packages/django/core/handlers/base.py", line 185, in _get_response
    response = wrapped_callback(request, *callback_args, **callback_kwargs)
  File "/home/python/.virtualenvs/django_py3_11/lib/python3.5/site-packages/django/views/decorators/csrf.py", line 58, in wrapped_view
    return view_func(*args, **kwargs)
  File "/home/python/.virtualenvs/django_py3_11/lib/python3.5/site-packages/django/views/generic/base.py", line 68, in view
    return self.dispatch(request, *args, **kwargs)
  File "/home/python/.virtualenvs/django_py3_11/lib/python3.5/site-packages/rest_framework/views.py", line 483, in dispatch
    response = self.handle_exception(exc)
  File "/home/python/.virtualenvs/django_py3_11/lib/python3.5/site-packages/rest_framework/views.py", line 437, in handle_exception
    exception_handler = self.get_exception_handler()
  File "/home/python/.virtualenvs/django_py3_11/lib/python3.5/site-packages/rest_framework/views.py", line 288, in get_exception_handler
    return self.settings.EXCEPTION_HANDLER
  File "/home/python/.virtualenvs/django_py3_11/lib/python3.5/site-packages/rest_framework/settings.py", line 227, in __getattr__
    val = perform_import(val, attr)
  File "/home/python/.virtualenvs/django_py3_11/lib/python3.5/site-packages/rest_framework/settings.py", line 170, in perform_import
    return import_from_string(val, setting_name)
  File "/home/python/.virtualenvs/django_py3_11/lib/python3.5/site-packages/rest_framework/settings.py", line 187, in import_from_string
    raise ImportError(msg)
ImportError: Could not import 'meiduo_mall.utils.exceptions.exception_handler' for API setting 'EXCEPTION_HANDLER'. ImportError: No module named 'meiduo_mall'.
ERROR 2018-12-27 20:32:01,130 basehttp 124 "GET /sms_codes/17775309063/ HTTP/1.1" 500 128404
ERROR 2018-12-27 20:34:31,478 exception 135 Internal Server Error: /sms_codes/17775309063/
Traceback (most recent call last):
  File "/home/python/.virtualenvs/django_py3_11/lib/python3.5/site-packages/django/core/handlers/exception.py", line 41, in inner
    response = get_response(request)
  File "/home/python/.virtualenvs/django_py3_11/lib/python3.5/site-packages/django/core/handlers/base.py", line 187, in _get_response
    response = self.process_exception_by_middleware(e, request)
  File "/home/python/.virtualenvs/django_py3_11/lib/python3.5/site-packages/django/core/handlers/base.py", line 185, in _get_response
    response = wrapped_callback(request, *callback_args, **callback_kwargs)
  File "/home/python/.virtualenvs/django_py3_11/lib/python3.5/site-packages/django/views/decorators/csrf.py", line 58, in wrapped_view
    return view_func(*args, **kwargs)
  File "/home/python/.virtualenvs/django_py3_11/lib/python3.5/site-packages/django/views/generic/base.py", line 68, in view
    return self.dispatch(request, *args, **kwargs)
  File "/home/python/.virtualenvs/django_py3_11/lib/python3.5/site-packages/rest_framework/views.py", line 483, in dispatch
    response = self.handle_exception(exc)
  File "/home/python/.virtualenvs/django_py3_11/lib/python3.5/site-packages/rest_framework/views.py", line 443, in handle_exception
    self.raise_uncaught_exception(exc)
  File "/home/python/.virtualenvs/django_py3_11/lib/python3.5/site-packages/rest_framework/views.py", line 480, in dispatch
    response = handler(request, *args, **kwargs)
  File "/home/python/Desktop/meiduo_test1/meiduo_test/meiduo_test/apps/verifications/views.py", line 37, in get
    redis_conn = get_redis_connection('verify_codes')  # StrictRedis对象
  File "/home/python/.virtualenvs/django_py3_11/lib/python3.5/site-packages/django_redis/__init__.py", line 14, in get_redis_connection
    cache = caches[alias]
  File "/home/python/.virtualenvs/django_py3_11/lib/python3.5/site-packages/django/core/cache/__init__.py", line 77, in __getitem__
    "Could not find config for '%s' in settings.CACHES" % alias
django.core.cache.backends.base.InvalidCacheBackendError: Could not find config for 'verify_codes' in settings.CACHES
ERROR 2018-12-27 20:34:31,539 basehttp 124 "GET /sms_codes/17775309063/ HTTP/1.1" 500 17865
ERROR 2018-12-27 20:41:49,258 exceptions 28 [<verifications.views.SMSCodeView object at 0x7f1a3360bf98>] <class 'redis.exceptions.ConnectionError'>
ERROR 2018-12-27 20:41:49,261 basehttp 124 "GET /sms_codes/17775309063/ HTTP/1.1" 507 35
ERROR 2018-12-27 20:44:36,248 exceptions 28 [<verifications.views.SMSCodeView object at 0x7feefc587c50>] <class 'redis.exceptions.ConnectionError'>
ERROR 2018-12-27 20:44:51,348 basehttp 124 "GET /sms_codes/17775309063/ HTTP/1.1" 507 35
ERROR 2018-12-27 20:47:12,016 exceptions 28 [<verifications.views.SMSCodeView object at 0x7f5c9e713198>] <class 'redis.exceptions.ConnectionError'>
ERROR 2018-12-27 20:47:12,020 basehttp 124 "GET /sms_codes/17775309063/ HTTP/1.1" 507 35
ERROR 2018-12-27 20:52:39,658 exceptions 28 [<verifications.views.SMSCodeView object at 0x7f7d6c446f98>] <class 'redis.exceptions.ConnectionError'>
ERROR 2018-12-27 20:53:30,193 basehttp 124 "GET /sms_codes/17775309063/ HTTP/1.1" 507 35
ERROR 2018-12-27 20:55:31,169 exceptions 28 [<verifications.views.SMSCodeView object at 0x7f35f7902f98>] <class 'redis.exceptions.ConnectionError'>
ERROR 2018-12-27 20:55:31,170 basehttp 124 "GET /sms_codes/17775309063/ HTTP/1.1" 507 35
INFO 2018-12-27 20:58:33,709 basehttp 124 "GET /sms_codes/17775309063/ HTTP/1.1" 200 16
