INFO 2018-12-27 10:18:02,781 basehttp 124 "GET / HTTP/1.1" 200 1714
WARNING 2018-12-27 10:18:05,540 base 152 Not Found: /favicon.ico
WARNING 2018-12-27 10:18:05,545 basehttp 124 "GET /favicon.ico HTTP/1.1" 404 1967
WARNING 2018-12-27 19:54:37,002 base 152 Not Found: /sms_codes/
WARNING 2018-12-27 19:54:37,046 basehttp 124 "GET /sms_codes/?177775309063 HTTP/1.1" 404 2167
WARNING 2018-12-27 19:56:42,261 base 152 Not Found: /sms_codes/
WARNING 2018-12-27 19:56:42,265 basehttp 124 "GET /sms_codes/?177775309063 HTTP/1.1" 404 2079
WARNING 2018-12-27 19:59:33,236 base 152 Not Found: /sms_codes/177775309063/
WARNING 2018-12-27 19:59:33,239 basehttp 124 "GET /sms_codes/177775309063/ HTTP/1.1" 404 2105
WARNING 2018-12-27 20:00:50,285 base 152 Not Found: /sms_codes/177775309063/
WARNING 2018-12-27 20:00:50,288 basehttp 124 "GET /sms_codes/177775309063/ HTTP/1.1" 404 2105
WARNING 2018-12-27 20:02:10,983 base 152 Not Found: /sms_codes/177775309063/
WARNING 2018-12-27 20:02:10,993 basehttp 124 "GET /sms_codes/177775309063/ HTTP/1.1" 404 2193
WARNING 2018-12-27 20:03:24,685 base 152 Not Found: /sms_codes/177775309063/
WARNING 2018-12-27 20:03:24,687 basehttp 124 "GET /sms_codes/177775309063/ HTTP/1.1" 404 2193
WARNING 2018-12-27 20:03:57,076 base 152 Not Found: /sms_codes/177775309063/
WARNING 2018-12-27 20:03:57,079 basehttp 124 "GET /sms_codes/177775309063/ HTTP/1.1" 404 2086
WARNING 2018-12-27 20:11:56,770 base 152 Not Found: /sms_codes/177775309063/
WARNING 2018-12-27 20:11:56,772 basehttp 124 "GET /sms_codes/177775309063/ HTTP/1.1" 404 2193
WARNING 2018-12-27 20:15:54,874 base 152 Not Found: /sms_codes/177775309063/
WARNING 2018-12-27 20:15:54,892 basehttp 124 "GET /sms_codes/177775309063/ HTTP/1.1" 404 2193
WARNING 2018-12-27 20:16:19,687 base 152 Not Found: /sms_codes/177775309063/
WARNING 2018-12-27 20:16:19,689 basehttp 124 "GET /sms_codes/177775309063/ HTTP/1.1" 404 2192
WARNING 2018-12-27 20:16:48,660 base 152 Not Found: /sms_codes/177775309063/
WARNING 2018-12-27 20:16:48,663 basehttp 124 "GET /sms_codes/177775309063/ HTTP/1.1" 404 2191
WARNING 2018-12-27 20:16:49,900 base 152 Not Found: /sms_codes/177775309063/
WARNING 2018-12-27 20:16:49,900 basehttp 124 "GET /sms_codes/177775309063/ HTTP/1.1" 404 2191
WARNING 2018-12-27 20:17:27,923 base 152 Not Found: /sms_codes/177775309063/
WARNING 2018-12-27 20:17:27,924 basehttp 124 "GET /sms_codes/177775309063/ HTTP/1.1" 404 2192
ERROR 2018-12-27 20:17:57,058 exception 135 Internal Server Error: /sms_codes/17777530903/
Traceback (most recent call last):
  File "/home/python/.virtualenvs/django_py3_11/lib/python3.5/site-packages/rest_framework/views.py", line 480, in dispatch
    response = handler(request, *args, **kwargs)
  File "/home/python/Desktop/meiduo_test1/meiduo_test/meiduo_test/apps/verifications/views.py", line 33, in get
    redis_conn = get_redis_connection("verify_codes")  # StrictRedis 对象
  File "/home/python/.virtualenvs/django_py3_11/lib/python3.5/site-packages/django_redis/__init__.py", line 14, in get_redis_connection
    cache = caches[alias]
  File "/home/python/.virtualenvs/django_py3_11/lib/python3.5/site-packages/django/core/cache/__init__.py", line 77, in __getitem__
    "Could not find config for '%s' in settings.CACHES" % alias
django.core.cache.backends.base.InvalidCacheBackendError: Could not find config for 'verify_codes' in settings.CACHES

During handling of the above exception, another exception occurred:

Traceback (most recent call last):
  File "/home/python/.virtualenvs/django_py3_11/lib/python3.5/site-packages/rest_framework/settings.py", line 183, in import_from_string
    module = import_module(module_path)
  File "/home/python/.virtualenvs/django_py3_11/lib/python3.5/importlib/__init__.py", line 126, in import_module
    return _bootstrap._gcd_import(name[level:], package, level)
  File "<frozen importlib._bootstrap>", line 986, in _gcd_import
  File "<frozen importlib._bootstrap>", line 969, in _find_and_load
  File "<frozen importlib._bootstrap>", line 944, in _find_and_load_unlocked
  File "<frozen importlib._bootstrap>", line 222, in _call_with_frames_removed
  File "<frozen importlib._bootstrap>", line 986, in _gcd_import
  File "<frozen importlib._bootstrap>", line 969, in _find_and_load
  File "<frozen importlib._bootstrap>", line 944, in _find_and_load_unlocked
  File "<frozen importlib._bootstrap>", line 222, in _call_with_frames_removed
  File "<frozen importlib._bootstrap>", line 986, in _gcd_import
  File "<frozen importlib._bootstrap>", line 969, in _find_and_load
  File "<frozen importlib._bootstrap>", line 956, in _find_and_load_unlocked
ImportError: No module named 'meiduo_mall'

During handling of the above exception, another exception occurred:

Traceback (most recent call last):
  File "/home/python/.virtualenvs/django_py3_11/lib/python3.5/site-packages/django/core/handlers/exception.py", line 41, in inner
    response = get_response(request)
  File "/home/python/.virtualenvs/django_py3_11/lib/python3.5/site-packages/django/core/handlers/base.py", line 187, in _get_response
    response = self.process_exception_by_middleware(e, request)
  File "/home/python/.virtualenvs/django_py3_11/lib/python3.5/site-packages/django/core/handlers/base.py", line 185, in _get_response
    response = wrapped_callback(request, *callback_args, **callback_kwargs)
  File "/home/python/.virtualenvs/django_py3_11/lib/python3.5/site-packages/django/views/decorators/csrf.py", line 58, in wrapped_view
    return view_func(*args, **kwargs)
  File "/home/python/.virtualenvs/django_py3_11/lib/python3.5/site-packages/django/views/generic/base.py", line 68, in view
    return self.dispatch(request, *args, **kwargs)
  File "/home/python/.virtualenvs/django_py3_11/lib/python3.5/site-packages/rest_framework/views.py", line 483, in dispatch
    response = self.handle_exception(exc)
  File "/home/python/.virtualenvs/django_py3_11/lib/python3.5/site-packages/rest_framework/views.py", line 437, in handle_exception
    exception_handler = self.get_exception_handler()
  File "/home/python/.virtualenvs/django_py3_11/lib/python3.5/site-packages/rest_framework/views.py", line 288, in get_exception_handler
    return self.settings.EXCEPTION_HANDLER
  File "/home/python/.virtualenvs/django_py3_11/lib/python3.5/site-packages/rest_framework/settings.py", line 227, in __getattr__
    val = perform_import(val, attr)
  File "/home/python/.virtualenvs/django_py3_11/lib/python3.5/site-packages/rest_framework/settings.py", line 170, in perform_import
    return import_from_string(val, setting_name)
  File "/home/python/.virtualenvs/django_py3_11/lib/python3.5/site-packages/rest_framework/settings.py", line 187, in import_from_string
    raise ImportError(msg)
ImportError: Could not import 'meiduo_mall.utils.exceptions.exception_handler' for API setting 'EXCEPTION_HANDLER'. ImportError: No module named 'meiduo_mall'.
ERROR 2018-12-27 20:17:57,749 basehttp 124 "GET /sms_codes/17777530903/ HTTP/1.1" 500 128353
WARNING 2018-12-27 20:18:07,467 base 152 Not Found: /sms_codes/1777530903/
WARNING 2018-12-27 20:18:07,471 basehttp 124 "GET /sms_codes/1777530903/ HTTP/1.1" 404 2186
WARNING 2018-12-27 20:18:16,139 base 152 Not Found: /sms_codes/1777530903/
WARNING 2018-12-27 20:18:16,140 basehttp 124 "GET /sms_codes/1777530903/ HTTP/1.1" 404 2186
ERROR 2018-12-27 20:18:27,268 exception 135 Internal Server Error: /sms_codes/17775309063/
Traceback (most recent call last):
  File "/home/python/.virtualenvs/django_py3_11/lib/python3.5/site-packages/rest_framework/views.py", line 480, in dispatch
    response = handler(request, *args, **kwargs)
  File "/home/python/Desktop/meiduo_test1/meiduo_test/meiduo_test/apps/verifications/views.py", line 33, in get
    redis_conn = get_redis_connection("verify_codes")  # StrictRedis 对象
  File "/home/python/.virtualenvs/django_py3_11/lib/python3.5/site-packages/django_redis/__init__.py", line 14, in get_redis_connection
    cache = caches[alias]
  File "/home/python/.virtualenvs/django_py3_11/lib/python3.5/site-packages/django/core/cache/__init__.py", line 77, in __getitem__
    "Could not find config for '%s' in settings.CACHES" % alias
django.core.cache.backends.base.InvalidCacheBackendError: Could not find config for 'verify_codes' in settings.CACHES

During handling of the above exception, another exception occurred:

Traceback (most recent call last):
  File "/home/python/.virtualenvs/django_py3_11/lib/python3.5/site-packages/rest_framework/settings.py", line 183, in import_from_string
    module = import_module(module_path)
  File "/home/python/.virtualenvs/django_py3_11/lib/python3.5/importlib/__init__.py", line 126, in import_module
    return _bootstrap._gcd_import(name[level:], package, level)
  File "<frozen importlib._bootstrap>", line 986, in _gcd_import
  File "<frozen importlib._bootstrap>", line 969, in _find_and_load
  File "<frozen importlib._bootstrap>", line 944, in _find_and_load_unlocked
  File "<frozen importlib._bootstrap>", line 222, in _call_with_frames_removed
  File "<frozen importlib._bootstrap>", line 986, in _gcd_import
  File "<frozen importlib._bootstrap>", line 969, in _find_and_load
  File "<frozen importlib._bootstrap>", line 944, in _find_and_load_unlocked
  File "<frozen importlib._bootstrap>", line 222, in _call_with_frames_removed
  File "<frozen importlib._bootstrap>", line 986, in _gcd_import
  File "<frozen importlib._bootstrap>", line 969, in _find_and_load
  File "<frozen importlib._bootstrap>", line 956, in _find_and_load_unlocked
ImportError: No module named 'meiduo_mall'

During handling of the above exception, another exception occurred:

Traceback (most recent call last):
  File "/home/python/.virtualenvs/django_py3_11/lib/python3.5/site-packages/django/core/handlers/exception.py", line 41, in inner
    response = get_response(request)
  File "/home/python/.virtualenvs/django_py3_11/lib/python3.5/site-packages/django/core/handlers/base.py", line 187, in _get_response
    response = self.process_exception_by_middleware(e, request)
  File "/home/python/.virtualenvs/django_py3_11/lib/python3.5/site-packages/django/core/handlers/base.py", line 185, in _get_response
    response = wrapped_callback(request, *callback_args, **callback_kwargs)
  File "/home/python/.virtualenvs/django_py3_11/lib/python3.5/site-packages/django/views/decorators/csrf.py", line 58, in wrapped_view
    return view_func(*args, **kwargs)
  File "/home/python/.virtualenvs/django_py3_11/lib/python3.5/site-packages/django/views/generic/base.py", line 68, in view
    return self.dispatch(request, *args, **kwargs)
  File "/home/python/.virtualenvs/django_py3_11/lib/python3.5/site-packages/rest_framework/views.py", line 483, in dispatch
    response = self.handle_exception(exc)
  File "/home/python/.virtualenvs/django_py3_11/lib/python3.5/site-packages/rest_framework/views.py", line 437, in handle_exception
    exception_handler = self.get_exception_handler()
  File "/home/python/.virtualenvs/django_py3_11/lib/python3.5/site-packages/rest_framework/views.py", line 288, in get_exception_handler
    return self.settings.EXCEPTION_HANDLER
  File "/home/python/.virtualenvs/django_py3_11/lib/python3.5/site-packages/rest_framework/settings.py", line 227, in __getattr__
    val = perform_import(val, attr)
  File "/home/python/.virtualenvs/django_py3_11/lib/python3.5/site-packages/rest_framework/settings.py", line 170, in perform_import
    return import_from_string(val, setting_name)
  File "/home/python/.virtualenvs/django_py3_11/lib/python3.5/site-packages/rest_framework/settings.py", line 187, in import_from_string
    raise ImportError(msg)
ImportError: Could not import 'meiduo_mall.utils.exceptions.exception_handler' for API setting 'EXCEPTION_HANDLER'. ImportError: No module named 'meiduo_mall'.
ERROR 2018-12-27 20:18:27,408 basehttp 124 "GET /sms_codes/17775309063/ HTTP/1.1" 500 128353
ERROR 2018-12-27 20:24:19,808 exception 135 Internal Server Error: /sms_codes/17775309063/
Traceback (most recent call last):
  File "/home/python/.virtualenvs/django_py3_11/lib/python3.5/site-packages/rest_framework/views.py", line 480, in dispatch
    response = handler(request, *args, **kwargs)
  File "/home/python/Desktop/meiduo_test1/meiduo_test/meiduo_test/apps/verifications/views.py", line 33, in get
    redis_conn = get_redis_connection('verify_codes')  # StrictRedis 对象
  File "/home/python/.virtualenvs/django_py3_11/lib/python3.5/site-packages/django_redis/__init__.py", line 14, in get_redis_connection
    cache = caches[alias]
  File "/home/python/.virtualenvs/django_py3_11/lib/python3.5/site-packages/django/core/cache/__init__.py", line 77, in __getitem__
    "Could not find config for '%s' in settings.CACHES" % alias
django.core.cache.backends.base.InvalidCacheBackendError: Could not find config for 'verify_codes' in settings.CACHES

During handling of the above exception, another exception occurred:

Traceback (most recent call last):
  File "/home/python/.virtualenvs/django_py3_11/lib/python3.5/site-packages/rest_framework/settings.py", line 183, in import_from_string
    module = import_module(module_path)
  File "/home/python/.virtualenvs/django_py3_11/lib/python3.5/importlib/__init__.py", line 126, in import_module
    return _bootstrap._gcd_import(name[level:], package, level)
  File "<frozen importlib._bootstrap>", line 986, in _gcd_import
  File "<frozen importlib._bootstrap>", line 969, in _find_and_load
  File "<frozen importlib._bootstrap>", line 944, in _find_and_load_unlocked
  File "<frozen importlib._bootstrap>", line 222, in _call_with_frames_removed
  File "<frozen importlib._bootstrap>", line 986, in _gcd_import
  File "<frozen importlib._bootstrap>", line 969, in _find_and_load
  File "<frozen importlib._bootstrap>", line 944, in _find_and_load_unlocked
  File "<frozen importlib._bootstrap>", line 222, in _call_with_frames_removed
  File "<frozen importlib._bootstrap>", line 986, in _gcd_import
  File "<frozen importlib._bootstrap>", line 969, in _find_and_load
  File "<frozen importlib._bootstrap>", line 956, in _find_and_load_unlocked
ImportError: No module named 'meiduo_mall'

During handling of the above exception, another exception occurred:

Traceback (most recent call last):
  File "/home/python/.virtualenvs/django_py3_11/lib/python3.5/site-packages/django/core/handlers/exception.py", line 41, in inner
    response = get_response(request)
  File "/home/python/.virtualenvs/django_py3_11/lib/python3.5/site-packages/django/core/handlers/base.py", line 187, in _get_response
    response = self.process_exception_by_middleware(e, request)
  File "/home/python/.virtualenvs/django_py3_11/lib/python3.5/site-packages/django/core/handlers/base.py", line 185, in _get_response
    response = wrapped_callback(request, *callback_args, **callback_kwargs)
  File "/home/python/.virtualenvs/django_py3_11/lib/python3.5/site-packages/django/views/decorators/csrf.py", line 58, in wrapped_view
    return view_func(*args, **kwargs)
  File "/home/python/.virtualenvs/django_py3_11/lib/python3.5/site-packages/django/views/generic/base.py", line 68, in view
    return self.dispatch(request, *args, **kwargs)
  File "/home/python/.virtualenvs/django_py3_11/lib/python3.5/site-packages/rest_framework/views.py", line 483, in dispatch
    response = self.handle_exception(exc)
  File "/home/python/.virtualenvs/django_py3_11/lib/python3.5/site-packages/rest_framework/views.py", line 437, in handle_exception
    exception_handler = self.get_exception_handler()
  File "/home/python/.virtualenvs/django_py3_11/lib/python3.5/site-packages/rest_framework/views.py", line 288, in get_exception_handler
    return self.settings.EXCEPTION_HANDLER
  File "/home/python/.virtualenvs/django_py3_11/lib/python3.5/site-packages/rest_framework/settings.py", line 227, in __getattr__
    val = perform_import(val, attr)
  File "/home/python/.virtualenvs/django_py3_11/lib/python3.5/site-packages/rest_framework/settings.py", line 170, in perform_import
    return import_from_string(val, setting_name)
  File "/home/python/.virtualenvs/django_py3_11/lib/python3.5/site-packages/rest_framework/settings.py", line 187, in import_from_string
    raise ImportError(msg)
ImportError: Could not import 'meiduo_mall.utils.exceptions.exception_handler' for API setting 'EXCEPTION_HANDLER'. ImportError: No module named 'meiduo_mall'.
ERROR 2018-12-27 20:24:19,937 basehttp 124 "GET /sms_codes/17775309063/ HTTP/1.1" 500 128350
ERROR 2018-12-27 20:26:02,460 exception 135 Internal Server Error: /sms_codes/17775309063/
Traceback (most recent call last):
  File "/home/python/.virtualenvs/django_py3_11/lib/python3.5/site-packages/rest_framework/views.py", line 480, in dispatch
    response = handler(request, *args, **kwargs)
  File "/home/python/Desktop/meiduo_test1/meiduo_test/meiduo_test/apps/verifications/views.py", line 37, in get
    redis_conn = get_redis_connection('verify_codes')  # StrictRedis对象
  File "/home/python/.virtualenvs/django_py3_11/lib/python3.5/site-packages/django_redis/__init__.py", line 14, in get_redis_connection
    cache = caches[alias]
  File "/home/python/.virtualenvs/django_py3_11/lib/python3.5/site-packages/django/core/cache/__init__.py", line 77, in __getitem__
    "Could not find config for '%s' in settings.CACHES" % alias
django.core.cache.backends.base.InvalidCacheBackendError: Could not find config for 'verify_codes' in settings.CACHES

During handling of the above exception, another exception occurred:

Traceback (most recent call last):
  File "/home/python/.virtualenvs/django_py3_11/lib/python3.5/site-packages/rest_framework/settings.py", line 183, in import_from_string
    module = import_module(module_path)
  File "/home/python/.virtualenvs/django_py3_11/lib/python3.5/importlib/__init__.py", line 126, in import_module
    return _bootstrap._gcd_import(name[level:], package, level)
  File "<frozen importlib._bootstrap>", line 986, in _gcd_import
  File "<frozen importlib._bootstrap>", line 969, in _find_and_load
  File "<frozen importlib._bootstrap>", line 944, in _find_and_load_unlocked
  File "<frozen importlib._bootstrap>", line 222, in _call_with_frames_removed
  File "<frozen importlib._bootstrap>", line 986, in _gcd_import
  File "<frozen importlib._bootstrap>", line 969, in _find_and_load
  File "<frozen importlib._bootstrap>", line 944, in _find_and_load_unlocked
  File "<frozen importlib._bootstrap>", line 222, in _call_with_frames_removed
  File "<frozen importlib._bootstrap>", line 986, in _gcd_import
  File "<frozen importlib._bootstrap>", line 969, in _find_and_load
  File "<frozen importlib._bootstrap>", line 956, in _find_and_load_unlocked
ImportError: No module named 'meiduo_mall'

During handling of the above exception, another exception occurred:

Traceback (most recent call last):
  File "/home/python/.virtualenvs/django_py3_11/lib/python3.5/site-packages/django/core/handlers/exception.py", line 41, in inner
    response = get_response(request)
  File "/home/python/.virtualenvs/django_py3_11/lib/python3.5/site-packages/django/core/handlers/base.py", line 187, in _get_response
    response = self.process_exception_by_middleware(e, request)
  File "/home/python/.virtualenvs/django_py3_11/lib/python3.5/site-packages/django/core/handlers/base.py", line 185, in _get_response
    response = wrapped_callback(request, *callback_args, **callback_kwargs)
  File "/home/python/.virtualenvs/django_py3_11/lib/python3.5/site-packages/django/views/decorators/csrf.py", line 58, in wrapped_view
    return view_func(*args, **kwargs)
  File "/home/python/.virtualenvs/django_py3_11/lib/python3.5/site-packages/django/views/generic/base.py", line 68, in view
    return self.dispatch(request, *args, **kwargs)
  File "/home/python/.virtualenvs/django_py3_11/lib/python3.5/site-packages/rest_framework/views.py", line 483, in dispatch
    response = self.handle_exception(exc)
  File "/home/python/.virtualenvs/django_py3_11/lib/python3.5/site-packages/rest_framework/views.py", line 437, in handle_exception
    exception_handler = self.get_exception_handler()
  File "/home/python/.virtualenvs/django_py3_11/lib/python3.5/site-packages/rest_framework/views.py", line 288, in get_exception_handler
    return self.settings.EXCEPTION_HANDLER
  File "/home/python/.virtualenvs/django_py3_11/lib/python3.5/site-packages/rest_framework/settings.py", line 227, in __getattr__
    val = perform_import(val, attr)
  File "/home/python/.virtualenvs/django_py3_11/lib/python3.5/site-packages/rest_framework/settings.py", line 170, in perform_import
    return import_from_string(val, setting_name)
  File "/home/python/.virtualenvs/django_py3_11/lib/python3.5/site-packages/rest_framework/settings.py", line 187, in import_from_string
    raise ImportError(msg)
ImportError: Could not import 'meiduo_mall.utils.exceptions.exception_handler' for API setting 'EXCEPTION_HANDLER'. ImportError: No module named 'meiduo_mall'.
ERROR 2018-12-27 20:26:02,653 basehttp 124 "GET /sms_codes/17775309063/ HTTP/1.1" 500 128404
ERROR 2018-12-27 20:32:00,925 exception 135 Internal Server Error: /sms_codes/17775309063/
Traceback (most recent call last):
  File "/home/python/.virtualenvs/django_py3_11/lib/python3.5/site-packages/rest_framework/views.py", line 480, in dispatch
    response = handler(request, *args, **kwargs)
  File "/home/python/Desktop/meiduo_test1/meiduo_test/meiduo_test/apps/verifications/views.py", line 37, in get
    redis_conn = get_redis_connection('verify_codes')  # StrictRedis对象
  File "/home/python/.virtualenvs/django_py3_11/lib/python3.5/site-packages/django_redis/__init__.py", line 14, in get_redis_connection
    cache = caches[alias]
  File "/home/python/.virtualenvs/django_py3_11/lib/python3.5/site-packages/django/core/cache/__init__.py", line 77, in __getitem__
    "Could not find config for '%s' in settings.CACHES" % alias
django.core.cache.backends.base.InvalidCacheBackendError: Could not find config for 'verify_codes' in settings.CACHES

During handling of the above exception, another exception occurred:

Traceback (most recent call last):
  File "/home/python/.virtualenvs/django_py3_11/lib/python3.5/site-packages/rest_framework/settings.py", line 183, in import_from_string
    module = import_module(module_path)
  File "/home/python/.virtualenvs/django_py3_11/lib/python3.5/importlib/__init__.py", line 126, in import_module
    return _bootstrap._gcd_import(name[level:], package, level)
  File "<frozen importlib._bootstrap>", line 986, in _gcd_import
  File "<frozen importlib._bootstrap>", line 969, in _find_and_load
  File "<frozen importlib._bootstrap>", line 944, in _find_and_load_unlocked
  File "<frozen importlib._bootstrap>", line 222, in _call_with_frames_removed
  File "<frozen importlib._bootstrap>", line 986, in _gcd_import
  File "<frozen importlib._bootstrap>", line 969, in _find_and_load
  File "<frozen importlib._bootstrap>", line 944, in _find_and_load_unlocked
  File "<frozen importlib._bootstrap>", line 222, in _call_with_frames_removed
  File "<frozen importlib._bootstrap>", line 986, in _gcd_import
  File "<frozen importlib._bootstrap>", line 969, in _find_and_load
  File "<frozen importlib._bootstrap>", line 956, in _find_and_load_unlocked
ImportError: No module named 'meiduo_mall'

During handling of the above exception, another exception occurred:

Traceback (most recent call last):
  File "/home/python/.virtualenvs/django_py3_11/lib/python3.5/site-packages/django/core/handlers/exception.py", line 41, in inner
    response = get_response(request)
  File "/home/python/.virtualenvs/django_py3_11/lib/python3.5/site-packages/django/core/handlers/base.py", line 187, in _get_response
    response = self.process_exception_by_middleware(e, request)
  File "/home/python/.virtualenvs/django_py3_11/lib/python3.5/site-packages/django/core/handlers/base.py", line 185, in _get_response
    response = wrapped_callback(request, *callback_args, **callback_kwargs)
  File "/home/python/.virtualenvs/django_py3_11/lib/python3.5/site-packages/django/views/decorators/csrf.py", line 58, in wrapped_view
    return view_func(*args, **kwargs)
  File "/home/python/.virtualenvs/django_py3_11/lib/python3.5/site-packages/django/views/generic/base.py", line 68, in view
    return self.dispatch(request, *args, **kwargs)
  File "/home/python/.virtualenvs/django_py3_11/lib/python3.5/site-packages/rest_framework/views.py", line 483, in dispatch
    response = self.handle_exception(exc)
  File "/home/python/.virtualenvs/django_py3_11/lib/python3.5/site-packages/rest_framework/views.py", line 437, in handle_exception
    exception_handler = self.get_exception_handler()
  File "/home/python/.virtualenvs/django_py3_11/lib/python3.5/site-packages/rest_framework/views.py", line 288, in get_exception_handler
    return self.settings.EXCEPTION_HANDLER
  File "/home/python/.virtualenvs/django_py3_11/lib/python3.5/site-packages/rest_framework/settings.py", line 227, in __getattr__
    val = perform_import(val, attr)
  File "/home/python/.virtualenvs/django_py3_11/lib/python3.5/site-packages/rest_framework/settings.py", line 170, in perform_import
    return import_from_string(val, setting_name)
  File "/home/python/.virtualenvs/django_py3_11/lib/python3.5/site-packages/rest_framework/settings.py", line 187, in import_from_string
    raise ImportError(msg)
ImportError: Could not import 'meiduo_mall.utils.exceptions.exception_handler' for API setting 'EXCEPTION_HANDLER'. ImportError: No module named 'meiduo_mall'.
ERROR 2018-12-27 20:32:01,130 basehttp 124 "GET /sms_codes/17775309063/ HTTP/1.1" 500 128404
ERROR 2018-12-27 20:34:31,478 exception 135 Internal Server Error: /sms_codes/17775309063/
Traceback (most recent call last):
  File "/home/python/.virtualenvs/django_py3_11/lib/python3.5/site-packages/django/core/handlers/exception.py", line 41, in inner
    response = get_response(request)
  File "/home/python/.virtualenvs/django_py3_11/lib/python3.5/site-packages/django/core/handlers/base.py", line 187, in _get_response
    response = self.process_exception_by_middleware(e, request)
  File "/home/python/.virtualenvs/django_py3_11/lib/python3.5/site-packages/django/core/handlers/base.py", line 185, in _get_response
    response = wrapped_callback(request, *callback_args, **callback_kwargs)
  File "/home/python/.virtualenvs/django_py3_11/lib/python3.5/site-packages/django/views/decorators/csrf.py", line 58, in wrapped_view
    return view_func(*args, **kwargs)
  File "/home/python/.virtualenvs/django_py3_11/lib/python3.5/site-packages/django/views/generic/base.py", line 68, in view
    return self.dispatch(request, *args, **kwargs)
  File "/home/python/.virtualenvs/django_py3_11/lib/python3.5/site-packages/rest_framework/views.py", line 483, in dispatch
    response = self.handle_exception(exc)
  File "/home/python/.virtualenvs/django_py3_11/lib/python3.5/site-packages/rest_framework/views.py", line 443, in handle_exception
    self.raise_uncaught_exception(exc)
  File "/home/python/.virtualenvs/django_py3_11/lib/python3.5/site-packages/rest_framework/views.py", line 480, in dispatch
    response = handler(request, *args, **kwargs)
  File "/home/python/Desktop/meiduo_test1/meiduo_test/meiduo_test/apps/verifications/views.py", line 37, in get
    redis_conn = get_redis_connection('verify_codes')  # StrictRedis对象
  File "/home/python/.virtualenvs/django_py3_11/lib/python3.5/site-packages/django_redis/__init__.py", line 14, in get_redis_connection
    cache = caches[alias]
  File "/home/python/.virtualenvs/django_py3_11/lib/python3.5/site-packages/django/core/cache/__init__.py", line 77, in __getitem__
    "Could not find config for '%s' in settings.CACHES" % alias
django.core.cache.backends.base.InvalidCacheBackendError: Could not find config for 'verify_codes' in settings.CACHES
ERROR 2018-12-27 20:34:31,539 basehttp 124 "GET /sms_codes/17775309063/ HTTP/1.1" 500 17865
ERROR 2018-12-27 20:41:49,258 exceptions 28 [<verifications.views.SMSCodeView object at 0x7f1a3360bf98>] <class 'redis.exceptions.ConnectionError'>
ERROR 2018-12-27 20:41:49,261 basehttp 124 "GET /sms_codes/17775309063/ HTTP/1.1" 507 35
ERROR 2018-12-27 20:44:36,248 exceptions 28 [<verifications.views.SMSCodeView object at 0x7feefc587c50>] <class 'redis.exceptions.ConnectionError'>
ERROR 2018-12-27 20:44:51,348 basehttp 124 "GET /sms_codes/17775309063/ HTTP/1.1" 507 35
ERROR 2018-12-27 20:47:12,016 exceptions 28 [<verifications.views.SMSCodeView object at 0x7f5c9e713198>] <class 'redis.exceptions.ConnectionError'>
ERROR 2018-12-27 20:47:12,020 basehttp 124 "GET /sms_codes/17775309063/ HTTP/1.1" 507 35
ERROR 2018-12-27 20:52:39,658 exceptions 28 [<verifications.views.SMSCodeView object at 0x7f7d6c446f98>] <class 'redis.exceptions.ConnectionError'>
ERROR 2018-12-27 20:53:30,193 basehttp 124 "GET /sms_codes/17775309063/ HTTP/1.1" 507 35
ERROR 2018-12-27 20:55:31,169 exceptions 28 [<verifications.views.SMSCodeView object at 0x7f35f7902f98>] <class 'redis.exceptions.ConnectionError'>
ERROR 2018-12-27 20:55:31,170 basehttp 124 "GET /sms_codes/17775309063/ HTTP/1.1" 507 35
INFO 2018-12-27 20:58:33,709 basehttp 124 "GET /sms_codes/17775309063/ HTTP/1.1" 200 16
INFO 2018-12-27 21:24:47,940 basehttp 124 "GET /sms_codes/17775309063/ HTTP/1.1" 200 16
WARNING 2018-12-27 21:24:50,143 basehttp 124 "GET /sms_codes/17775309063/ HTTP/1.1" 400 38
WARNING 2018-12-27 21:45:48,479 base 152 Not Found: /register.html
WARNING 2018-12-27 21:45:48,632 basehttp 124 "GET /register.html HTTP/1.1" 404 2162
INFO 2018-12-27 21:47:29,970 basehttp 124 "GET /sms_codes/17775309063/ HTTP/1.1" 200 16
WARNING 2018-12-27 21:54:00,909 base 152 Not Found: /mobiles/17775309063/count/
WARNING 2018-12-27 21:54:00,910 basehttp 124 "GET /mobiles/17775309063/count/ HTTP/1.1" 404 2201
WARNING 2018-12-27 21:54:01,043 base 152 Not Found: /mobiles/17775309063/count/
WARNING 2018-12-27 21:54:01,048 basehttp 124 "GET /mobiles/17775309063/count/ HTTP/1.1" 404 2201
ERROR 2018-12-27 21:54:01,086 exceptions 28 [<verifications.views.SMSCodeView object at 0x7fa00d542588>] <class 'redis.exceptions.ConnectionError'>
ERROR 2018-12-27 21:54:01,087 basehttp 124 "GET /sms_codes/17775309063/ HTTP/1.1" 507 35
WARNING 2018-12-27 21:56:51,980 base 152 Not Found: /mobiles/17775309063/count/
WARNING 2018-12-27 21:56:51,984 basehttp 124 "GET /mobiles/17775309063/count/ HTTP/1.1" 404 2201
WARNING 2018-12-27 21:56:59,408 base 152 Not Found: /mobiles/17775309063/count/
WARNING 2018-12-27 21:56:59,410 basehttp 124 "GET /mobiles/17775309063/count/ HTTP/1.1" 404 2201
WARNING 2018-12-27 21:56:59,420 base 152 Not Found: /mobiles/17775309063/count/
WARNING 2018-12-27 21:56:59,421 basehttp 124 "GET /mobiles/17775309063/count/ HTTP/1.1" 404 2201
ERROR 2018-12-27 21:56:59,430 exceptions 28 [<verifications.views.SMSCodeView object at 0x7fa00d554828>] <class 'redis.exceptions.ConnectionError'>
ERROR 2018-12-27 21:56:59,431 basehttp 124 "GET /sms_codes/17775309063/ HTTP/1.1" 507 35
WARNING 2018-12-27 21:58:57,087 base 152 Not Found: /mobiles/17775309063/count/
WARNING 2018-12-27 21:58:57,091 base 152 Not Found: /mobiles/17775309063/count/
WARNING 2018-12-27 21:58:57,096 basehttp 124 "GET /mobiles/17775309063/count/ HTTP/1.1" 404 2201
WARNING 2018-12-27 21:58:57,097 basehttp 124 "GET /mobiles/17775309063/count/ HTTP/1.1" 404 2201
ERROR 2018-12-27 21:58:57,141 exceptions 28 [<verifications.views.SMSCodeView object at 0x7ff324469f28>] <class 'redis.exceptions.ConnectionError'>
ERROR 2018-12-27 21:58:57,142 basehttp 124 "GET /sms_codes/17775309063/ HTTP/1.1" 507 35
ERROR 2018-12-27 22:01:35,295 exceptions 28 [<verifications.views.SMSCodeView object at 0x7f53fca66f60>] <class 'redis.exceptions.ConnectionError'>
ERROR 2018-12-27 22:01:35,296 basehttp 124 "GET /sms_codes/17775309063/ HTTP/1.1" 507 35
ERROR 2018-12-27 22:02:07,284 exceptions 28 [<verifications.views.SMSCodeView object at 0x7f389ac7cf98>] <class 'redis.exceptions.ConnectionError'>
ERROR 2018-12-27 22:02:07,285 basehttp 124 "GET /sms_codes/17775309063/ HTTP/1.1" 507 35
INFO 2018-12-27 22:02:53,033 basehttp 124 "GET /sms_codes/17775309063/ HTTP/1.1" 200 16
ERROR 2018-12-27 22:03:51,357 exceptions 28 [<verifications.views.SMSCodeView object at 0x7f9fc9737390>] <class 'redis.exceptions.ConnectionError'>
ERROR 2018-12-27 22:03:51,358 basehttp 124 "GET /sms_codes/17775309063/ HTTP/1.1" 507 35
ERROR 2018-12-27 22:03:55,826 exceptions 28 [<verifications.views.SMSCodeView object at 0x7f9fc973e358>] <class 'redis.exceptions.ConnectionError'>
ERROR 2018-12-27 22:03:55,828 basehttp 124 "GET /sms_codes/17775309063/ HTTP/1.1" 507 35
ERROR 2018-12-27 22:03:56,836 exceptions 28 [<verifications.views.SMSCodeView object at 0x7f9fc9737048>] <class 'redis.exceptions.ConnectionError'>
ERROR 2018-12-27 22:03:56,837 basehttp 124 "GET /sms_codes/17775309063/ HTTP/1.1" 507 35
ERROR 2018-12-27 22:03:57,606 exceptions 28 [<verifications.views.SMSCodeView object at 0x7f9fc973ef28>] <class 'redis.exceptions.ConnectionError'>
ERROR 2018-12-27 22:03:57,608 basehttp 124 "GET /sms_codes/17775309063/ HTTP/1.1" 507 35
WARNING 2018-12-27 22:04:52,393 base 152 Not Found: /mobiles/17775309063/count/
WARNING 2018-12-27 22:04:52,395 basehttp 124 "GET /mobiles/17775309063/count/ HTTP/1.1" 404 2201
ERROR 2018-12-27 22:04:52,496 exceptions 28 [<verifications.views.SMSCodeView object at 0x7f9fc973e710>] <class 'redis.exceptions.ConnectionError'>
ERROR 2018-12-27 22:04:52,497 basehttp 124 "GET /sms_codes/17775309063/ HTTP/1.1" 507 35
WARNING 2018-12-27 22:04:52,512 base 152 Not Found: /mobiles/17775309063/count/
WARNING 2018-12-27 22:04:52,513 basehttp 124 "GET /mobiles/17775309063/count/ HTTP/1.1" 404 2201
ERROR 2018-12-27 22:07:17,056 exception 80 Invalid HTTP_HOST header: 'api.meiduo.site:8000'. You may need to add 'api.meiduo.site' to ALLOWED_HOSTS.
ERROR 2018-12-27 22:07:17,073 exception 80 Invalid HTTP_HOST header: 'api.meiduo.site:8000'. You may need to add 'api.meiduo.site' to ALLOWED_HOSTS.
ERROR 2018-12-27 22:07:17,091 exception 80 Invalid HTTP_HOST header: 'api.meiduo.site:8000'. You may need to add 'api.meiduo.site' to ALLOWED_HOSTS.
WARNING 2018-12-27 22:07:17,467 basehttp 124 "GET /mobiles/17775309063/count/ HTTP/1.1" 400 70842
WARNING 2018-12-27 22:07:17,471 basehttp 124 "GET /sms_codes/17775309063/ HTTP/1.1" 400 70798
WARNING 2018-12-27 22:07:17,517 basehttp 124 "GET /mobiles/17775309063/count/ HTTP/1.1" 400 70842
ERROR 2018-12-27 22:15:27,967 exception 80 Invalid HTTP_HOST header: 'api.meiduo.site:8000'. You may need to add 'api.meiduo.site' to ALLOWED_HOSTS.
ERROR 2018-12-27 22:15:28,034 exception 80 Invalid HTTP_HOST header: 'api.meiduo.site:8000'. You may need to add 'api.meiduo.site' to ALLOWED_HOSTS.
ERROR 2018-12-27 22:15:28,059 exception 80 Invalid HTTP_HOST header: 'api.meiduo.site:8000'. You may need to add 'api.meiduo.site' to ALLOWED_HOSTS.
WARNING 2018-12-27 22:15:28,283 basehttp 124 "GET /mobiles/17775309063/count/ HTTP/1.1" 400 70842
WARNING 2018-12-27 22:15:28,298 basehttp 124 "GET /sms_codes/17775309063/ HTTP/1.1" 400 70798
WARNING 2018-12-27 22:15:28,299 basehttp 124 "GET /mobiles/17775309063/count/ HTTP/1.1" 400 70842
ERROR 2018-12-27 22:21:04,824 exception 80 Invalid HTTP_HOST header: 'api.meiduo.site:8000'. You may need to add 'api.meiduo.site' to ALLOWED_HOSTS.
WARNING 2018-12-27 22:21:04,996 basehttp 124 "GET /sms_codes/17775309063/ HTTP/1.1" 400 70798
ERROR 2018-12-27 22:23:32,829 exceptions 28 [<verifications.views.SMSCodeView object at 0x7f95ce4b3e48>] <class 'redis.exceptions.ConnectionError'>
ERROR 2018-12-27 22:23:32,831 basehttp 124 "GET /sms_codes/17775309063/ HTTP/1.1" 507 35
ERROR 2018-12-27 22:24:50,477 exception 80 Invalid HTTP_HOST header: 'api.meiduo.site:8000'. You may need to add 'api.meiduo.site' to ALLOWED_HOSTS.
WARNING 2018-12-27 22:24:50,698 basehttp 124 "GET /sms_codes/17775309063/ HTTP/1.1" 400 70798
ERROR 2018-12-28 14:17:36,743 exception 80 Invalid HTTP_HOST header: 'api.meiduo.site:8000'. You may need to add 'api.meiduo.site' to ALLOWED_HOSTS.
WARNING 2018-12-28 14:17:37,107 basehttp 124 "GET /sms_codes/17775309063/ HTTP/1.1" 400 71144
ERROR 2018-12-28 14:21:01,358 exceptions 28 [<verifications.views.SMSCodeView object at 0x7f9f744e1eb8>] <class 'redis.exceptions.ConnectionError'>
ERROR 2018-12-28 14:21:01,386 basehttp 124 "GET /sms_codes/17775309063/ HTTP/1.1" 507 35
ERROR 2018-12-28 14:21:23,027 exceptions 28 [<verifications.views.SMSCodeView object at 0x7f9f744e4c50>] <class 'redis.exceptions.ConnectionError'>
ERROR 2018-12-28 14:21:23,029 basehttp 124 "GET /sms_codes/17775309063/ HTTP/1.1" 507 35
ERROR 2018-12-28 14:21:24,278 exceptions 28 [<verifications.views.SMSCodeView object at 0x7f9f744e1128>] <class 'redis.exceptions.ConnectionError'>
ERROR 2018-12-28 14:21:24,279 basehttp 124 "GET /sms_codes/17775309063/ HTTP/1.1" 507 35
ERROR 2018-12-28 14:21:25,165 exceptions 28 [<verifications.views.SMSCodeView object at 0x7f9f744ee470>] <class 'redis.exceptions.ConnectionError'>
ERROR 2018-12-28 14:21:25,200 basehttp 124 "GET /sms_codes/17775309063/ HTTP/1.1" 507 35
INFO 2018-12-28 14:21:40,987 basehttp 124 "GET /sms_codes/17775309063/ HTTP/1.1" 200 16
INFO 2018-12-28 14:23:00,764 basehttp 124 "GET /sms_codes/17775309063/ HTTP/1.1" 200 16
WARNING 2018-12-28 14:23:02,367 basehttp 124 "GET /sms_codes/17775309063/ HTTP/1.1" 400 38
ERROR 2018-12-28 14:23:24,972 exception 80 Invalid HTTP_HOST header: 'api.meiduo.site:8000'. You may need to add 'api.meiduo.site' to ALLOWED_HOSTS.
WARNING 2018-12-28 14:23:25,213 basehttp 124 "GET /sms_codes/17775309063/ HTTP/1.1" 400 70853
INFO 2018-12-28 16:05:56,773 basehttp 124 "GET /mobiles/17775309063/count/ HTTP/1.1" 200 34
INFO 2018-12-28 16:05:56,784 basehttp 124 "GET /mobiles/17775309063/count/ HTTP/1.1" 200 34
ERROR 2018-12-28 16:05:57,477 exception 135 Internal Server Error: /sms_codes/17775309063/
Traceback (most recent call last):
  File "/home/python/.virtualenvs/django_py3_11/lib/python3.5/site-packages/celery/local.py", line 319, in _get_current_object
    return object.__getattribute__(self, '__thing')
AttributeError: 'PromiseProxy' object has no attribute '__thing'

During handling of the above exception, another exception occurred:

Traceback (most recent call last):
  File "/home/python/.virtualenvs/django_py3_11/lib/python3.5/site-packages/kombu/utils/objects.py", line 42, in __get__
    return obj.__dict__[self.__name__]
KeyError: 'data'

During handling of the above exception, another exception occurred:

Traceback (most recent call last):
  File "/home/python/.virtualenvs/django_py3_11/lib/python3.5/site-packages/celery/loaders/base.py", line 144, in _smart_import
    return imp(path)
  File "/home/python/.virtualenvs/django_py3_11/lib/python3.5/site-packages/celery/loaders/base.py", line 104, in import_from_cwd
    package=package,
  File "/home/python/.virtualenvs/django_py3_11/lib/python3.5/site-packages/celery/utils/imports.py", line 104, in import_from_cwd
    return imp(module, package=package)
  File "/home/python/.virtualenvs/django_py3_11/lib/python3.5/site-packages/celery/loaders/base.py", line 98, in import_module
    return importlib.import_module(module, package=package)
  File "/home/python/.virtualenvs/django_py3_11/lib/python3.5/importlib/__init__.py", line 126, in import_module
    return _bootstrap._gcd_import(name[level:], package, level)
  File "<frozen importlib._bootstrap>", line 986, in _gcd_import
  File "<frozen importlib._bootstrap>", line 969, in _find_and_load
  File "<frozen importlib._bootstrap>", line 956, in _find_and_load_unlocked
ImportError: No module named 'celery_tasks_config'

During handling of the above exception, another exception occurred:

Traceback (most recent call last):
  File "/home/python/.virtualenvs/django_py3_11/lib/python3.5/site-packages/django/core/handlers/exception.py", line 41, in inner
    response = get_response(request)
  File "/home/python/.virtualenvs/django_py3_11/lib/python3.5/site-packages/django/core/handlers/base.py", line 187, in _get_response
    response = self.process_exception_by_middleware(e, request)
  File "/home/python/.virtualenvs/django_py3_11/lib/python3.5/site-packages/django/core/handlers/base.py", line 185, in _get_response
    response = wrapped_callback(request, *callback_args, **callback_kwargs)
  File "/home/python/.virtualenvs/django_py3_11/lib/python3.5/site-packages/django/views/decorators/csrf.py", line 58, in wrapped_view
    return view_func(*args, **kwargs)
  File "/home/python/.virtualenvs/django_py3_11/lib/python3.5/site-packages/django/views/generic/base.py", line 68, in view
    return self.dispatch(request, *args, **kwargs)
  File "/home/python/.virtualenvs/django_py3_11/lib/python3.5/site-packages/rest_framework/views.py", line 483, in dispatch
    response = self.handle_exception(exc)
  File "/home/python/.virtualenvs/django_py3_11/lib/python3.5/site-packages/rest_framework/views.py", line 443, in handle_exception
    self.raise_uncaught_exception(exc)
  File "/home/python/.virtualenvs/django_py3_11/lib/python3.5/site-packages/rest_framework/views.py", line 480, in dispatch
    response = handler(request, *args, **kwargs)
  File "/home/python/Desktop/meiduo_test1/meiduo_test/meiduo_test/apps/verifications/views.py", line 63, in get
    send_sms_code.delay(mobile, sms_code, expires)
  File "/home/python/.virtualenvs/django_py3_11/lib/python3.5/site-packages/celery/local.py", line 148, in __getattr__
    return getattr(self._get_current_object(), name)
  File "/home/python/.virtualenvs/django_py3_11/lib/python3.5/site-packages/celery/local.py", line 321, in _get_current_object
    return self.__evaluate__()
  File "/home/python/.virtualenvs/django_py3_11/lib/python3.5/site-packages/celery/local.py", line 351, in __evaluate__
    thing = Proxy._get_current_object(self)
  File "/home/python/.virtualenvs/django_py3_11/lib/python3.5/site-packages/celery/local.py", line 111, in _get_current_object
    return loc(*self.__args, **self.__kwargs)
  File "/home/python/.virtualenvs/django_py3_11/lib/python3.5/site-packages/celery/app/base.py", line 453, in _task_from_fun
    task.bind(self)  # connects task to this app
  File "/home/python/.virtualenvs/django_py3_11/lib/python3.5/site-packages/celery/app/task.py", line 319, in bind
    setattr(cls, attr_name, conf[config_name])
  File "/home/python/.virtualenvs/django_py3_11/lib/python3.5/site-packages/celery/utils/collections.py", line 432, in __getitem__
    return getitem(k)
  File "/home/python/.virtualenvs/django_py3_11/lib/python3.5/site-packages/celery/utils/collections.py", line 281, in __getitem__
    return mapping[_key]
  File "/home/python/.virtualenvs/django_py3_11/lib/python3.5/collections/__init__.py", line 982, in __getitem__
    if key in self.data:
  File "/home/python/.virtualenvs/django_py3_11/lib/python3.5/site-packages/kombu/utils/objects.py", line 44, in __get__
    value = obj.__dict__[self.__name__] = self.__get(obj)
  File "/home/python/.virtualenvs/django_py3_11/lib/python3.5/site-packages/celery/app/base.py", line 139, in data
    return self.callback()
  File "/home/python/.virtualenvs/django_py3_11/lib/python3.5/site-packages/celery/app/base.py", line 902, in _finalize_pending_conf
    conf = self._conf = self._load_config()
  File "/home/python/.virtualenvs/django_py3_11/lib/python3.5/site-packages/celery/app/base.py", line 912, in _load_config
    self.loader.config_from_object(self._config_source)
  File "/home/python/.virtualenvs/django_py3_11/lib/python3.5/site-packages/celery/loaders/base.py", line 126, in config_from_object
    obj = self._smart_import(obj, imp=self.import_from_cwd)
  File "/home/python/.virtualenvs/django_py3_11/lib/python3.5/site-packages/celery/loaders/base.py", line 147, in _smart_import
    return symbol_by_name(path, imp=imp)
  File "/home/python/.virtualenvs/django_py3_11/lib/python3.5/site-packages/kombu/utils/imports.py", line 56, in symbol_by_name
    module = imp(module_name, package=package, **kwargs)
  File "/home/python/.virtualenvs/django_py3_11/lib/python3.5/site-packages/celery/loaders/base.py", line 104, in import_from_cwd
    package=package,
  File "/home/python/.virtualenvs/django_py3_11/lib/python3.5/site-packages/celery/utils/imports.py", line 104, in import_from_cwd
    return imp(module, package=package)
  File "/home/python/.virtualenvs/django_py3_11/lib/python3.5/site-packages/celery/loaders/base.py", line 98, in import_module
    return importlib.import_module(module, package=package)
  File "/home/python/.virtualenvs/django_py3_11/lib/python3.5/importlib/__init__.py", line 126, in import_module
    return _bootstrap._gcd_import(name[level:], package, level)
  File "<frozen importlib._bootstrap>", line 986, in _gcd_import
  File "<frozen importlib._bootstrap>", line 969, in _find_and_load
  File "<frozen importlib._bootstrap>", line 956, in _find_and_load_unlocked
ImportError: No module named 'celery_tasks_config'
ERROR 2018-12-28 16:05:57,752 basehttp 124 "GET /sms_codes/17775309063/ HTTP/1.1" 500 22951
INFO 2018-12-28 16:14:01,185 basehttp 124 "GET /mobiles/17775309063/count/ HTTP/1.1" 200 34
INFO 2018-12-28 16:14:02,531 basehttp 124 "GET /sms_codes/17775309063/ HTTP/1.1" 200 16
INFO 2018-12-28 16:15:43,574 basehttp 124 "GET /mobiles/17775309063/count/ HTTP/1.1" 200 34
INFO 2018-12-28 16:15:43,683 basehttp 124 "GET /sms_codes/17775309063/ HTTP/1.1" 200 16
WARNING 2018-12-28 16:16:26,318 basehttp 124 "GET /sms_codes/17775309063/ HTTP/1.1" 400 38
INFO 2018-12-28 16:16:26,463 basehttp 124 "GET /mobiles/17775309063/count/ HTTP/1.1" 200 34
INFO 2018-12-28 16:16:26,466 basehttp 124 "GET /mobiles/17775309063/count/ HTTP/1.1" 200 34
INFO 2018-12-28 16:25:19,742 basehttp 124 "GET /sms_codes/17775309063/ HTTP/1.1" 200 16
INFO 2018-12-29 20:48:56,389 basehttp 124 "GET /usernames/python2/count/ HTTP/1.1" 200 31
INFO 2018-12-29 20:48:56,410 basehttp 124 "GET /mobiles/13155556666/count/ HTTP/1.1" 200 34
INFO 2018-12-29 20:49:18,256 basehttp 124 "GET /usernames/python3/count/ HTTP/1.1" 200 31
INFO 2018-12-29 20:49:36,197 basehttp 124 "GET /mobiles/13144445555/count/ HTTP/1.1" 200 34
INFO 2018-12-29 20:49:36,369 basehttp 124 "GET /mobiles/13144445555/count/ HTTP/1.1" 200 34
INFO 2018-12-29 20:49:36,371 views 42 短信验证码内容为: 565069
INFO 2018-12-29 20:49:36,666 basehttp 124 "GET /sms_codes/13144445555/ HTTP/1.1" 200 16
INFO 2018-12-29 20:49:52,099 basehttp 124 "OPTIONS /users/ HTTP/1.1" 200 0
INFO 2018-12-29 20:49:52,123 basehttp 124 "GET /usernames/python3/count/ HTTP/1.1" 200 31
INFO 2018-12-29 20:49:52,128 basehttp 124 "GET /mobiles/13144445555/count/ HTTP/1.1" 200 34
INFO 2018-12-29 20:49:53,281 basehttp 124 "POST /users/ HTTP/1.1" 201 227
INFO 2018-12-29 21:21:28,437 basehttp 124 "GET /mobiles/17612345678/count/ HTTP/1.1" 200 34
INFO 2018-12-29 21:21:41,998 basehttp 124 "GET /mobiles/13866667777/count/ HTTP/1.1" 200 34
INFO 2018-12-29 21:21:46,542 basehttp 124 "GET /mobiles/13866667777/count/ HTTP/1.1" 200 34
INFO 2018-12-29 21:21:48,437 basehttp 124 "GET /mobiles/13866667777/count/ HTTP/1.1" 200 34
INFO 2018-12-29 21:21:48,655 views 42 短信验证码内容为: 142388
INFO 2018-12-29 21:21:51,588 basehttp 124 "GET /sms_codes/13866667777/ HTTP/1.1" 200 16
WARNING 2018-12-29 21:22:04,108 basehttp 124 "POST /users/ HTTP/1.1" 400 83
INFO 2018-12-29 21:22:12,334 basehttp 124 "POST /users/ HTTP/1.1" 201 222
INFO 2018-12-29 21:58:42,201 basehttp 124 "OPTIONS /authorizations/ HTTP/1.1" 200 0
WARNING 2018-12-29 21:58:42,382 basehttp 124 "POST /authorizations/ HTTP/1.1" 400 67
INFO 2018-12-29 21:59:10,041 basehttp 124 "POST /authorizations/ HTTP/1.1" 200 204
INFO 2019-01-01 14:22:03,640 basehttp 124 "GET /mobiles/13155667788/count/ HTTP/1.1" 200 34
INFO 2019-01-01 14:23:28,406 basehttp 124 "GET /mobiles/13155667788/count/ HTTP/1.1" 200 34
WARNING 2019-01-01 15:00:23,570 base 152 Not Found: /oauth/qq/authorization/
WARNING 2019-01-01 15:00:23,824 basehttp 124 "GET /oauth/qq/authorization/ HTTP/1.1" 404 2908
INFO 2019-01-01 15:01:17,015 basehttp 124 "GET /oauth/qq/authorization/ HTTP/1.1" 200 220
WARNING 2019-01-01 15:07:25,684 base 152 Not Found: /
WARNING 2019-01-01 15:07:25,685 basehttp 124 "GET / HTTP/1.1" 404 2922
WARNING 2019-01-01 15:07:25,910 base 152 Not Found: /favicon.ico
WARNING 2019-01-01 15:07:25,911 basehttp 124 "GET /favicon.ico HTTP/1.1" 404 2973
WARNING 2019-01-01 15:14:52,357 basehttp 124 "GET /oauth/qq/authorization/ HTTP/1.1" 405 45
WARNING 2019-01-01 15:15:18,243 basehttp 124 "GET /oauth/qq/authorization/ HTTP/1.1" 405 45
INFO 2019-01-01 15:17:06,092 basehttp 124 "GET /oauth/qq/authorization/ HTTP/1.1" 200 220
INFO 2019-01-01 17:22:48,836 basehttp 124 "GET /oauth/qq/authorization/ HTTP/1.1" 200 220
INFO 2019-01-01 17:33:53,888 basehttp 124 "GET /oauth/qq/authorization/ HTTP/1.1" 200 220
INFO 2019-01-01 17:35:22,711 basehttp 124 "GET /oauth/qq/authorization/ HTTP/1.1" 200 220
INFO 2019-01-01 17:44:51,963 basehttp 124 "GET /oauth/qq/authorization/ HTTP/1.1" 200 220
INFO 2019-01-01 17:53:11,314 basehttp 124 "GET /oauth/qq/authorization/?next=/ HTTP/1.1" 200 220
INFO 2019-01-01 17:54:19,120 basehttp 124 "GET /admin/ HTTP/1.1" 302 0
INFO 2019-01-01 17:54:19,522 basehttp 124 "GET /admin/login/?next=/admin/ HTTP/1.1" 200 1652
INFO 2019-01-01 17:54:28,447 basehttp 124 "GET /admin/login/?next=/admin/ HTTP/1.1" 200 1652
INFO 2019-01-01 17:59:35,367 basehttp 124 "GET /oauth/qq/authorization/?next=/ HTTP/1.1" 200 220
INFO 2019-01-01 18:00:56,365 basehttp 124 "GET /oauth/qq/user/?code=56C8CBC51653F421AFF318AB27F2B27F HTTP/1.1" 200 190
INFO 2019-01-01 18:09:26,869 basehttp 124 "GET /oauth/qq/authorization/?next=/ HTTP/1.1" 200 220
INFO 2019-01-01 19:12:44,124 views 42 短信验证码内容为: 438779
INFO 2019-01-01 19:12:47,076 basehttp 124 "GET /sms_codes/17775309063/ HTTP/1.1" 200 16
INFO 2019-01-01 19:18:51,567 basehttp 124 "GET /oauth/qq/user/?code=99ABBA7EF540C16279623E9AA64AB475 HTTP/1.1" 200 190
WARNING 2019-01-01 19:19:22,595 basehttp 124 "POST /oauth/qq/user/ HTTP/1.1" 405 46
INFO 2019-01-01 19:23:53,062 basehttp 124 "GET /oauth/qq/authorization/?next=/ HTTP/1.1" 200 220
WARNING 2019-01-01 19:29:54,570 basehttp 124 "POST /oauth/qq/user/ HTTP/1.1" 405 46
WARNING 2019-01-01 19:31:40,249 basehttp 124 "POST /oauth/qq/user/ HTTP/1.1" 405 46
INFO 2019-01-02 09:56:16,438 basehttp 124 "GET /oauth/qq/authorization/?next=/ HTTP/1.1" 200 220
INFO 2019-01-02 09:58:53,977 views 42 短信验证码内容为: 374870
INFO 2019-01-02 09:58:55,277 basehttp 124 "GET /sms_codes/17775309063/ HTTP/1.1" 200 16
INFO 2019-01-02 10:07:11,274 basehttp 124 "GET /oauth/qq/authorization/?next=/ HTTP/1.1" 200 220
INFO 2019-01-02 10:07:30,451 basehttp 124 "GET /oauth/qq/user/?code=AA95E103BBEBD6AFDE1A95AAFB69ABC7 HTTP/1.1" 200 190
INFO 2019-01-02 10:07:59,834 views 42 短信验证码内容为: 633568
INFO 2019-01-02 10:08:00,030 basehttp 124 "GET /sms_codes/17612345678/ HTTP/1.1" 200 16
INFO 2019-01-02 10:08:15,781 basehttp 124 "OPTIONS /oauth/qq/user/ HTTP/1.1" 200 0
WARNING 2019-01-02 10:08:15,862 basehttp 124 "POST /oauth/qq/user/ HTTP/1.1" 405 46
WARNING 2019-01-02 10:08:20,920 basehttp 124 "POST /oauth/qq/user/ HTTP/1.1" 405 46
WARNING 2019-01-02 10:08:31,437 basehttp 124 "POST /oauth/qq/user/ HTTP/1.1" 405 46
WARNING 2019-01-02 10:08:32,673 basehttp 124 "POST /oauth/qq/user/ HTTP/1.1" 405 46
WARNING 2019-01-02 10:08:33,445 basehttp 124 "POST /oauth/qq/user/ HTTP/1.1" 405 46
WARNING 2019-01-02 10:08:34,132 basehttp 124 "POST /oauth/qq/user/ HTTP/1.1" 405 46
WARNING 2019-01-02 10:08:34,353 basehttp 124 "POST /oauth/qq/user/ HTTP/1.1" 405 46
WARNING 2019-01-02 10:08:34,519 basehttp 124 "POST /oauth/qq/user/ HTTP/1.1" 405 46
WARNING 2019-01-02 10:08:34,712 basehttp 124 "POST /oauth/qq/user/ HTTP/1.1" 405 46
WARNING 2019-01-02 10:08:40,940 basehttp 124 "POST /oauth/qq/user/ HTTP/1.1" 405 46
WARNING 2019-01-02 10:08:41,137 basehttp 124 "POST /oauth/qq/user/ HTTP/1.1" 405 46
WARNING 2019-01-02 10:08:41,324 basehttp 124 "POST /oauth/qq/user/ HTTP/1.1" 405 46
INFO 2019-01-02 18:48:21,527 basehttp 124 "GET /oauth/qq/authorization/?next=/ HTTP/1.1" 200 195
INFO 2019-01-02 18:48:44,039 basehttp 124 "GET /oauth/qq/user/?code=FC2D1C5DFC2A599C264F56C36B52BCF3 HTTP/1.1" 200 190
INFO 2019-01-02 18:48:47,539 views 42 短信验证码内容为: 842748
INFO 2019-01-02 18:48:47,794 basehttp 124 "GET /sms_codes/17612345678/ HTTP/1.1" 200 16
INFO 2019-01-02 18:49:00,123 basehttp 124 "OPTIONS /oauth/qq/user/ HTTP/1.1" 200 0
INFO 2019-01-02 18:49:00,374 basehttp 124 "POST /oauth/qq/user/ HTTP/1.1" 201 225
INFO 2019-01-02 19:40:47,248 basehttp 124 "GET /oauth/qq/authorization/?next=/ HTTP/1.1" 200 195
INFO 2019-01-02 19:41:03,767 basehttp 124 "GET /oauth/qq/user/?code=0F03DB057DE200A5139265A9B75D3432 HTTP/1.1" 200 230
INFO 2019-01-02 19:41:06,729 basehttp 124 "OPTIONS /user/ HTTP/1.1" 200 0
WARNING 2019-01-02 19:41:06,880 base 152 Not Found: /user/
WARNING 2019-01-02 19:41:06,881 basehttp 124 "GET /user/ HTTP/1.1" 404 2961
WARNING 2019-01-02 19:41:10,897 base 152 Not Found: /user/
WARNING 2019-01-02 19:41:10,898 basehttp 124 "GET /user/ HTTP/1.1" 404 2961
WARNING 2019-01-02 19:41:13,078 base 152 Not Found: /user/
WARNING 2019-01-02 19:41:13,079 basehttp 124 "GET /user/ HTTP/1.1" 404 2961
ERROR 2019-01-02 19:49:45,456 exception 135 Internal Server Error: /user/
Traceback (most recent call last):
  File "/home/python/.virtualenvs/django_py3_11/lib/python3.5/site-packages/django/core/handlers/exception.py", line 41, in inner
    response = get_response(request)
  File "/home/python/.virtualenvs/django_py3_11/lib/python3.5/site-packages/django/core/handlers/base.py", line 187, in _get_response
    response = self.process_exception_by_middleware(e, request)
  File "/home/python/.virtualenvs/django_py3_11/lib/python3.5/site-packages/django/core/handlers/base.py", line 185, in _get_response
    response = wrapped_callback(request, *callback_args, **callback_kwargs)
  File "/home/python/.virtualenvs/django_py3_11/lib/python3.5/site-packages/django/views/decorators/csrf.py", line 58, in wrapped_view
    return view_func(*args, **kwargs)
  File "/home/python/.virtualenvs/django_py3_11/lib/python3.5/site-packages/django/views/generic/base.py", line 68, in view
    return self.dispatch(request, *args, **kwargs)
  File "/home/python/.virtualenvs/django_py3_11/lib/python3.5/site-packages/rest_framework/views.py", line 483, in dispatch
    response = self.handle_exception(exc)
  File "/home/python/.virtualenvs/django_py3_11/lib/python3.5/site-packages/rest_framework/views.py", line 443, in handle_exception
    self.raise_uncaught_exception(exc)
  File "/home/python/.virtualenvs/django_py3_11/lib/python3.5/site-packages/rest_framework/views.py", line 480, in dispatch
    response = handler(request, *args, **kwargs)
  File "/home/python/.virtualenvs/django_py3_11/lib/python3.5/site-packages/rest_framework/generics.py", line 210, in get
    return self.retrieve(request, *args, **kwargs)
  File "/home/python/.virtualenvs/django_py3_11/lib/python3.5/site-packages/rest_framework/mixins.py", line 58, in retrieve
    return Response(serializer.data)
  File "/home/python/.virtualenvs/django_py3_11/lib/python3.5/site-packages/rest_framework/serializers.py", line 560, in data
    ret = super(Serializer, self).data
  File "/home/python/.virtualenvs/django_py3_11/lib/python3.5/site-packages/rest_framework/serializers.py", line 262, in data
    self._data = self.to_representation(self.instance)
  File "/home/python/.virtualenvs/django_py3_11/lib/python3.5/site-packages/rest_framework/serializers.py", line 510, in to_representation
    fields = self._readable_fields
  File "/home/python/.virtualenvs/django_py3_11/lib/python3.5/site-packages/django/utils/functional.py", line 35, in __get__
    res = instance.__dict__[self.name] = self.func(instance)
  File "/home/python/.virtualenvs/django_py3_11/lib/python3.5/site-packages/rest_framework/serializers.py", line 376, in _readable_fields
    field for field in self.fields.values()
  File "/home/python/.virtualenvs/django_py3_11/lib/python3.5/site-packages/rest_framework/serializers.py", line 363, in fields
    for key, value in self.get_fields().items():
  File "/home/python/.virtualenvs/django_py3_11/lib/python3.5/site-packages/rest_framework/serializers.py", line 1002, in get_fields
    serializer_class=self.__class__.__name__
AssertionError: Class UserDetailSerializer missing "Meta.model" attribute
ERROR 2019-01-02 19:49:45,875 basehttp 124 "GET /user/ HTTP/1.1" 500 19977
ERROR 2019-01-02 19:49:47,178 exception 135 Internal Server Error: /user/
Traceback (most recent call last):
  File "/home/python/.virtualenvs/django_py3_11/lib/python3.5/site-packages/django/core/handlers/exception.py", line 41, in inner
    response = get_response(request)
  File "/home/python/.virtualenvs/django_py3_11/lib/python3.5/site-packages/django/core/handlers/base.py", line 187, in _get_response
    response = self.process_exception_by_middleware(e, request)
  File "/home/python/.virtualenvs/django_py3_11/lib/python3.5/site-packages/django/core/handlers/base.py", line 185, in _get_response
    response = wrapped_callback(request, *callback_args, **callback_kwargs)
  File "/home/python/.virtualenvs/django_py3_11/lib/python3.5/site-packages/django/views/decorators/csrf.py", line 58, in wrapped_view
    return view_func(*args, **kwargs)
  File "/home/python/.virtualenvs/django_py3_11/lib/python3.5/site-packages/django/views/generic/base.py", line 68, in view
    return self.dispatch(request, *args, **kwargs)
  File "/home/python/.virtualenvs/django_py3_11/lib/python3.5/site-packages/rest_framework/views.py", line 483, in dispatch
    response = self.handle_exception(exc)
  File "/home/python/.virtualenvs/django_py3_11/lib/python3.5/site-packages/rest_framework/views.py", line 443, in handle_exception
    self.raise_uncaught_exception(exc)
  File "/home/python/.virtualenvs/django_py3_11/lib/python3.5/site-packages/rest_framework/views.py", line 480, in dispatch
    response = handler(request, *args, **kwargs)
  File "/home/python/.virtualenvs/django_py3_11/lib/python3.5/site-packages/rest_framework/generics.py", line 210, in get
    return self.retrieve(request, *args, **kwargs)
  File "/home/python/.virtualenvs/django_py3_11/lib/python3.5/site-packages/rest_framework/mixins.py", line 58, in retrieve
    return Response(serializer.data)
  File "/home/python/.virtualenvs/django_py3_11/lib/python3.5/site-packages/rest_framework/serializers.py", line 560, in data
    ret = super(Serializer, self).data
  File "/home/python/.virtualenvs/django_py3_11/lib/python3.5/site-packages/rest_framework/serializers.py", line 262, in data
    self._data = self.to_representation(self.instance)
  File "/home/python/.virtualenvs/django_py3_11/lib/python3.5/site-packages/rest_framework/serializers.py", line 510, in to_representation
    fields = self._readable_fields
  File "/home/python/.virtualenvs/django_py3_11/lib/python3.5/site-packages/django/utils/functional.py", line 35, in __get__
    res = instance.__dict__[self.name] = self.func(instance)
  File "/home/python/.virtualenvs/django_py3_11/lib/python3.5/site-packages/rest_framework/serializers.py", line 376, in _readable_fields
    field for field in self.fields.values()
  File "/home/python/.virtualenvs/django_py3_11/lib/python3.5/site-packages/rest_framework/serializers.py", line 363, in fields
    for key, value in self.get_fields().items():
  File "/home/python/.virtualenvs/django_py3_11/lib/python3.5/site-packages/rest_framework/serializers.py", line 1002, in get_fields
    serializer_class=self.__class__.__name__
AssertionError: Class UserDetailSerializer missing "Meta.model" attribute
ERROR 2019-01-02 19:49:47,241 basehttp 124 "GET /user/ HTTP/1.1" 500 19977
INFO 2019-01-02 19:49:53,599 basehttp 124 "GET /oauth/qq/authorization/?next=/ HTTP/1.1" 200 195
INFO 2019-01-02 19:50:08,392 basehttp 124 "GET /oauth/qq/user/?code=B81973D7EC4DE97C0C2998453F8DCFD1 HTTP/1.1" 200 230
INFO 2019-01-02 19:50:11,899 basehttp 124 "OPTIONS /user/ HTTP/1.1" 200 0
ERROR 2019-01-02 19:50:11,976 exception 135 Internal Server Error: /user/
Traceback (most recent call last):
  File "/home/python/.virtualenvs/django_py3_11/lib/python3.5/site-packages/django/core/handlers/exception.py", line 41, in inner
    response = get_response(request)
  File "/home/python/.virtualenvs/django_py3_11/lib/python3.5/site-packages/django/core/handlers/base.py", line 187, in _get_response
    response = self.process_exception_by_middleware(e, request)
  File "/home/python/.virtualenvs/django_py3_11/lib/python3.5/site-packages/django/core/handlers/base.py", line 185, in _get_response
    response = wrapped_callback(request, *callback_args, **callback_kwargs)
  File "/home/python/.virtualenvs/django_py3_11/lib/python3.5/site-packages/django/views/decorators/csrf.py", line 58, in wrapped_view
    return view_func(*args, **kwargs)
  File "/home/python/.virtualenvs/django_py3_11/lib/python3.5/site-packages/django/views/generic/base.py", line 68, in view
    return self.dispatch(request, *args, **kwargs)
  File "/home/python/.virtualenvs/django_py3_11/lib/python3.5/site-packages/rest_framework/views.py", line 483, in dispatch
    response = self.handle_exception(exc)
  File "/home/python/.virtualenvs/django_py3_11/lib/python3.5/site-packages/rest_framework/views.py", line 443, in handle_exception
    self.raise_uncaught_exception(exc)
  File "/home/python/.virtualenvs/django_py3_11/lib/python3.5/site-packages/rest_framework/views.py", line 480, in dispatch
    response = handler(request, *args, **kwargs)
  File "/home/python/.virtualenvs/django_py3_11/lib/python3.5/site-packages/rest_framework/generics.py", line 210, in get
    return self.retrieve(request, *args, **kwargs)
  File "/home/python/.virtualenvs/django_py3_11/lib/python3.5/site-packages/rest_framework/mixins.py", line 58, in retrieve
    return Response(serializer.data)
  File "/home/python/.virtualenvs/django_py3_11/lib/python3.5/site-packages/rest_framework/serializers.py", line 560, in data
    ret = super(Serializer, self).data
  File "/home/python/.virtualenvs/django_py3_11/lib/python3.5/site-packages/rest_framework/serializers.py", line 262, in data
    self._data = self.to_representation(self.instance)
  File "/home/python/.virtualenvs/django_py3_11/lib/python3.5/site-packages/rest_framework/serializers.py", line 510, in to_representation
    fields = self._readable_fields
  File "/home/python/.virtualenvs/django_py3_11/lib/python3.5/site-packages/django/utils/functional.py", line 35, in __get__
    res = instance.__dict__[self.name] = self.func(instance)
  File "/home/python/.virtualenvs/django_py3_11/lib/python3.5/site-packages/rest_framework/serializers.py", line 376, in _readable_fields
    field for field in self.fields.values()
  File "/home/python/.virtualenvs/django_py3_11/lib/python3.5/site-packages/rest_framework/serializers.py", line 363, in fields
    for key, value in self.get_fields().items():
  File "/home/python/.virtualenvs/django_py3_11/lib/python3.5/site-packages/rest_framework/serializers.py", line 1002, in get_fields
    serializer_class=self.__class__.__name__
AssertionError: Class UserDetailSerializer missing "Meta.model" attribute
ERROR 2019-01-02 19:50:12,061 basehttp 124 "GET /user/ HTTP/1.1" 500 19977
INFO 2019-01-02 19:51:53,014 basehttp 124 "GET /oauth/qq/authorization/?next=/ HTTP/1.1" 200 195
INFO 2019-01-02 19:51:58,740 basehttp 124 "GET /oauth/qq/user/?code=87014721E01D88302C47244E57E47054 HTTP/1.1" 200 230
INFO 2019-01-02 19:52:08,895 basehttp 124 "OPTIONS /user/ HTTP/1.1" 200 0
ERROR 2019-01-02 19:52:09,046 exception 135 Internal Server Error: /user/
Traceback (most recent call last):
  File "/home/python/.virtualenvs/django_py3_11/lib/python3.5/site-packages/django/core/handlers/exception.py", line 41, in inner
    response = get_response(request)
  File "/home/python/.virtualenvs/django_py3_11/lib/python3.5/site-packages/django/core/handlers/base.py", line 187, in _get_response
    response = self.process_exception_by_middleware(e, request)
  File "/home/python/.virtualenvs/django_py3_11/lib/python3.5/site-packages/django/core/handlers/base.py", line 185, in _get_response
    response = wrapped_callback(request, *callback_args, **callback_kwargs)
  File "/home/python/.virtualenvs/django_py3_11/lib/python3.5/site-packages/django/views/decorators/csrf.py", line 58, in wrapped_view
    return view_func(*args, **kwargs)
  File "/home/python/.virtualenvs/django_py3_11/lib/python3.5/site-packages/django/views/generic/base.py", line 68, in view
    return self.dispatch(request, *args, **kwargs)
  File "/home/python/.virtualenvs/django_py3_11/lib/python3.5/site-packages/rest_framework/views.py", line 483, in dispatch
    response = self.handle_exception(exc)
  File "/home/python/.virtualenvs/django_py3_11/lib/python3.5/site-packages/rest_framework/views.py", line 443, in handle_exception
    self.raise_uncaught_exception(exc)
  File "/home/python/.virtualenvs/django_py3_11/lib/python3.5/site-packages/rest_framework/views.py", line 480, in dispatch
    response = handler(request, *args, **kwargs)
  File "/home/python/.virtualenvs/django_py3_11/lib/python3.5/site-packages/rest_framework/generics.py", line 210, in get
    return self.retrieve(request, *args, **kwargs)
  File "/home/python/.virtualenvs/django_py3_11/lib/python3.5/site-packages/rest_framework/mixins.py", line 58, in retrieve
    return Response(serializer.data)
  File "/home/python/.virtualenvs/django_py3_11/lib/python3.5/site-packages/rest_framework/serializers.py", line 560, in data
    ret = super(Serializer, self).data
  File "/home/python/.virtualenvs/django_py3_11/lib/python3.5/site-packages/rest_framework/serializers.py", line 262, in data
    self._data = self.to_representation(self.instance)
  File "/home/python/.virtualenvs/django_py3_11/lib/python3.5/site-packages/rest_framework/serializers.py", line 510, in to_representation
    fields = self._readable_fields
  File "/home/python/.virtualenvs/django_py3_11/lib/python3.5/site-packages/django/utils/functional.py", line 35, in __get__
    res = instance.__dict__[self.name] = self.func(instance)
  File "/home/python/.virtualenvs/django_py3_11/lib/python3.5/site-packages/rest_framework/serializers.py", line 376, in _readable_fields
    field for field in self.fields.values()
  File "/home/python/.virtualenvs/django_py3_11/lib/python3.5/site-packages/rest_framework/serializers.py", line 363, in fields
    for key, value in self.get_fields().items():
  File "/home/python/.virtualenvs/django_py3_11/lib/python3.5/site-packages/rest_framework/serializers.py", line 1002, in get_fields
    serializer_class=self.__class__.__name__
AssertionError: Class UserDetailSerializer missing "Meta.model" attribute
ERROR 2019-01-02 19:52:09,167 basehttp 124 "GET /user/ HTTP/1.1" 500 19977
ERROR 2019-01-02 19:53:13,540 exception 135 Internal Server Error: /user/
Traceback (most recent call last):
  File "/home/python/.virtualenvs/django_py3_11/lib/python3.5/site-packages/django/core/handlers/exception.py", line 41, in inner
    response = get_response(request)
  File "/home/python/.virtualenvs/django_py3_11/lib/python3.5/site-packages/django/core/handlers/base.py", line 187, in _get_response
    response = self.process_exception_by_middleware(e, request)
  File "/home/python/.virtualenvs/django_py3_11/lib/python3.5/site-packages/django/core/handlers/base.py", line 185, in _get_response
    response = wrapped_callback(request, *callback_args, **callback_kwargs)
  File "/home/python/.virtualenvs/django_py3_11/lib/python3.5/site-packages/django/views/decorators/csrf.py", line 58, in wrapped_view
    return view_func(*args, **kwargs)
  File "/home/python/.virtualenvs/django_py3_11/lib/python3.5/site-packages/django/views/generic/base.py", line 68, in view
    return self.dispatch(request, *args, **kwargs)
  File "/home/python/.virtualenvs/django_py3_11/lib/python3.5/site-packages/rest_framework/views.py", line 483, in dispatch
    response = self.handle_exception(exc)
  File "/home/python/.virtualenvs/django_py3_11/lib/python3.5/site-packages/rest_framework/views.py", line 443, in handle_exception
    self.raise_uncaught_exception(exc)
  File "/home/python/.virtualenvs/django_py3_11/lib/python3.5/site-packages/rest_framework/views.py", line 480, in dispatch
    response = handler(request, *args, **kwargs)
  File "/home/python/.virtualenvs/django_py3_11/lib/python3.5/site-packages/rest_framework/generics.py", line 210, in get
    return self.retrieve(request, *args, **kwargs)
  File "/home/python/.virtualenvs/django_py3_11/lib/python3.5/site-packages/rest_framework/mixins.py", line 58, in retrieve
    return Response(serializer.data)
  File "/home/python/.virtualenvs/django_py3_11/lib/python3.5/site-packages/rest_framework/serializers.py", line 560, in data
    ret = super(Serializer, self).data
  File "/home/python/.virtualenvs/django_py3_11/lib/python3.5/site-packages/rest_framework/serializers.py", line 262, in data
    self._data = self.to_representation(self.instance)
  File "/home/python/.virtualenvs/django_py3_11/lib/python3.5/site-packages/rest_framework/serializers.py", line 510, in to_representation
    fields = self._readable_fields
  File "/home/python/.virtualenvs/django_py3_11/lib/python3.5/site-packages/django/utils/functional.py", line 35, in __get__
    res = instance.__dict__[self.name] = self.func(instance)
  File "/home/python/.virtualenvs/django_py3_11/lib/python3.5/site-packages/rest_framework/serializers.py", line 376, in _readable_fields
    field for field in self.fields.values()
  File "/home/python/.virtualenvs/django_py3_11/lib/python3.5/site-packages/rest_framework/serializers.py", line 363, in fields
    for key, value in self.get_fields().items():
  File "/home/python/.virtualenvs/django_py3_11/lib/python3.5/site-packages/rest_framework/serializers.py", line 1002, in get_fields
    serializer_class=self.__class__.__name__
AssertionError: Class UserDetailSerializer missing "Meta.model" attribute
ERROR 2019-01-02 19:53:13,580 basehttp 124 "GET /user/ HTTP/1.1" 500 20068
INFO 2019-01-02 19:53:23,984 basehttp 124 "GET /usernames/17612345678/count/ HTTP/1.1" 200 36
INFO 2019-01-02 19:53:39,108 basehttp 124 "GET /mobiles/17612345678/count/ HTTP/1.1" 200 34
INFO 2019-01-02 19:53:50,500 basehttp 124 "GET /mobiles/17612345678/count/ HTTP/1.1" 200 34
INFO 2019-01-02 19:53:56,308 basehttp 124 "GET /usernames/python111/count/ HTTP/1.1" 200 34
INFO 2019-01-02 19:54:12,576 basehttp 124 "GET /mobiles/17612341234/count/ HTTP/1.1" 200 34
INFO 2019-01-02 19:54:13,711 basehttp 124 "GET /mobiles/17612341234/count/ HTTP/1.1" 200 34
INFO 2019-01-02 19:54:13,849 views 42 短信验证码内容为: 445041
INFO 2019-01-02 19:54:16,035 basehttp 124 "GET /sms_codes/17612341234/ HTTP/1.1" 200 16
INFO 2019-01-02 19:54:28,573 basehttp 124 "OPTIONS /users/ HTTP/1.1" 200 0
INFO 2019-01-02 19:54:28,735 basehttp 124 "GET /mobiles/17612341234/count/ HTTP/1.1" 200 34
INFO 2019-01-02 19:54:28,753 basehttp 124 "GET /usernames/python111/count/ HTTP/1.1" 200 34
INFO 2019-01-02 19:54:28,928 basehttp 124 "POST /users/ HTTP/1.1" 201 232
ERROR 2019-01-02 19:54:36,161 exception 135 Internal Server Error: /user/
Traceback (most recent call last):
  File "/home/python/.virtualenvs/django_py3_11/lib/python3.5/site-packages/django/core/handlers/exception.py", line 41, in inner
    response = get_response(request)
  File "/home/python/.virtualenvs/django_py3_11/lib/python3.5/site-packages/django/core/handlers/base.py", line 187, in _get_response
    response = self.process_exception_by_middleware(e, request)
  File "/home/python/.virtualenvs/django_py3_11/lib/python3.5/site-packages/django/core/handlers/base.py", line 185, in _get_response
    response = wrapped_callback(request, *callback_args, **callback_kwargs)
  File "/home/python/.virtualenvs/django_py3_11/lib/python3.5/site-packages/django/views/decorators/csrf.py", line 58, in wrapped_view
    return view_func(*args, **kwargs)
  File "/home/python/.virtualenvs/django_py3_11/lib/python3.5/site-packages/django/views/generic/base.py", line 68, in view
    return self.dispatch(request, *args, **kwargs)
  File "/home/python/.virtualenvs/django_py3_11/lib/python3.5/site-packages/rest_framework/views.py", line 483, in dispatch
    response = self.handle_exception(exc)
  File "/home/python/.virtualenvs/django_py3_11/lib/python3.5/site-packages/rest_framework/views.py", line 443, in handle_exception
    self.raise_uncaught_exception(exc)
  File "/home/python/.virtualenvs/django_py3_11/lib/python3.5/site-packages/rest_framework/views.py", line 480, in dispatch
    response = handler(request, *args, **kwargs)
  File "/home/python/.virtualenvs/django_py3_11/lib/python3.5/site-packages/rest_framework/generics.py", line 210, in get
    return self.retrieve(request, *args, **kwargs)
  File "/home/python/.virtualenvs/django_py3_11/lib/python3.5/site-packages/rest_framework/mixins.py", line 58, in retrieve
    return Response(serializer.data)
  File "/home/python/.virtualenvs/django_py3_11/lib/python3.5/site-packages/rest_framework/serializers.py", line 560, in data
    ret = super(Serializer, self).data
  File "/home/python/.virtualenvs/django_py3_11/lib/python3.5/site-packages/rest_framework/serializers.py", line 262, in data
    self._data = self.to_representation(self.instance)
  File "/home/python/.virtualenvs/django_py3_11/lib/python3.5/site-packages/rest_framework/serializers.py", line 510, in to_representation
    fields = self._readable_fields
  File "/home/python/.virtualenvs/django_py3_11/lib/python3.5/site-packages/django/utils/functional.py", line 35, in __get__
    res = instance.__dict__[self.name] = self.func(instance)
  File "/home/python/.virtualenvs/django_py3_11/lib/python3.5/site-packages/rest_framework/serializers.py", line 376, in _readable_fields
    field for field in self.fields.values()
  File "/home/python/.virtualenvs/django_py3_11/lib/python3.5/site-packages/rest_framework/serializers.py", line 363, in fields
    for key, value in self.get_fields().items():
  File "/home/python/.virtualenvs/django_py3_11/lib/python3.5/site-packages/rest_framework/serializers.py", line 1002, in get_fields
    serializer_class=self.__class__.__name__
AssertionError: Class UserDetailSerializer missing "Meta.model" attribute
ERROR 2019-01-02 19:54:36,246 basehttp 124 "GET /user/ HTTP/1.1" 500 20097
ERROR 2019-01-02 19:57:17,580 exception 135 Internal Server Error: /user/
Traceback (most recent call last):
  File "/home/python/.virtualenvs/django_py3_11/lib/python3.5/site-packages/django/core/handlers/exception.py", line 41, in inner
    response = get_response(request)
  File "/home/python/.virtualenvs/django_py3_11/lib/python3.5/site-packages/django/core/handlers/base.py", line 187, in _get_response
    response = self.process_exception_by_middleware(e, request)
  File "/home/python/.virtualenvs/django_py3_11/lib/python3.5/site-packages/django/core/handlers/base.py", line 185, in _get_response
    response = wrapped_callback(request, *callback_args, **callback_kwargs)
  File "/home/python/.virtualenvs/django_py3_11/lib/python3.5/site-packages/django/views/decorators/csrf.py", line 58, in wrapped_view
    return view_func(*args, **kwargs)
  File "/home/python/.virtualenvs/django_py3_11/lib/python3.5/site-packages/django/views/generic/base.py", line 68, in view
    return self.dispatch(request, *args, **kwargs)
  File "/home/python/.virtualenvs/django_py3_11/lib/python3.5/site-packages/rest_framework/views.py", line 483, in dispatch
    response = self.handle_exception(exc)
  File "/home/python/.virtualenvs/django_py3_11/lib/python3.5/site-packages/rest_framework/views.py", line 443, in handle_exception
    self.raise_uncaught_exception(exc)
  File "/home/python/.virtualenvs/django_py3_11/lib/python3.5/site-packages/rest_framework/views.py", line 480, in dispatch
    response = handler(request, *args, **kwargs)
  File "/home/python/.virtualenvs/django_py3_11/lib/python3.5/site-packages/rest_framework/generics.py", line 210, in get
    return self.retrieve(request, *args, **kwargs)
  File "/home/python/.virtualenvs/django_py3_11/lib/python3.5/site-packages/rest_framework/mixins.py", line 58, in retrieve
    return Response(serializer.data)
  File "/home/python/.virtualenvs/django_py3_11/lib/python3.5/site-packages/rest_framework/serializers.py", line 560, in data
    ret = super(Serializer, self).data
  File "/home/python/.virtualenvs/django_py3_11/lib/python3.5/site-packages/rest_framework/serializers.py", line 262, in data
    self._data = self.to_representation(self.instance)
  File "/home/python/.virtualenvs/django_py3_11/lib/python3.5/site-packages/rest_framework/serializers.py", line 510, in to_representation
    fields = self._readable_fields
  File "/home/python/.virtualenvs/django_py3_11/lib/python3.5/site-packages/django/utils/functional.py", line 35, in __get__
    res = instance.__dict__[self.name] = self.func(instance)
  File "/home/python/.virtualenvs/django_py3_11/lib/python3.5/site-packages/rest_framework/serializers.py", line 376, in _readable_fields
    field for field in self.fields.values()
  File "/home/python/.virtualenvs/django_py3_11/lib/python3.5/site-packages/rest_framework/serializers.py", line 363, in fields
    for key, value in self.get_fields().items():
  File "/home/python/.virtualenvs/django_py3_11/lib/python3.5/site-packages/rest_framework/serializers.py", line 1002, in get_fields
    serializer_class=self.__class__.__name__
AssertionError: Class UserDetailSerializer missing "Meta.model" attribute
ERROR 2019-01-02 19:57:17,620 basehttp 124 "GET /user/ HTTP/1.1" 500 20097
INFO 2019-01-02 19:57:57,524 basehttp 124 "GET /usernames/17812341234/count/ HTTP/1.1" 200 36
INFO 2019-01-02 19:58:12,596 basehttp 124 "GET /mobiles/17812341234/count/ HTTP/1.1" 200 34
INFO 2019-01-02 19:58:12,649 views 42 短信验证码内容为: 916621
INFO 2019-01-02 19:58:12,675 basehttp 124 "GET /mobiles/17812341234/count/ HTTP/1.1" 200 34
INFO 2019-01-02 19:58:12,859 basehttp 124 "GET /sms_codes/17812341234/ HTTP/1.1" 200 16
INFO 2019-01-02 19:58:29,812 basehttp 124 "GET /usernames/17812341234/count/ HTTP/1.1" 200 36
INFO 2019-01-02 19:58:29,817 basehttp 124 "GET /mobiles/17812341234/count/ HTTP/1.1" 200 34
INFO 2019-01-02 19:58:29,862 basehttp 124 "POST /users/ HTTP/1.1" 201 236
ERROR 2019-01-02 19:58:32,723 exception 135 Internal Server Error: /user/
Traceback (most recent call last):
  File "/home/python/.virtualenvs/django_py3_11/lib/python3.5/site-packages/django/core/handlers/exception.py", line 41, in inner
    response = get_response(request)
  File "/home/python/.virtualenvs/django_py3_11/lib/python3.5/site-packages/django/core/handlers/base.py", line 187, in _get_response
    response = self.process_exception_by_middleware(e, request)
  File "/home/python/.virtualenvs/django_py3_11/lib/python3.5/site-packages/django/core/handlers/base.py", line 185, in _get_response
    response = wrapped_callback(request, *callback_args, **callback_kwargs)
  File "/home/python/.virtualenvs/django_py3_11/lib/python3.5/site-packages/django/views/decorators/csrf.py", line 58, in wrapped_view
    return view_func(*args, **kwargs)
  File "/home/python/.virtualenvs/django_py3_11/lib/python3.5/site-packages/django/views/generic/base.py", line 68, in view
    return self.dispatch(request, *args, **kwargs)
  File "/home/python/.virtualenvs/django_py3_11/lib/python3.5/site-packages/rest_framework/views.py", line 483, in dispatch
    response = self.handle_exception(exc)
  File "/home/python/.virtualenvs/django_py3_11/lib/python3.5/site-packages/rest_framework/views.py", line 443, in handle_exception
    self.raise_uncaught_exception(exc)
  File "/home/python/.virtualenvs/django_py3_11/lib/python3.5/site-packages/rest_framework/views.py", line 480, in dispatch
    response = handler(request, *args, **kwargs)
  File "/home/python/.virtualenvs/django_py3_11/lib/python3.5/site-packages/rest_framework/generics.py", line 210, in get
    return self.retrieve(request, *args, **kwargs)
  File "/home/python/.virtualenvs/django_py3_11/lib/python3.5/site-packages/rest_framework/mixins.py", line 58, in retrieve
    return Response(serializer.data)
  File "/home/python/.virtualenvs/django_py3_11/lib/python3.5/site-packages/rest_framework/serializers.py", line 560, in data
    ret = super(Serializer, self).data
  File "/home/python/.virtualenvs/django_py3_11/lib/python3.5/site-packages/rest_framework/serializers.py", line 262, in data
    self._data = self.to_representation(self.instance)
  File "/home/python/.virtualenvs/django_py3_11/lib/python3.5/site-packages/rest_framework/serializers.py", line 510, in to_representation
    fields = self._readable_fields
  File "/home/python/.virtualenvs/django_py3_11/lib/python3.5/site-packages/django/utils/functional.py", line 35, in __get__
    res = instance.__dict__[self.name] = self.func(instance)
  File "/home/python/.virtualenvs/django_py3_11/lib/python3.5/site-packages/rest_framework/serializers.py", line 376, in _readable_fields
    field for field in self.fields.values()
  File "/home/python/.virtualenvs/django_py3_11/lib/python3.5/site-packages/rest_framework/serializers.py", line 363, in fields
    for key, value in self.get_fields().items():
  File "/home/python/.virtualenvs/django_py3_11/lib/python3.5/site-packages/rest_framework/serializers.py", line 1002, in get_fields
    serializer_class=self.__class__.__name__
AssertionError: Class UserDetailSerializer missing "Meta.model" attribute
ERROR 2019-01-02 19:58:32,808 basehttp 124 "GET /user/ HTTP/1.1" 500 20101
INFO 2019-01-02 20:04:17,099 basehttp 124 "OPTIONS /user/ HTTP/1.1" 200 0
INFO 2019-01-02 20:04:17,621 basehttp 124 "GET /user/ HTTP/1.1" 200 65
INFO 2019-01-02 20:04:55,061 basehttp 124 "OPTIONS /authorizations/ HTTP/1.1" 200 0
INFO 2019-01-02 20:04:55,182 basehttp 124 "POST /authorizations/ HTTP/1.1" 200 218
INFO 2019-01-02 20:04:57,660 basehttp 124 "GET /user/ HTTP/1.1" 200 65
INFO 2019-01-02 20:07:15,691 basehttp 124 "GET /user/ HTTP/1.1" 200 65
INFO 2019-01-02 20:11:06,132 basehttp 124 "OPTIONS /user/ HTTP/1.1" 200 0
INFO 2019-01-02 20:11:06,296 basehttp 124 "GET /user/ HTTP/1.1" 200 65
INFO 2019-01-02 20:14:11,353 basehttp 124 "OPTIONS /user/ HTTP/1.1" 200 0
INFO 2019-01-02 20:14:11,514 basehttp 124 "GET /user/ HTTP/1.1" 200 88
WARNING 2019-01-02 21:00:51,399 base 152 Not Found: /
WARNING 2019-01-02 21:00:51,455 basehttp 124 "GET / HTTP/1.1" 404 3077
WARNING 2019-01-02 21:00:57,511 base 152 Not Found: /favicon.ico
WARNING 2019-01-02 21:00:57,512 basehttp 124 "GET /favicon.ico HTTP/1.1" 404 3128
INFO 2019-01-02 21:02:35,292 basehttp 124 "OPTIONS /authorizations/ HTTP/1.1" 200 0
INFO 2019-01-02 21:02:38,278 basehttp 124 "POST /authorizations/ HTTP/1.1" 200 218
INFO 2019-01-02 21:02:38,294 basehttp 124 "POST /authorizations/ HTTP/1.1" 200 218
INFO 2019-01-02 21:02:40,763 basehttp 124 "OPTIONS /user/ HTTP/1.1" 200 0
INFO 2019-01-02 21:02:40,872 basehttp 124 "GET /user/ HTTP/1.1" 200 88
INFO 2019-01-02 22:24:16,769 basehttp 124 "OPTIONS /user/ HTTP/1.1" 200 0
INFO 2019-01-02 22:24:17,166 basehttp 124 "GET /user/ HTTP/1.1" 200 88
INFO 2019-01-02 22:24:42,201 basehttp 124 "OPTIONS /email/ HTTP/1.1" 200 0
INFO 2019-01-02 22:24:46,186 basehttp 124 "PUT /email/ HTTP/1.1" 200 41
INFO 2019-01-02 22:33:58,208 basehttp 124 "GET /user/ HTTP/1.1" 200 110
INFO 2019-01-02 22:34:00,108 basehttp 124 "PUT /email/ HTTP/1.1" 200 41
INFO 2019-01-02 22:38:27,266 basehttp 124 "OPTIONS /user/ HTTP/1.1" 200 0
INFO 2019-01-02 22:38:27,398 basehttp 124 "GET /user/ HTTP/1.1" 200 110
INFO 2019-01-02 22:38:28,774 basehttp 124 "OPTIONS /email/ HTTP/1.1" 200 0
INFO 2019-01-02 22:38:29,049 basehttp 124 "PUT /email/ HTTP/1.1" 200 41
INFO 2019-01-02 22:46:19,452 basehttp 124 "GET /user/ HTTP/1.1" 200 110
INFO 2019-01-02 22:46:21,089 basehttp 124 "PUT /email/ HTTP/1.1" 200 41
INFO 2019-01-02 22:47:22,265 basehttp 124 "GET /user/ HTTP/1.1" 200 110
INFO 2019-01-02 22:47:24,525 basehttp 124 "PUT /email/ HTTP/1.1" 200 41
INFO 2019-01-02 22:48:48,249 basehttp 124 "OPTIONS /user/ HTTP/1.1" 200 0
INFO 2019-01-02 22:48:48,347 basehttp 124 "GET /user/ HTTP/1.1" 200 110
INFO 2019-01-02 22:48:49,830 basehttp 124 "OPTIONS /email/ HTTP/1.1" 200 0
INFO 2019-01-02 22:48:49,970 basehttp 124 "PUT /email/ HTTP/1.1" 200 41
INFO 2019-01-02 22:49:13,389 basehttp 124 "GET /user/ HTTP/1.1" 200 110
INFO 2019-01-02 22:49:15,029 basehttp 124 "PUT /email/ HTTP/1.1" 200 41
INFO 2019-01-02 22:50:02,943 basehttp 124 "GET /user/ HTTP/1.1" 200 110
INFO 2019-01-02 22:50:04,227 basehttp 124 "PUT /email/ HTTP/1.1" 200 41
INFO 2019-01-02 22:53:03,604 basehttp 124 "GET /user/ HTTP/1.1" 200 110
INFO 2019-01-02 22:53:04,745 basehttp 124 "PUT /email/ HTTP/1.1" 200 41
INFO 2019-01-02 22:58:12,652 basehttp 124 "GET /user/ HTTP/1.1" 200 110
INFO 2019-01-02 22:58:14,144 basehttp 124 "PUT /email/ HTTP/1.1" 200 41
INFO 2019-01-03 00:27:06,690 basehttp 124 "OPTIONS /authorizations/ HTTP/1.1" 200 0
INFO 2019-01-03 00:27:06,914 basehttp 124 "POST /authorizations/ HTTP/1.1" 200 248
INFO 2019-01-03 00:27:10,994 basehttp 124 "OPTIONS /user/ HTTP/1.1" 200 0
INFO 2019-01-03 00:27:11,092 basehttp 124 "GET /user/ HTTP/1.1" 200 110
INFO 2019-01-03 00:27:14,068 basehttp 124 "OPTIONS /email/ HTTP/1.1" 200 0
INFO 2019-01-03 00:27:14,817 basehttp 124 "PUT /email/ HTTP/1.1" 200 41
INFO 2019-01-03 00:27:37,795 basehttp 124 "OPTIONS /emails/verification/?token=eyJhbGciOiJIUzI1NiIsImV4cCI6MTU0NjQ1MzYzNCwiaWF0IjoxNTQ2NDQ2NDM0fQ.eyJlbWFpbCI6InNzXzIyenhtOTY4NzEyQDE2My5jb20iLCJpZCI6NX0.C-7EfDwWMl92-O_xY_NF25Tldg5apYMvtDxD_TDhQn4 HTTP/1.1" 200 0
INFO 2019-01-03 00:31:49,331 basehttp 124 "GET /user/ HTTP/1.1" 200 110
INFO 2019-01-03 00:31:51,800 basehttp 124 "PUT /email/ HTTP/1.1" 200 41
INFO 2019-01-03 00:32:20,775 basehttp 124 "OPTIONS /emails/verification/?token=eyJhbGciOiJIUzI1NiIsImV4cCI6MTU0NjQ1MzkxMSwiaWF0IjoxNTQ2NDQ2NzExfQ.eyJlbWFpbCI6InNzXzIyenhtOTY4NzEyQDE2My5jb20iLCJpZCI6NX0.Eej3QYZLNTmmNHHCTYc6tk1QkH9EjC8dvKU4ODksjyo HTTP/1.1" 200 0
INFO 2019-01-03 00:34:22,263 basehttp 124 "GET /user/ HTTP/1.1" 200 110
INFO 2019-01-03 00:34:25,950 basehttp 124 "PUT /email/ HTTP/1.1" 200 41
INFO 2019-01-03 00:34:39,294 basehttp 124 "OPTIONS /emails/verification/?token=eyJpYXQiOjE1NDY0NDY4NjQsImFsZyI6IkhTMjU2IiwiZXhwIjoxNTQ2NDU0MDY0fQ.eyJlbWFpbCI6InNzXzIyenhtOTY4NzEyQDE2My5jb20iLCJpZCI6NX0.hrBXIgkJpa1nbL48o4fx3CaEU-5Smf4pjD90xomwsMo HTTP/1.1" 200 0
INFO 2019-01-03 18:47:47,033 basehttp 124 "OPTIONS /authorizations/ HTTP/1.1" 200 0
INFO 2019-01-03 18:47:48,264 basehttp 124 "POST /authorizations/ HTTP/1.1" 200 248
INFO 2019-01-03 18:47:52,006 basehttp 124 "OPTIONS /user/ HTTP/1.1" 200 0
INFO 2019-01-03 18:47:52,130 basehttp 124 "GET /user/ HTTP/1.1" 200 110
INFO 2019-01-03 18:47:53,280 basehttp 124 "OPTIONS /email/ HTTP/1.1" 200 0
INFO 2019-01-03 18:47:53,681 basehttp 124 "PUT /email/ HTTP/1.1" 200 41
INFO 2019-01-03 18:50:14,984 basehttp 124 "GET /user/ HTTP/1.1" 200 110
INFO 2019-01-03 18:50:16,893 basehttp 124 "PUT /email/ HTTP/1.1" 200 41
INFO 2019-01-03 18:51:34,191 basehttp 124 "GET /user/ HTTP/1.1" 200 110
INFO 2019-01-03 18:52:17,230 basehttp 124 "GET /user/ HTTP/1.1" 200 110
INFO 2019-01-03 18:53:25,179 basehttp 124 "PUT /email/ HTTP/1.1" 200 41
INFO 2019-01-03 18:56:06,522 basehttp 124 "GET /user/ HTTP/1.1" 200 110
INFO 2019-01-03 18:57:28,975 basehttp 124 "GET /user/ HTTP/1.1" 200 110
INFO 2019-01-03 18:59:07,001 basehttp 124 "OPTIONS /user/ HTTP/1.1" 200 0
INFO 2019-01-03 18:59:07,070 basehttp 124 "GET /user/ HTTP/1.1" 200 110
INFO 2019-01-03 18:59:08,582 basehttp 124 "OPTIONS /email/ HTTP/1.1" 200 0
INFO 2019-01-03 18:59:08,880 basehttp 124 "PUT /email/ HTTP/1.1" 200 41
INFO 2019-01-03 19:00:41,904 basehttp 124 "GET /user/ HTTP/1.1" 200 110
INFO 2019-01-03 19:00:43,921 basehttp 124 "PUT /email/ HTTP/1.1" 200 41
INFO 2019-01-03 19:00:56,722 basehttp 124 "OPTIONS /emails/verification/?token=eyJhbGciOiJIUzI1NiIsImlhdCI6MTU0NjUxMzI0MywiZXhwIjoxNTQ2NTIwNDQzfQ.eyJlbWFpbCI6InNzXzIyenhtOTY4NzEyQDE2My5jb20iLCJpZCI6NX0.d7W1bBoHcZNzOoUima7s8IvoCdPLol4bqR4A4FQETqo HTTP/1.1" 200 0
INFO 2019-01-03 19:02:23,658 basehttp 124 "GET /user/ HTTP/1.1" 200 110
INFO 2019-01-03 19:02:54,531 basehttp 124 "PUT /email/ HTTP/1.1" 200 41
INFO 2019-01-03 19:04:53,405 basehttp 124 "OPTIONS /emails/verification/?token=eyJleHAiOjE1NDY1MjA1NjcsImlhdCI6MTU0NjUxMzM2NywiYWxnIjoiSFMyNTYifQ.eyJpZCI6NSwiZW1haWwiOiJzc18yMnp4bTk2ODcxMkAxNjMuY29tIn0.29wEujHu8oqcAw1wZaJymshl4ioyPhHW3O9K-wDSNKU HTTP/1.1" 200 0
INFO 2019-01-03 19:07:17,330 basehttp 124 "OPTIONS /emails/verification/?token=eyJleHAiOjE1NDY1MjA1NjcsImlhdCI6MTU0NjUxMzM2NywiYWxnIjoiSFMyNTYifQ.eyJpZCI6NSwiZW1haWwiOiJzc18yMnp4bTk2ODcxMkAxNjMuY29tIn0.29wEujHu8oqcAw1wZaJymshl4ioyPhHW3O9K-wDSNKU HTTP/1.1" 200 0
INFO 2019-01-03 19:08:11,990 basehttp 124 "OPTIONS /emails/verification/?token=eyJleHAiOjE1NDY1MjA1NjcsImlhdCI6MTU0NjUxMzM2NywiYWxnIjoiSFMyNTYifQ.eyJpZCI6NSwiZW1haWwiOiJzc18yMnp4bTk2ODcxMkAxNjMuY29tIn0.29wEujHu8oqcAw1wZaJymshl4ioyPhHW3O9K-wDSNKU HTTP/1.1" 200 0
INFO 2019-01-03 19:08:19,181 basehttp 124 "OPTIONS /emails/verification/?token=eyJleHAiOjE1NDY1MjA1NjcsImlhdCI6MTU0NjUxMzM2NywiYWxnIjoiSFMyNTYifQ.eyJpZCI6NSwiZW1haWwiOiJzc18yMnp4bTk2ODcxMkAxNjMuY29tIn0.29wEujHu8oqcAw1wZaJymshl4ioyPhHW3O9K-wDSNKU HTTP/1.1" 200 0
INFO 2019-01-03 19:10:06,874 basehttp 124 "OPTIONS /emails/verification/?token=eyJleHAiOjE1NDY1MjA1NjcsImlhdCI6MTU0NjUxMzM2NywiYWxnIjoiSFMyNTYifQ.eyJpZCI6NSwiZW1haWwiOiJzc18yMnp4bTk2ODcxMkAxNjMuY29tIn0.29wEujHu8oqcAw1wZaJymshl4ioyPhHW3O9K-wDSNKU HTTP/1.1" 200 0
INFO 2019-01-03 19:14:10,077 basehttp 124 "OPTIONS /user/ HTTP/1.1" 200 0
INFO 2019-01-03 19:14:10,113 basehttp 124 "OPTIONS /emails/verification/?token=eyJleHAiOjE1NDY1MjA1NjcsImlhdCI6MTU0NjUxMzM2NywiYWxnIjoiSFMyNTYifQ.eyJpZCI6NSwiZW1haWwiOiJzc18yMnp4bTk2ODcxMkAxNjMuY29tIn0.29wEujHu8oqcAw1wZaJymshl4ioyPhHW3O9K-wDSNKU HTTP/1.1" 200 0
INFO 2019-01-03 19:14:10,262 basehttp 124 "GET /user/ HTTP/1.1" 200 110
INFO 2019-01-03 19:14:23,820 basehttp 124 "OPTIONS /emails/verification/?token=eyJleHAiOjE1NDY1MjA1NjcsImlhdCI6MTU0NjUxMzM2NywiYWxnIjoiSFMyNTYifQ.eyJpZCI6NSwiZW1haWwiOiJzc18yMnp4bTk2ODcxMkAxNjMuY29tIn0.29wEujHu8oqcAw1wZaJymshl4ioyPhHW3O9K-wDSNKU HTTP/1.1" 200 0
INFO 2019-01-03 19:14:24,054 basehttp 124 "GET /user/ HTTP/1.1" 200 110
INFO 2019-01-03 19:14:25,306 basehttp 124 "OPTIONS /emails/verification/?token=eyJleHAiOjE1NDY1MjA1NjcsImlhdCI6MTU0NjUxMzM2NywiYWxnIjoiSFMyNTYifQ.eyJpZCI6NSwiZW1haWwiOiJzc18yMnp4bTk2ODcxMkAxNjMuY29tIn0.29wEujHu8oqcAw1wZaJymshl4ioyPhHW3O9K-wDSNKU HTTP/1.1" 200 0
INFO 2019-01-03 19:14:25,527 basehttp 124 "GET /user/ HTTP/1.1" 200 110
INFO 2019-01-03 19:14:26,907 basehttp 124 "GET /user/ HTTP/1.1" 200 110
INFO 2019-01-03 19:14:26,910 basehttp 124 "OPTIONS /emails/verification/?token=eyJleHAiOjE1NDY1MjA1NjcsImlhdCI6MTU0NjUxMzM2NywiYWxnIjoiSFMyNTYifQ.eyJpZCI6NSwiZW1haWwiOiJzc18yMnp4bTk2ODcxMkAxNjMuY29tIn0.29wEujHu8oqcAw1wZaJymshl4ioyPhHW3O9K-wDSNKU HTTP/1.1" 200 0
INFO 2019-01-03 19:14:44,127 basehttp 124 "OPTIONS /emails/verification/?token=eyJleHAiOjE1NDY1MjA1NjcsImlhdCI6MTU0NjUxMzM2NywiYWxnIjoiSFMyNTYifQ.eyJpZCI6NSwiZW1haWwiOiJzc18yMnp4bTk2ODcxMkAxNjMuY29tIn0.29wEujHu8oqcAw1wZaJymshl4ioyPhHW3O9K-wDSNKU HTTP/1.1" 200 0
INFO 2019-01-03 19:15:41,420 basehttp 124 "GET /user/ HTTP/1.1" 200 110
INFO 2019-01-03 19:15:43,566 basehttp 124 "OPTIONS /email/ HTTP/1.1" 200 0
INFO 2019-01-03 19:15:44,124 basehttp 124 "PUT /email/ HTTP/1.1" 200 41
INFO 2019-01-03 19:15:53,777 basehttp 124 "OPTIONS /emails/verification/?token=eyJleHAiOjE1NDY1MjEzNDMsImFsZyI6IkhTMjU2IiwiaWF0IjoxNTQ2NTE0MTQzfQ.eyJpZCI6NSwiZW1haWwiOiJzc18yMnp4bTk2ODcxMkAxNjMuY29tIn0.5LnhXHVf7Imh-_6eS-XLY4bVyVccx92rP3rVRqzNRNc HTTP/1.1" 200 0
INFO 2019-01-03 19:16:34,332 basehttp 124 "OPTIONS /emails/verification/?token=eyJleHAiOjE1NDY1MjEzNDMsImFsZyI6IkhTMjU2IiwiaWF0IjoxNTQ2NTE0MTQzfQ.eyJpZCI6NSwiZW1haWwiOiJzc18yMnp4bTk2ODcxMkAxNjMuY29tIn0.5LnhXHVf7Imh-_6eS-XLY4bVyVccx92rP3rVRqzNRNc HTTP/1.1" 200 0
INFO 2019-01-03 19:18:36,383 basehttp 124 "OPTIONS /emails/verification/?token=eyJleHAiOjE1NDY1MjEzNDMsImFsZyI6IkhTMjU2IiwiaWF0IjoxNTQ2NTE0MTQzfQ.eyJpZCI6NSwiZW1haWwiOiJzc18yMnp4bTk2ODcxMkAxNjMuY29tIn0.5LnhXHVf7Imh-_6eS-XLY4bVyVccx92rP3rVRqzNRNc HTTP/1.1" 200 0
INFO 2019-01-03 19:23:10,747 basehttp 124 "GET /user/ HTTP/1.1" 200 110
INFO 2019-01-03 19:23:13,003 basehttp 124 "PUT /email/ HTTP/1.1" 200 41
INFO 2019-01-03 19:23:23,444 basehttp 124 "OPTIONS /emails/verification/?token=eyJpYXQiOjE1NDY1MTQ1OTIsImV4cCI6MTU0NjUyMTc5MiwiYWxnIjoiSFMyNTYifQ.eyJpZCI6NSwiZW1haWwiOiJzc18yMnp4bTk2ODcxMkAxNjMuY29tIn0.T0j6cwxNbvzPGjTa89scwXkLtMLCj0rl7ofA44uFXfY HTTP/1.1" 200 0
INFO 2019-01-03 19:25:10,973 basehttp 124 "OPTIONS /emails/verification/?token=eyJleHAiOjE1NDY1MjEzNDMsImFsZyI6IkhTMjU2IiwiaWF0IjoxNTQ2NTE0MTQzfQ.eyJpZCI6NSwiZW1haWwiOiJzc18yMnp4bTk2ODcxMkAxNjMuY29tIn0.5LnhXHVf7Imh-_6eS-XLY4bVyVccx92rP3rVRqzNRNc HTTP/1.1" 200 0
INFO 2019-01-03 19:25:19,342 basehttp 124 "OPTIONS /user/ HTTP/1.1" 200 0
INFO 2019-01-03 19:25:19,720 basehttp 124 "GET /user/ HTTP/1.1" 200 110
INFO 2019-01-03 19:25:22,053 basehttp 124 "PUT /email/ HTTP/1.1" 200 41
INFO 2019-01-03 19:25:37,366 basehttp 124 "OPTIONS /emails/verification/?token=eyJleHAiOjE1NDY1MjE5MjEsImFsZyI6IkhTMjU2IiwiaWF0IjoxNTQ2NTE0NzIxfQ.eyJpZCI6NSwiZW1haWwiOiJzc18yMnp4bTk2ODcxMkAxNjMuY29tIn0.kWeP0Pky6weQi6djYo58jH-DQjP3Y6SLIuXSKSektcU HTTP/1.1" 200 0
INFO 2019-01-03 19:33:22,877 basehttp 124 "OPTIONS /authorizations/ HTTP/1.1" 200 0
INFO 2019-01-03 19:33:24,377 basehttp 124 "POST /authorizations/ HTTP/1.1" 200 248
INFO 2019-01-03 19:33:26,997 basehttp 124 "OPTIONS /user/ HTTP/1.1" 200 0
INFO 2019-01-03 19:33:27,194 basehttp 124 "GET /user/ HTTP/1.1" 200 110
INFO 2019-01-03 19:33:28,807 basehttp 124 "OPTIONS /email/ HTTP/1.1" 200 0
INFO 2019-01-03 19:33:32,166 basehttp 124 "PUT /email/ HTTP/1.1" 200 41
INFO 2019-01-03 19:34:00,493 basehttp 124 "OPTIONS /emails/verification/?token=eyJleHAiOjE1NDY1MjI0MTIsImFsZyI6IkhTMjU2IiwiaWF0IjoxNTQ2NTE1MjEyfQ.eyJpZCI6NSwiZW1haWwiOiJzc18yMnp4bTk2ODcxMkAxNjMuY29tIn0.eMMZTqfBSn2UngQNzJJE7edJPXeZFnnOaM8f2tDhmn0 HTTP/1.1" 200 0
INFO 2019-01-03 19:37:49,953 basehttp 124 "OPTIONS /authorizations/ HTTP/1.1" 200 0
INFO 2019-01-03 19:37:50,106 basehttp 124 "POST /authorizations/ HTTP/1.1" 200 248
INFO 2019-01-03 19:38:22,361 basehttp 124 "OPTIONS /user/ HTTP/1.1" 200 0
INFO 2019-01-03 19:38:22,504 basehttp 124 "GET /user/ HTTP/1.1" 200 110
INFO 2019-01-03 19:38:24,028 basehttp 124 "OPTIONS /email/ HTTP/1.1" 200 0
INFO 2019-01-03 19:38:25,698 basehttp 124 "PUT /email/ HTTP/1.1" 200 41
INFO 2019-01-03 19:38:44,918 basehttp 124 "OPTIONS /emails/verification/?token=eyJpYXQiOjE1NDY1MTU1MDQsImFsZyI6IkhTMjU2IiwiZXhwIjoxNTQ2NTIyNzA0fQ.eyJlbWFpbCI6InNzXzIyenhtOTY4NzEyQDE2My5jb20iLCJpZCI6NX0.lLOqquhVoLpzFWeqTigBH-v3d4rtoBBncNvJxWsefQE HTTP/1.1" 200 0
INFO 2019-01-03 19:41:24,956 basehttp 124 "GET /user/ HTTP/1.1" 200 110
INFO 2019-01-03 19:41:29,294 basehttp 124 "PUT /email/ HTTP/1.1" 200 41
INFO 2019-01-03 19:41:49,075 basehttp 124 "OPTIONS /emails/verification/?token=eyJleHAiOjE1NDY1MjI4ODYsImlhdCI6MTU0NjUxNTY4NiwiYWxnIjoiSFMyNTYifQ.eyJpZCI6NSwiZW1haWwiOiJzc18yMnp4bTk2ODcxMkAxNjMuY29tIn0.2f51wSV5NcqEOHiGESa8FIQS136tpUNYwtihTAkNpvg HTTP/1.1" 200 0
WARNING 2019-01-03 22:25:00,759 basehttp 124 "PUT /areas/ HTTP/1.1" 405 45
ERROR 2019-01-03 22:25:06,488 exception 135 Internal Server Error: /areas/
Traceback (most recent call last):
  File "/home/python/.virtualenvs/django_py3_11/lib/python3.5/site-packages/django/core/handlers/exception.py", line 41, in inner
    response = get_response(request)
  File "/home/python/.virtualenvs/django_py3_11/lib/python3.5/site-packages/django/core/handlers/base.py", line 187, in _get_response
    response = self.process_exception_by_middleware(e, request)
  File "/home/python/.virtualenvs/django_py3_11/lib/python3.5/site-packages/django/core/handlers/base.py", line 185, in _get_response
    response = wrapped_callback(request, *callback_args, **callback_kwargs)
  File "/home/python/.virtualenvs/django_py3_11/lib/python3.5/site-packages/django/views/decorators/csrf.py", line 58, in wrapped_view
    return view_func(*args, **kwargs)
  File "/home/python/.virtualenvs/django_py3_11/lib/python3.5/site-packages/django/views/generic/base.py", line 68, in view
    return self.dispatch(request, *args, **kwargs)
  File "/home/python/.virtualenvs/django_py3_11/lib/python3.5/site-packages/rest_framework/views.py", line 485, in dispatch
    self.response = self.finalize_response(request, response, *args, **kwargs)
  File "/home/python/.virtualenvs/django_py3_11/lib/python3.5/site-packages/rest_framework/views.py", line 400, in finalize_response
    % type(response)
AssertionError: Expected a `Response`, `HttpResponse` or `HttpStreamingResponse` to be returned from the view, but received a `<class 'NoneType'>`
ERROR 2019-01-03 22:25:07,776 basehttp 124 "GET /areas/ HTTP/1.1" 500 88401
ERROR 2019-01-03 22:30:29,387 exception 135 Internal Server Error: /areas/
Traceback (most recent call last):
  File "/home/python/.virtualenvs/django_py3_11/lib/python3.5/site-packages/django/core/handlers/exception.py", line 41, in inner
    response = get_response(request)
  File "/home/python/.virtualenvs/django_py3_11/lib/python3.5/site-packages/django/core/handlers/base.py", line 187, in _get_response
    response = self.process_exception_by_middleware(e, request)
  File "/home/python/.virtualenvs/django_py3_11/lib/python3.5/site-packages/django/core/handlers/base.py", line 185, in _get_response
    response = wrapped_callback(request, *callback_args, **callback_kwargs)
  File "/home/python/.virtualenvs/django_py3_11/lib/python3.5/site-packages/django/views/decorators/csrf.py", line 58, in wrapped_view
    return view_func(*args, **kwargs)
  File "/home/python/.virtualenvs/django_py3_11/lib/python3.5/site-packages/django/views/generic/base.py", line 68, in view
    return self.dispatch(request, *args, **kwargs)
  File "/home/python/.virtualenvs/django_py3_11/lib/python3.5/site-packages/rest_framework/views.py", line 483, in dispatch
    response = self.handle_exception(exc)
  File "/home/python/.virtualenvs/django_py3_11/lib/python3.5/site-packages/rest_framework/views.py", line 443, in handle_exception
    self.raise_uncaught_exception(exc)
  File "/home/python/.virtualenvs/django_py3_11/lib/python3.5/site-packages/rest_framework/views.py", line 480, in dispatch
    response = handler(request, *args, **kwargs)
  File "/home/python/Desktop/meiduo_test1/meiduo_test/meiduo_test/apps/areas/views.py", line 25, in get
    serializer = self.get_serializer(areas, many=True)
AttributeError: 'AreasView' object has no attribute 'get_serializer'
ERROR 2019-01-03 22:30:29,597 basehttp 124 "GET /areas/ HTTP/1.1" 500 18584
INFO 2019-01-03 22:32:23,487 basehttp 124 "GET /areas/ HTTP/1.1" 200 1204
INFO 2019-01-04 09:53:11,235 basehttp 124 "GET /areas/ HTTP/1.1" 200 1204
INFO 2019-01-04 09:53:32,757 basehttp 124 "GET /areas/?130000/ HTTP/1.1" 200 1204
INFO 2019-01-04 09:54:14,937 basehttp 124 "GET /areas/360000/ HTTP/1.1" 200 407
INFO 2019-01-04 10:11:55,734 basehttp 124 "OPTIONS /authorizations/ HTTP/1.1" 200 0
WARNING 2019-01-04 10:11:55,975 basehttp 124 "POST /authorizations/ HTTP/1.1" 400 67
INFO 2019-01-04 10:12:03,511 basehttp 124 "POST /authorizations/ HTTP/1.1" 200 248
INFO 2019-01-04 10:12:17,111 basehttp 124 "OPTIONS /user/ HTTP/1.1" 200 0
INFO 2019-01-04 10:12:17,281 basehttp 124 "GET /user/ HTTP/1.1" 200 110
INFO 2019-01-04 10:12:21,810 basehttp 124 "GET /areas/ HTTP/1.1" 200 1204
INFO 2019-01-04 10:12:26,818 basehttp 124 "GET /areas/120000/ HTTP/1.1" 200 74
INFO 2019-01-04 10:12:29,228 basehttp 124 "GET /areas/120100/ HTTP/1.1" 200 572
INFO 2019-01-04 10:12:33,250 basehttp 124 "GET /areas/130000/ HTTP/1.1" 200 464
INFO 2019-01-04 10:12:35,242 basehttp 124 "GET /areas/130400/ HTTP/1.1" 200 659
INFO 2019-01-04 10:12:59,429 basehttp 124 "GET /areas/130300/ HTTP/1.1" 200 293
INFO 2019-01-04 11:16:20,835 basehttp 124 "OPTIONS /user/ HTTP/1.1" 200 0
INFO 2019-01-04 11:16:21,364 basehttp 124 "GET /user/ HTTP/1.1" 200 110
INFO 2019-01-04 11:16:23,384 basehttp 124 "GET /areas/ HTTP/1.1" 200 1204
INFO 2019-01-04 11:16:32,663 basehttp 124 "GET /areas/120000/ HTTP/1.1" 200 74
INFO 2019-01-04 11:16:34,818 basehttp 124 "GET /areas/120100/ HTTP/1.1" 200 572
INFO 2019-01-04 11:18:41,755 basehttp 124 "GET /areas/ HTTP/1.1" 200 1204
INFO 2019-01-04 11:18:41,769 basehttp 124 "OPTIONS /addresses/ HTTP/1.1" 200 0
INFO 2019-01-04 11:18:42,013 basehttp 124 "GET /addresses/ HTTP/1.1" 200 65
INFO 2019-01-04 11:18:42,404 basehttp 124 "GET /areas/ HTTP/1.1" 200 1204
INFO 2019-01-04 11:18:42,530 basehttp 124 "GET /addresses/ HTTP/1.1" 200 65
INFO 2019-01-04 11:18:50,711 basehttp 124 "GET /areas/ HTTP/1.1" 200 1204
INFO 2019-01-04 11:18:50,879 basehttp 124 "GET /addresses/ HTTP/1.1" 200 65
INFO 2019-01-04 11:18:51,775 basehttp 124 "GET /areas/ HTTP/1.1" 200 1204
INFO 2019-01-04 11:18:52,247 basehttp 124 "GET /areas/ HTTP/1.1" 200 1204
INFO 2019-01-04 11:18:52,674 basehttp 124 "GET /addresses/ HTTP/1.1" 200 65
INFO 2019-01-04 11:18:52,692 basehttp 124 "GET /addresses/ HTTP/1.1" 200 65
INFO 2019-01-04 11:18:54,323 basehttp 124 "GET /areas/ HTTP/1.1" 200 1204
INFO 2019-01-04 11:18:54,444 basehttp 124 "GET /addresses/ HTTP/1.1" 200 65
INFO 2019-01-04 11:19:05,402 basehttp 124 "GET /areas/130000/ HTTP/1.1" 200 464
INFO 2019-01-04 11:19:07,438 basehttp 124 "GET /areas/130500/ HTTP/1.1" 200 662
INFO 2019-01-04 11:19:27,168 basehttp 124 "POST /addresses/ HTTP/1.1" 201 219
INFO 2019-01-04 11:19:37,480 basehttp 124 "GET /areas/130000/ HTTP/1.1" 200 464
INFO 2019-01-04 11:19:39,177 basehttp 124 "GET /areas/130600/ HTTP/1.1" 200 791
INFO 2019-01-04 11:20:21,630 basehttp 124 "POST /addresses/ HTTP/1.1" 201 219
INFO 2019-01-04 11:20:23,771 basehttp 124 "OPTIONS /addresses/2/status/ HTTP/1.1" 200 0
INFO 2019-01-04 11:20:24,097 basehttp 124 "PUT /addresses/2/status/ HTTP/1.1" 200 16
INFO 2019-01-04 14:35:50,374 basehttp 124 "OPTIONS /authorizations/ HTTP/1.1" 200 0
INFO 2019-01-04 14:35:52,481 basehttp 124 "POST /authorizations/ HTTP/1.1" 200 248
INFO 2019-01-04 14:35:55,366 basehttp 124 "OPTIONS /user/ HTTP/1.1" 200 0
INFO 2019-01-04 14:35:55,545 basehttp 124 "GET /user/ HTTP/1.1" 200 110
INFO 2019-01-04 14:36:06,010 basehttp 124 "OPTIONS /addresses/ HTTP/1.1" 200 0
INFO 2019-01-04 14:36:06,510 basehttp 124 "GET /areas/ HTTP/1.1" 200 1204
INFO 2019-01-04 14:36:06,526 basehttp 124 "GET /addresses/ HTTP/1.1" 200 504
INFO 2019-01-04 14:36:16,171 basehttp 124 "GET /user/ HTTP/1.1" 200 110
INFO 2019-01-04 14:38:51,087 basehttp 124 "OPTIONS /email/ HTTP/1.1" 200 0
INFO 2019-01-04 14:39:02,008 basehttp 124 "PUT /email/ HTTP/1.1" 200 41
INFO 2019-01-04 14:39:02,011 basehttp 124 "PUT /email/ HTTP/1.1" 200 41
INFO 2019-01-04 14:39:22,574 basehttp 124 "OPTIONS /emails/verification/?token=eyJleHAiOjE1NDY1OTExMzMsImlhdCI6MTU0NjU4MzkzMywiYWxnIjoiSFMyNTYifQ.eyJlbWFpbCI6InNzXzIyenhtOTY4NzEyQDE2My5jb20iLCJpZCI6NX0.9gOhuKyE-T54IsoqnvHXNHztmVUyeXM0_LBfRbnWptI HTTP/1.1" 200 0
ERROR 2019-01-04 14:39:23,390 exception 135 Internal Server Error: /emails/verification/
Traceback (most recent call last):
  File "/home/python/.virtualenvs/django_py3_11/lib/python3.5/site-packages/rest_framework/request.py", line 411, in __getattr__
    return getattr(self._request, attr)
AttributeError: 'WSGIRequest' object has no attribute 'query_param'

During handling of the above exception, another exception occurred:

Traceback (most recent call last):
  File "/home/python/.virtualenvs/django_py3_11/lib/python3.5/site-packages/django/core/handlers/exception.py", line 41, in inner
    response = get_response(request)
  File "/home/python/.virtualenvs/django_py3_11/lib/python3.5/site-packages/django/core/handlers/base.py", line 187, in _get_response
    response = self.process_exception_by_middleware(e, request)
  File "/home/python/.virtualenvs/django_py3_11/lib/python3.5/site-packages/django/core/handlers/base.py", line 185, in _get_response
    response = wrapped_callback(request, *callback_args, **callback_kwargs)
  File "/home/python/.virtualenvs/django_py3_11/lib/python3.5/site-packages/django/views/decorators/csrf.py", line 58, in wrapped_view
    return view_func(*args, **kwargs)
  File "/home/python/.virtualenvs/django_py3_11/lib/python3.5/site-packages/django/views/generic/base.py", line 68, in view
    return self.dispatch(request, *args, **kwargs)
  File "/home/python/.virtualenvs/django_py3_11/lib/python3.5/site-packages/rest_framework/views.py", line 483, in dispatch
    response = self.handle_exception(exc)
  File "/home/python/.virtualenvs/django_py3_11/lib/python3.5/site-packages/rest_framework/views.py", line 443, in handle_exception
    self.raise_uncaught_exception(exc)
  File "/home/python/.virtualenvs/django_py3_11/lib/python3.5/site-packages/rest_framework/views.py", line 480, in dispatch
    response = handler(request, *args, **kwargs)
  File "/home/python/Desktop/meiduo_test1/meiduo_test/meiduo_test/apps/users/views.py", line 154, in put
    token = request.query_param.get("token")
  File "/home/python/.virtualenvs/django_py3_11/lib/python3.5/site-packages/rest_framework/request.py", line 413, in __getattr__
    return self.__getattribute__(attr)
AttributeError: 'Request' object has no attribute 'query_param'
ERROR 2019-01-04 14:39:24,392 basehttp 124 "PUT /emails/verification/?token=eyJleHAiOjE1NDY1OTExMzMsImlhdCI6MTU0NjU4MzkzMywiYWxnIjoiSFMyNTYifQ.eyJlbWFpbCI6InNzXzIyenhtOTY4NzEyQDE2My5jb20iLCJpZCI6NX0.9gOhuKyE-T54IsoqnvHXNHztmVUyeXM0_LBfRbnWptI HTTP/1.1" 500 19990
INFO 2019-01-04 14:40:44,332 basehttp 124 "OPTIONS /emails/verification/?token=eyJleHAiOjE1NDY1OTExMzcsImlhdCI6MTU0NjU4MzkzNywiYWxnIjoiSFMyNTYifQ.eyJlbWFpbCI6InNzXzIyenhtOTY4NzEyQDE2My5jb20iLCJpZCI6NX0.Y4lWPeKjVDtk5fHQEig0igxQMOq5pWo1OZvKI5d5pVg HTTP/1.1" 200 0
ERROR 2019-01-04 14:40:44,429 exception 135 Internal Server Error: /emails/verification/
Traceback (most recent call last):
  File "/home/python/.virtualenvs/django_py3_11/lib/python3.5/site-packages/rest_framework/request.py", line 411, in __getattr__
    return getattr(self._request, attr)
AttributeError: 'WSGIRequest' object has no attribute 'query_param'

During handling of the above exception, another exception occurred:

Traceback (most recent call last):
  File "/home/python/.virtualenvs/django_py3_11/lib/python3.5/site-packages/django/core/handlers/exception.py", line 41, in inner
    response = get_response(request)
  File "/home/python/.virtualenvs/django_py3_11/lib/python3.5/site-packages/django/core/handlers/base.py", line 187, in _get_response
    response = self.process_exception_by_middleware(e, request)
  File "/home/python/.virtualenvs/django_py3_11/lib/python3.5/site-packages/django/core/handlers/base.py", line 185, in _get_response
    response = wrapped_callback(request, *callback_args, **callback_kwargs)
  File "/home/python/.virtualenvs/django_py3_11/lib/python3.5/site-packages/django/views/decorators/csrf.py", line 58, in wrapped_view
    return view_func(*args, **kwargs)
  File "/home/python/.virtualenvs/django_py3_11/lib/python3.5/site-packages/django/views/generic/base.py", line 68, in view
    return self.dispatch(request, *args, **kwargs)
  File "/home/python/.virtualenvs/django_py3_11/lib/python3.5/site-packages/rest_framework/views.py", line 483, in dispatch
    response = self.handle_exception(exc)
  File "/home/python/.virtualenvs/django_py3_11/lib/python3.5/site-packages/rest_framework/views.py", line 443, in handle_exception
    self.raise_uncaught_exception(exc)
  File "/home/python/.virtualenvs/django_py3_11/lib/python3.5/site-packages/rest_framework/views.py", line 480, in dispatch
    response = handler(request, *args, **kwargs)
  File "/home/python/Desktop/meiduo_test1/meiduo_test/meiduo_test/apps/users/views.py", line 154, in put
    token = request.query_param.get("token")
  File "/home/python/.virtualenvs/django_py3_11/lib/python3.5/site-packages/rest_framework/request.py", line 413, in __getattr__
    return self.__getattribute__(attr)
AttributeError: 'Request' object has no attribute 'query_param'
ERROR 2019-01-04 14:40:44,681 basehttp 124 "PUT /emails/verification/?token=eyJleHAiOjE1NDY1OTExMzcsImlhdCI6MTU0NjU4MzkzNywiYWxnIjoiSFMyNTYifQ.eyJlbWFpbCI6InNzXzIyenhtOTY4NzEyQDE2My5jb20iLCJpZCI6NX0.Y4lWPeKjVDtk5fHQEig0igxQMOq5pWo1OZvKI5d5pVg HTTP/1.1" 500 19990
INFO 2019-01-04 14:42:21,284 basehttp 124 "GET /user/ HTTP/1.1" 200 110
INFO 2019-01-04 14:42:27,342 basehttp 124 "PUT /email/ HTTP/1.1" 200 41
INFO 2019-01-04 14:42:55,876 basehttp 124 "OPTIONS /emails/verification/?token=eyJpYXQiOjE1NDY1ODQxNDMsImFsZyI6IkhTMjU2IiwiZXhwIjoxNTQ2NTkxMzQzfQ.eyJlbWFpbCI6InNzXzIyenhtOTY4NzEyQDE2My5jb20iLCJpZCI6NX0.MjVQDLoiCz4ra3XPBC4YU2IRyMabBOU322eRWcM7MFY HTTP/1.1" 200 0
ERROR 2019-01-04 14:42:56,490 exception 135 Internal Server Error: /emails/verification/
Traceback (most recent call last):
  File "/home/python/.virtualenvs/django_py3_11/lib/python3.5/site-packages/rest_framework/request.py", line 411, in __getattr__
    return getattr(self._request, attr)
AttributeError: 'WSGIRequest' object has no attribute 'query_param'

During handling of the above exception, another exception occurred:

Traceback (most recent call last):
  File "/home/python/.virtualenvs/django_py3_11/lib/python3.5/site-packages/django/core/handlers/exception.py", line 41, in inner
    response = get_response(request)
  File "/home/python/.virtualenvs/django_py3_11/lib/python3.5/site-packages/django/core/handlers/base.py", line 187, in _get_response
    response = self.process_exception_by_middleware(e, request)
  File "/home/python/.virtualenvs/django_py3_11/lib/python3.5/site-packages/django/core/handlers/base.py", line 185, in _get_response
    response = wrapped_callback(request, *callback_args, **callback_kwargs)
  File "/home/python/.virtualenvs/django_py3_11/lib/python3.5/site-packages/django/views/decorators/csrf.py", line 58, in wrapped_view
    return view_func(*args, **kwargs)
  File "/home/python/.virtualenvs/django_py3_11/lib/python3.5/site-packages/django/views/generic/base.py", line 68, in view
    return self.dispatch(request, *args, **kwargs)
  File "/home/python/.virtualenvs/django_py3_11/lib/python3.5/site-packages/rest_framework/views.py", line 483, in dispatch
    response = self.handle_exception(exc)
  File "/home/python/.virtualenvs/django_py3_11/lib/python3.5/site-packages/rest_framework/views.py", line 443, in handle_exception
    self.raise_uncaught_exception(exc)
  File "/home/python/.virtualenvs/django_py3_11/lib/python3.5/site-packages/rest_framework/views.py", line 480, in dispatch
    response = handler(request, *args, **kwargs)
  File "/home/python/Desktop/meiduo_test1/meiduo_test/meiduo_test/apps/users/views.py", line 154, in put
    token = request.query_param.get("token")
  File "/home/python/.virtualenvs/django_py3_11/lib/python3.5/site-packages/rest_framework/request.py", line 413, in __getattr__
    return self.__getattribute__(attr)
AttributeError: 'Request' object has no attribute 'query_param'
ERROR 2019-01-04 14:42:57,204 basehttp 124 "PUT /emails/verification/?token=eyJpYXQiOjE1NDY1ODQxNDMsImFsZyI6IkhTMjU2IiwiZXhwIjoxNTQ2NTkxMzQzfQ.eyJlbWFpbCI6InNzXzIyenhtOTY4NzEyQDE2My5jb20iLCJpZCI6NX0.MjVQDLoiCz4ra3XPBC4YU2IRyMabBOU322eRWcM7MFY HTTP/1.1" 500 19990
INFO 2019-01-04 14:46:54,653 basehttp 124 "OPTIONS /user/ HTTP/1.1" 200 0
INFO 2019-01-04 14:46:55,677 basehttp 124 "GET /user/ HTTP/1.1" 200 110
INFO 2019-01-04 14:46:58,139 basehttp 124 "PUT /email/ HTTP/1.1" 200 41
INFO 2019-01-04 14:47:14,835 basehttp 124 "OPTIONS /emails/verification/?token=eyJhbGciOiJIUzI1NiIsImV4cCI6MTU0NjU5MTYxNywiaWF0IjoxNTQ2NTg0NDE3fQ.eyJpZCI6NSwiZW1haWwiOiJzc18yMnp4bTk2ODcxMkAxNjMuY29tIn0.eMKmRWYGD6wcVJaZ2_sAyMTNtGuMG_0aXfKLXDHsz3o HTTP/1.1" 200 0
ERROR 2019-01-04 14:47:14,927 exception 135 Internal Server Error: /emails/verification/
Traceback (most recent call last):
  File "/home/python/.virtualenvs/django_py3_11/lib/python3.5/site-packages/django/core/handlers/exception.py", line 41, in inner
    response = get_response(request)
  File "/home/python/.virtualenvs/django_py3_11/lib/python3.5/site-packages/django/core/handlers/base.py", line 187, in _get_response
    response = self.process_exception_by_middleware(e, request)
  File "/home/python/.virtualenvs/django_py3_11/lib/python3.5/site-packages/django/core/handlers/base.py", line 185, in _get_response
    response = wrapped_callback(request, *callback_args, **callback_kwargs)
  File "/home/python/.virtualenvs/django_py3_11/lib/python3.5/site-packages/django/views/decorators/csrf.py", line 58, in wrapped_view
    return view_func(*args, **kwargs)
  File "/home/python/.virtualenvs/django_py3_11/lib/python3.5/site-packages/django/views/generic/base.py", line 68, in view
    return self.dispatch(request, *args, **kwargs)
  File "/home/python/.virtualenvs/django_py3_11/lib/python3.5/site-packages/rest_framework/views.py", line 483, in dispatch
    response = self.handle_exception(exc)
  File "/home/python/.virtualenvs/django_py3_11/lib/python3.5/site-packages/rest_framework/views.py", line 443, in handle_exception
    self.raise_uncaught_exception(exc)
  File "/home/python/.virtualenvs/django_py3_11/lib/python3.5/site-packages/rest_framework/views.py", line 480, in dispatch
    response = handler(request, *args, **kwargs)
  File "/home/python/Desktop/meiduo_test1/meiduo_test/meiduo_test/apps/users/views.py", line 187, in put
    user = User.check_verify_email_token(token)
  File "/home/python/Desktop/meiduo_test1/meiduo_test/meiduo_test/apps/users/models.py", line 52, in check_verify_email_token
    data = serializer.load(token)
  File "/home/python/.virtualenvs/django_py3_11/lib/python3.5/site-packages/itsdangerous.py", line 586, in load
    return self.loads(f.read(), salt)
AttributeError: 'str' object has no attribute 'read'
ERROR 2019-01-04 14:47:15,126 basehttp 124 "PUT /emails/verification/?token=eyJhbGciOiJIUzI1NiIsImV4cCI6MTU0NjU5MTYxNywiaWF0IjoxNTQ2NTg0NDE3fQ.eyJpZCI6NSwiZW1haWwiOiJzc18yMnp4bTk2ODcxMkAxNjMuY29tIn0.eMKmRWYGD6wcVJaZ2_sAyMTNtGuMG_0aXfKLXDHsz3o HTTP/1.1" 500 19795
WARNING 2019-01-04 14:47:53,715 base 152 Not Found: //emails/verification/
WARNING 2019-01-04 14:47:53,716 basehttp 124 "GET //emails/verification/?token=eyJhbGciOiJIUzI1NiIsImV4cCI6MTU0NjU5MTYxNywiaWF0IjoxNTQ2NTg0NDE3fQ.eyJpZCI6NSwiZW1haWwiOiJzc18yMnp4bTk2ODcxMkAxNjMuY29tIn0.eMKmRWYGD6wcVJaZ2_sAyMTNtGuMG_0aXfKLXDHsz3o HTTP/1.1" 404 6945
WARNING 2019-01-04 14:48:07,638 basehttp 124 "GET /emails/verification/?token=eyJhbGciOiJIUzI1NiIsImV4cCI6MTU0NjU5MTYxNywiaWF0IjoxNTQ2NTg0NDE3fQ.eyJpZCI6NSwiZW1haWwiOiJzc18yMnp4bTk2ODcxMkAxNjMuY29tIn0.eMKmRWYGD6wcVJaZ2_sAyMTNtGuMG_0aXfKLXDHsz3o HTTP/1.1" 405 45
INFO 2019-01-04 14:51:18,034 basehttp 124 "GET /user/ HTTP/1.1" 200 110
INFO 2019-01-04 14:51:19,442 basehttp 124 "OPTIONS /email/ HTTP/1.1" 200 0
INFO 2019-01-04 14:51:20,155 basehttp 124 "PUT /email/ HTTP/1.1" 200 41
INFO 2019-01-04 14:51:38,492 basehttp 124 "OPTIONS /emails/verification/?token=eyJpYXQiOjE1NDY1ODQ2NzksImV4cCI6MTU0NjU5MTg3OSwiYWxnIjoiSFMyNTYifQ.eyJlbWFpbCI6InNzXzIyenhtOTY4NzEyQDE2My5jb20iLCJpZCI6NX0.q7t1b24T8m4Uh2hfTAt3oQI2VEpkQ6JDahaUoTtkKdY HTTP/1.1" 200 0
INFO 2019-01-04 14:51:38,790 basehttp 124 "PUT /emails/verification/?token=eyJpYXQiOjE1NDY1ODQ2NzksImV4cCI6MTU0NjU5MTg3OSwiYWxnIjoiSFMyNTYifQ.eyJlbWFpbCI6InNzXzIyenhtOTY4NzEyQDE2My5jb20iLCJpZCI6NX0.q7t1b24T8m4Uh2hfTAt3oQI2VEpkQ6JDahaUoTtkKdY HTTP/1.1" 200 16
INFO 2019-01-04 14:51:57,627 basehttp 124 "GET /user/ HTTP/1.1" 200 109
INFO 2019-01-05 21:36:25,698 basehttp 124 "GET /admin/ HTTP/1.1" 302 0
INFO 2019-01-05 21:36:31,842 basehttp 124 "GET /admin/login/?next=/admin/ HTTP/1.1" 200 1652
WARNING 2019-01-05 21:36:32,845 base 152 Not Found: /favicon.ico
WARNING 2019-01-05 21:36:32,858 basehttp 124 "GET /favicon.ico HTTP/1.1" 404 6846
INFO 2019-01-05 21:37:00,978 basehttp 124 "POST /admin/login/?next=/admin/ HTTP/1.1" 302 0
INFO 2019-01-05 21:37:01,147 basehttp 124 "GET /admin/ HTTP/1.1" 200 2989
INFO 2019-01-05 21:37:01,334 basehttp 124 "GET /static/admin/fonts/Roboto-Bold-webfont.woff HTTP/1.1" 200 82564
INFO 2019-01-05 21:37:08,179 basehttp 124 "GET /admin/goods/goods/add/ HTTP/1.1" 200 7095
INFO 2019-01-05 21:37:08,292 basehttp 124 "GET /static/admin/js/vendor/xregexp/xregexp.js HTTP/1.1" 200 128820
INFO 2019-01-05 21:37:08,300 basehttp 124 "GET /static/admin/js/vendor/jquery/jquery.js HTTP/1.1" 200 258648
INFO 2019-01-05 21:37:08,313 basehttp 124 "GET /admin/jsi18n/ HTTP/1.1" 200 7682
INFO 2019-01-05 21:45:41,306 basehttp 124 "GET /admin/ HTTP/1.1" 200 2989
INFO 2019-01-05 21:46:22,469 basehttp 124 "GET /admin/ HTTP/1.1" 200 2989
INFO 2019-01-05 21:47:26,386 basehttp 124 "GET /admin/ HTTP/1.1" 200 2989
INFO 2019-01-05 21:47:29,965 basehttp 124 "GET /admin/ HTTP/1.1" 200 2989
INFO 2019-01-05 21:48:33,955 basehttp 124 "GET /admin HTTP/1.1" 301 0
INFO 2019-01-05 21:48:33,987 basehttp 124 "GET /admin/ HTTP/1.1" 302 0
INFO 2019-01-05 21:48:34,045 basehttp 124 "GET /admin/login/?next=/admin/ HTTP/1.1" 200 1652
INFO 2019-01-05 21:48:34,203 basehttp 124 "GET /static/admin/css/login.css HTTP/1.1" 200 1203
INFO 2019-01-05 21:48:34,206 basehttp 124 "GET /static/admin/css/base.css HTTP/1.1" 200 16066
INFO 2019-01-05 21:48:34,223 basehttp 124 "GET /static/admin/css/fonts.css HTTP/1.1" 200 423
INFO 2019-01-05 21:48:34,287 basehttp 124 "GET /static/admin/fonts/Roboto-Regular-webfont.woff HTTP/1.1" 200 80304
INFO 2019-01-05 21:48:34,310 basehttp 124 "GET /static/admin/fonts/Roboto-Light-webfont.woff HTTP/1.1" 200 81348
WARNING 2019-01-05 21:48:34,452 base 152 Not Found: /favicon.ico
WARNING 2019-01-05 21:48:34,454 basehttp 124 "GET /favicon.ico HTTP/1.1" 404 6852
INFO 2019-01-05 21:48:46,679 basehttp 124 "POST /admin/login/?next=/admin/ HTTP/1.1" 302 0
INFO 2019-01-05 21:48:46,722 basehttp 124 "GET /admin/ HTTP/1.1" 200 2989
INFO 2019-01-05 21:48:46,762 basehttp 124 "GET /static/admin/css/dashboard.css HTTP/1.1" 200 412
INFO 2019-01-05 21:48:46,830 basehttp 124 "GET /static/admin/img/icon-addlink.svg HTTP/1.1" 200 331
INFO 2019-01-05 21:48:46,833 basehttp 124 "GET /static/admin/fonts/Roboto-Bold-webfont.woff HTTP/1.1" 200 82564
INFO 2019-01-05 21:48:46,833 basehttp 124 "GET /static/admin/img/icon-changelink.svg HTTP/1.1" 200 380
INFO 2019-01-05 21:48:53,207 basehttp 124 "GET /admin/goods/goods/add/ HTTP/1.1" 200 7095
INFO 2019-01-05 21:48:53,253 basehttp 124 "GET /static/admin/css/forms.css HTTP/1.1" 200 8173
INFO 2019-01-05 21:48:53,287 basehttp 124 "GET /static/admin/js/vendor/jquery/jquery.js HTTP/1.1" 200 258648
INFO 2019-01-05 21:48:53,308 basehttp 124 "GET /admin/jsi18n/ HTTP/1.1" 200 7682
INFO 2019-01-05 21:48:53,341 basehttp 124 "GET /static/admin/js/core.js HTTP/1.1" 200 7976
INFO 2019-01-05 21:48:53,343 basehttp 124 "GET /static/admin/js/jquery.init.js HTTP/1.1" 200 363
INFO 2019-01-05 21:48:53,346 basehttp 124 "GET /static/admin/js/actions.js HTTP/1.1" 200 6501
INFO 2019-01-05 21:48:53,350 basehttp 124 "GET /static/admin/js/urlify.js HTTP/1.1" 200 8186
INFO 2019-01-05 21:48:53,358 basehttp 124 "GET /static/admin/css/widgets.css HTTP/1.1" 200 10340
INFO 2019-01-05 21:48:53,364 basehttp 124 "GET /static/admin/js/prepopulate.js HTTP/1.1" 200 1538
INFO 2019-01-05 21:48:53,368 basehttp 124 "GET /static/admin/js/admin/RelatedObjectLookups.js HTTP/1.1" 200 6591
INFO 2019-01-05 21:48:53,371 basehttp 124 "GET /static/admin/js/change_form.js HTTP/1.1" 200 712
INFO 2019-01-05 21:48:53,372 basehttp 124 "GET /static/admin/js/prepopulate_init.js HTTP/1.1" 200 495
INFO 2019-01-05 21:48:53,373 basehttp 124 "GET /static/admin/js/vendor/xregexp/xregexp.js HTTP/1.1" 200 128820
INFO 2019-01-05 21:49:11,072 basehttp 124 "GET /admin/goods/ HTTP/1.1" 200 2189
INFO 2019-01-05 21:49:14,272 basehttp 124 "GET /admin/ HTTP/1.1" 200 2989
INFO 2019-01-05 22:16:24,934 basehttp 124 "GET /admin/ HTTP/1.1" 200 2989
WARNING 2019-01-05 22:16:25,747 base 152 Not Found: /favicon.ico
WARNING 2019-01-05 22:16:25,753 basehttp 124 "GET /favicon.ico HTTP/1.1" 404 6852
INFO 2019-01-05 22:16:39,326 basehttp 124 "GET / HTTP/1.1" 200 5229
INFO 2019-01-05 22:16:39,750 basehttp 124 "GET /static/rest_framework/js/ajax-form.js HTTP/1.1" 200 3597
INFO 2019-01-05 22:16:39,754 basehttp 124 "GET /static/rest_framework/css/prettify.css HTTP/1.1" 304 0
INFO 2019-01-05 22:16:39,756 basehttp 124 "GET /static/rest_framework/css/default.css HTTP/1.1" 304 0
INFO 2019-01-05 22:16:39,763 basehttp 124 "GET /static/rest_framework/css/bootstrap-tweaks.css HTTP/1.1" 200 3385
INFO 2019-01-05 22:16:39,766 basehttp 124 "GET /static/rest_framework/js/csrf.js HTTP/1.1" 200 1735
INFO 2019-01-05 22:16:39,832 basehttp 124 "GET /static/rest_framework/js/bootstrap.min.js HTTP/1.1" 200 37045
INFO 2019-01-05 22:16:39,834 basehttp 124 "GET /static/rest_framework/js/jquery-3.3.1.min.js HTTP/1.1" 200 86927
INFO 2019-01-05 22:16:39,834 basehttp 124 "GET /static/rest_framework/js/default.js HTTP/1.1" 200 1262
INFO 2019-01-05 22:16:39,836 basehttp 124 "GET /static/rest_framework/css/bootstrap.min.css HTTP/1.1" 200 121200
INFO 2019-01-05 22:16:39,860 basehttp 124 "GET /static/rest_framework/js/prettify-min.js HTTP/1.1" 200 13632
INFO 2019-01-05 22:16:40,070 basehttp 124 "GET /static/rest_framework/img/grid.png HTTP/1.1" 304 0
INFO 2019-01-05 22:16:46,075 basehttp 124 "GET /admin/ HTTP/1.1" 200 2989
INFO 2019-01-05 22:21:54,493 basehttp 124 "GET /admin/ HTTP/1.1" 200 2989
INFO 2019-01-05 22:21:58,392 basehttp 124 "GET /admin/ HTTP/1.1" 200 2989
INFO 2019-01-05 22:21:59,549 basehttp 124 "GET /admin/ HTTP/1.1" 200 2989
INFO 2019-01-05 22:22:00,481 basehttp 124 "GET /admin/ HTTP/1.1" 200 2989
INFO 2019-01-05 22:22:01,454 basehttp 124 "GET /admin/ HTTP/1.1" 200 2989
INFO 2019-01-05 22:22:02,165 basehttp 124 "GET /admin/ HTTP/1.1" 200 2989
INFO 2019-01-05 22:22:02,904 basehttp 124 "GET /admin/ HTTP/1.1" 200 2989
INFO 2019-01-05 22:22:18,412 basehttp 124 "GET /admin/ HTTP/1.1" 200 2989
INFO 2019-01-05 22:22:22,285 basehttp 124 "GET /admin/goods/goods/add/ HTTP/1.1" 200 12276
INFO 2019-01-05 22:22:22,381 basehttp 124 "GET /static/ckeditor/ckeditor-init.js HTTP/1.1" 200 2039
INFO 2019-01-05 22:22:22,443 basehttp 124 "GET /admin/jsi18n/ HTTP/1.1" 200 7682
INFO 2019-01-05 22:22:22,505 basehttp 124 "GET /static/ckeditor/ckeditor/ckeditor.js HTTP/1.1" 200 690627
INFO 2019-01-05 22:22:22,912 basehttp 124 "GET /static/ckeditor/ckeditor/config.js?t=I3I8 HTTP/1.1" 200 338
INFO 2019-01-05 22:22:23,196 basehttp 124 "GET /static/ckeditor/ckeditor/skins/moono-lisa/editor.css?t=I3I8 HTTP/1.1" 200 46921
INFO 2019-01-05 22:22:23,226 basehttp 124 "GET /static/ckeditor/ckeditor/lang/zh.js?t=I3I8 HTTP/1.1" 200 18641
INFO 2019-01-05 22:22:23,377 basehttp 124 "GET /static/ckeditor/ckeditor/styles.js?t=I3I8 HTTP/1.1" 200 5583
INFO 2019-01-05 22:22:23,506 basehttp 124 "GET /static/ckeditor/ckeditor/skins/moono-lisa/icons.png?t=95e5d83 HTTP/1.1" 200 12421
INFO 2019-01-05 22:22:23,524 basehttp 124 "GET /static/ckeditor/ckeditor/plugins/copyformatting/styles/copyformatting.css HTTP/1.1" 200 1513
INFO 2019-01-05 22:22:23,535 basehttp 124 "GET /static/ckeditor/ckeditor/plugins/tableselection/styles/tableselection.css HTTP/1.1" 200 1082
INFO 2019-01-05 22:22:23,536 basehttp 124 "GET /static/ckeditor/ckeditor/contents.css?t=I3I8 HTTP/1.1" 200 2954
INFO 2019-01-05 22:22:23,540 basehttp 124 "GET /static/ckeditor/ckeditor/plugins/wsc/skins/moono-lisa/wsc.css HTTP/1.1" 200 1306
INFO 2019-01-05 22:22:23,547 basehttp 124 "GET /static/ckeditor/ckeditor/plugins/scayt/skins/moono-lisa/scayt.css HTTP/1.1" 200 381
INFO 2019-01-05 22:22:23,548 basehttp 124 "GET /static/ckeditor/ckeditor/plugins/scayt/dialogs/dialog.css HTTP/1.1" 200 419
INFO 2019-01-05 22:25:41,807 basehttp 124 "GET /admin/ HTTP/1.1" 200 2989
ERROR 2019-01-05 22:25:43,502 exception 135 Internal Server Error: /admin/goods/goods/
Traceback (most recent call last):
  File "/home/python/.virtualenvs/django_py3_11/lib/python3.5/site-packages/django/db/backends/utils.py", line 64, in execute
    return self.cursor.execute(sql, params)
  File "/home/python/.virtualenvs/django_py3_11/lib/python3.5/site-packages/django/db/backends/mysql/base.py", line 101, in execute
    return self.cursor.execute(query, args)
  File "/home/python/.virtualenvs/django_py3_11/lib/python3.5/site-packages/pymysql/cursors.py", line 170, in execute
    result = self._query(query)
  File "/home/python/.virtualenvs/django_py3_11/lib/python3.5/site-packages/pymysql/cursors.py", line 328, in _query
    conn.query(q)
  File "/home/python/.virtualenvs/django_py3_11/lib/python3.5/site-packages/pymysql/connections.py", line 516, in query
    self._affected_rows = self._read_query_result(unbuffered=unbuffered)
  File "/home/python/.virtualenvs/django_py3_11/lib/python3.5/site-packages/pymysql/connections.py", line 727, in _read_query_result
    result.read()
  File "/home/python/.virtualenvs/django_py3_11/lib/python3.5/site-packages/pymysql/connections.py", line 1066, in read
    first_packet = self.connection._read_packet()
  File "/home/python/.virtualenvs/django_py3_11/lib/python3.5/site-packages/pymysql/connections.py", line 683, in _read_packet
    packet.check_error()
  File "/home/python/.virtualenvs/django_py3_11/lib/python3.5/site-packages/pymysql/protocol.py", line 220, in check_error
    err.raise_mysql_exception(self._data)
  File "/home/python/.virtualenvs/django_py3_11/lib/python3.5/site-packages/pymysql/err.py", line 109, in raise_mysql_exception
    raise errorclass(errno, errval)
pymysql.err.InternalError: (1054, "Unknown column 'tb_goods.desc_detail' in 'field list'")

The above exception was the direct cause of the following exception:

Traceback (most recent call last):
  File "/home/python/.virtualenvs/django_py3_11/lib/python3.5/site-packages/django/core/handlers/exception.py", line 41, in inner
    response = get_response(request)
  File "/home/python/.virtualenvs/django_py3_11/lib/python3.5/site-packages/django/core/handlers/base.py", line 187, in _get_response
    response = self.process_exception_by_middleware(e, request)
  File "/home/python/.virtualenvs/django_py3_11/lib/python3.5/site-packages/django/core/handlers/base.py", line 185, in _get_response
    response = wrapped_callback(request, *callback_args, **callback_kwargs)
  File "/home/python/.virtualenvs/django_py3_11/lib/python3.5/site-packages/django/contrib/admin/options.py", line 551, in wrapper
    return self.admin_site.admin_view(view)(*args, **kwargs)
  File "/home/python/.virtualenvs/django_py3_11/lib/python3.5/site-packages/django/utils/decorators.py", line 149, in _wrapped_view
    response = view_func(request, *args, **kwargs)
  File "/home/python/.virtualenvs/django_py3_11/lib/python3.5/site-packages/django/views/decorators/cache.py", line 57, in _wrapped_view_func
    response = view_func(request, *args, **kwargs)
  File "/home/python/.virtualenvs/django_py3_11/lib/python3.5/site-packages/django/contrib/admin/sites.py", line 224, in inner
    return view(request, *args, **kwargs)
  File "/home/python/.virtualenvs/django_py3_11/lib/python3.5/site-packages/django/utils/decorators.py", line 67, in _wrapper
    return bound_func(*args, **kwargs)
  File "/home/python/.virtualenvs/django_py3_11/lib/python3.5/site-packages/django/utils/decorators.py", line 149, in _wrapped_view
    response = view_func(request, *args, **kwargs)
  File "/home/python/.virtualenvs/django_py3_11/lib/python3.5/site-packages/django/utils/decorators.py", line 63, in bound_func
    return func.__get__(self, type(self))(*args2, **kwargs2)
  File "/home/python/.virtualenvs/django_py3_11/lib/python3.5/site-packages/django/contrib/admin/options.py", line 1662, in changelist_view
    selection_note=_('0 of %(cnt)s selected') % {'cnt': len(cl.result_list)},
  File "/home/python/.virtualenvs/django_py3_11/lib/python3.5/site-packages/django/db/models/query.py", line 232, in __len__
    self._fetch_all()
  File "/home/python/.virtualenvs/django_py3_11/lib/python3.5/site-packages/django/db/models/query.py", line 1118, in _fetch_all
    self._result_cache = list(self._iterable_class(self))
  File "/home/python/.virtualenvs/django_py3_11/lib/python3.5/site-packages/django/db/models/query.py", line 53, in __iter__
    results = compiler.execute_sql(chunked_fetch=self.chunked_fetch)
  File "/home/python/.virtualenvs/django_py3_11/lib/python3.5/site-packages/django/db/models/sql/compiler.py", line 899, in execute_sql
    raise original_exception
  File "/home/python/.virtualenvs/django_py3_11/lib/python3.5/site-packages/django/db/models/sql/compiler.py", line 889, in execute_sql
    cursor.execute(sql, params)
  File "/home/python/.virtualenvs/django_py3_11/lib/python3.5/site-packages/django/db/backends/utils.py", line 79, in execute
    return super(CursorDebugWrapper, self).execute(sql, params)
  File "/home/python/.virtualenvs/django_py3_11/lib/python3.5/site-packages/django/db/backends/utils.py", line 64, in execute
    return self.cursor.execute(sql, params)
  File "/home/python/.virtualenvs/django_py3_11/lib/python3.5/site-packages/django/db/utils.py", line 94, in __exit__
    six.reraise(dj_exc_type, dj_exc_value, traceback)
  File "/home/python/.virtualenvs/django_py3_11/lib/python3.5/site-packages/django/utils/six.py", line 685, in reraise
    raise value.with_traceback(tb)
  File "/home/python/.virtualenvs/django_py3_11/lib/python3.5/site-packages/django/db/backends/utils.py", line 64, in execute
    return self.cursor.execute(sql, params)
  File "/home/python/.virtualenvs/django_py3_11/lib/python3.5/site-packages/django/db/backends/mysql/base.py", line 101, in execute
    return self.cursor.execute(query, args)
  File "/home/python/.virtualenvs/django_py3_11/lib/python3.5/site-packages/pymysql/cursors.py", line 170, in execute
    result = self._query(query)
  File "/home/python/.virtualenvs/django_py3_11/lib/python3.5/site-packages/pymysql/cursors.py", line 328, in _query
    conn.query(q)
  File "/home/python/.virtualenvs/django_py3_11/lib/python3.5/site-packages/pymysql/connections.py", line 516, in query
    self._affected_rows = self._read_query_result(unbuffered=unbuffered)
  File "/home/python/.virtualenvs/django_py3_11/lib/python3.5/site-packages/pymysql/connections.py", line 727, in _read_query_result
    result.read()
  File "/home/python/.virtualenvs/django_py3_11/lib/python3.5/site-packages/pymysql/connections.py", line 1066, in read
    first_packet = self.connection._read_packet()
  File "/home/python/.virtualenvs/django_py3_11/lib/python3.5/site-packages/pymysql/connections.py", line 683, in _read_packet
    packet.check_error()
  File "/home/python/.virtualenvs/django_py3_11/lib/python3.5/site-packages/pymysql/protocol.py", line 220, in check_error
    err.raise_mysql_exception(self._data)
  File "/home/python/.virtualenvs/django_py3_11/lib/python3.5/site-packages/pymysql/err.py", line 109, in raise_mysql_exception
    raise errorclass(errno, errval)
django.db.utils.InternalError: (1054, "Unknown column 'tb_goods.desc_detail' in 'field list'")
ERROR 2019-01-05 22:25:43,892 basehttp 124 "GET /admin/goods/goods/ HTTP/1.1" 500 239691
INFO 2019-01-06 09:22:20,351 basehttp 124 "GET /admin/ HTTP/1.1" 200 2989
WARNING 2019-01-06 09:22:22,561 base 152 Not Found: /favicon.ico
WARNING 2019-01-06 09:22:22,564 basehttp 124 "GET /favicon.ico HTTP/1.1" 404 6852
ERROR 2019-01-06 09:22:28,891 exception 135 Internal Server Error: /admin/goods/goods/
Traceback (most recent call last):
  File "/home/python/.virtualenvs/django_py3_11/lib/python3.5/site-packages/django/db/backends/utils.py", line 64, in execute
    return self.cursor.execute(sql, params)
  File "/home/python/.virtualenvs/django_py3_11/lib/python3.5/site-packages/django/db/backends/mysql/base.py", line 101, in execute
    return self.cursor.execute(query, args)
  File "/home/python/.virtualenvs/django_py3_11/lib/python3.5/site-packages/pymysql/cursors.py", line 170, in execute
    result = self._query(query)
  File "/home/python/.virtualenvs/django_py3_11/lib/python3.5/site-packages/pymysql/cursors.py", line 328, in _query
    conn.query(q)
  File "/home/python/.virtualenvs/django_py3_11/lib/python3.5/site-packages/pymysql/connections.py", line 516, in query
    self._affected_rows = self._read_query_result(unbuffered=unbuffered)
  File "/home/python/.virtualenvs/django_py3_11/lib/python3.5/site-packages/pymysql/connections.py", line 727, in _read_query_result
    result.read()
  File "/home/python/.virtualenvs/django_py3_11/lib/python3.5/site-packages/pymysql/connections.py", line 1066, in read
    first_packet = self.connection._read_packet()
  File "/home/python/.virtualenvs/django_py3_11/lib/python3.5/site-packages/pymysql/connections.py", line 683, in _read_packet
    packet.check_error()
  File "/home/python/.virtualenvs/django_py3_11/lib/python3.5/site-packages/pymysql/protocol.py", line 220, in check_error
    err.raise_mysql_exception(self._data)
  File "/home/python/.virtualenvs/django_py3_11/lib/python3.5/site-packages/pymysql/err.py", line 109, in raise_mysql_exception
    raise errorclass(errno, errval)
pymysql.err.InternalError: (1054, "Unknown column 'tb_goods.desc_detail' in 'field list'")

The above exception was the direct cause of the following exception:

Traceback (most recent call last):
  File "/home/python/.virtualenvs/django_py3_11/lib/python3.5/site-packages/django/core/handlers/exception.py", line 41, in inner
    response = get_response(request)
  File "/home/python/.virtualenvs/django_py3_11/lib/python3.5/site-packages/django/core/handlers/base.py", line 187, in _get_response
    response = self.process_exception_by_middleware(e, request)
  File "/home/python/.virtualenvs/django_py3_11/lib/python3.5/site-packages/django/core/handlers/base.py", line 185, in _get_response
    response = wrapped_callback(request, *callback_args, **callback_kwargs)
  File "/home/python/.virtualenvs/django_py3_11/lib/python3.5/site-packages/django/contrib/admin/options.py", line 551, in wrapper
    return self.admin_site.admin_view(view)(*args, **kwargs)
  File "/home/python/.virtualenvs/django_py3_11/lib/python3.5/site-packages/django/utils/decorators.py", line 149, in _wrapped_view
    response = view_func(request, *args, **kwargs)
  File "/home/python/.virtualenvs/django_py3_11/lib/python3.5/site-packages/django/views/decorators/cache.py", line 57, in _wrapped_view_func
    response = view_func(request, *args, **kwargs)
  File "/home/python/.virtualenvs/django_py3_11/lib/python3.5/site-packages/django/contrib/admin/sites.py", line 224, in inner
    return view(request, *args, **kwargs)
  File "/home/python/.virtualenvs/django_py3_11/lib/python3.5/site-packages/django/utils/decorators.py", line 67, in _wrapper
    return bound_func(*args, **kwargs)
  File "/home/python/.virtualenvs/django_py3_11/lib/python3.5/site-packages/django/utils/decorators.py", line 149, in _wrapped_view
    response = view_func(request, *args, **kwargs)
  File "/home/python/.virtualenvs/django_py3_11/lib/python3.5/site-packages/django/utils/decorators.py", line 63, in bound_func
    return func.__get__(self, type(self))(*args2, **kwargs2)
  File "/home/python/.virtualenvs/django_py3_11/lib/python3.5/site-packages/django/contrib/admin/options.py", line 1662, in changelist_view
    selection_note=_('0 of %(cnt)s selected') % {'cnt': len(cl.result_list)},
  File "/home/python/.virtualenvs/django_py3_11/lib/python3.5/site-packages/django/db/models/query.py", line 232, in __len__
    self._fetch_all()
  File "/home/python/.virtualenvs/django_py3_11/lib/python3.5/site-packages/django/db/models/query.py", line 1118, in _fetch_all
    self._result_cache = list(self._iterable_class(self))
  File "/home/python/.virtualenvs/django_py3_11/lib/python3.5/site-packages/django/db/models/query.py", line 53, in __iter__
    results = compiler.execute_sql(chunked_fetch=self.chunked_fetch)
  File "/home/python/.virtualenvs/django_py3_11/lib/python3.5/site-packages/django/db/models/sql/compiler.py", line 899, in execute_sql
    raise original_exception
  File "/home/python/.virtualenvs/django_py3_11/lib/python3.5/site-packages/django/db/models/sql/compiler.py", line 889, in execute_sql
    cursor.execute(sql, params)
  File "/home/python/.virtualenvs/django_py3_11/lib/python3.5/site-packages/django/db/backends/utils.py", line 79, in execute
    return super(CursorDebugWrapper, self).execute(sql, params)
  File "/home/python/.virtualenvs/django_py3_11/lib/python3.5/site-packages/django/db/backends/utils.py", line 64, in execute
    return self.cursor.execute(sql, params)
  File "/home/python/.virtualenvs/django_py3_11/lib/python3.5/site-packages/django/db/utils.py", line 94, in __exit__
    six.reraise(dj_exc_type, dj_exc_value, traceback)
  File "/home/python/.virtualenvs/django_py3_11/lib/python3.5/site-packages/django/utils/six.py", line 685, in reraise
    raise value.with_traceback(tb)
  File "/home/python/.virtualenvs/django_py3_11/lib/python3.5/site-packages/django/db/backends/utils.py", line 64, in execute
    return self.cursor.execute(sql, params)
  File "/home/python/.virtualenvs/django_py3_11/lib/python3.5/site-packages/django/db/backends/mysql/base.py", line 101, in execute
    return self.cursor.execute(query, args)
  File "/home/python/.virtualenvs/django_py3_11/lib/python3.5/site-packages/pymysql/cursors.py", line 170, in execute
    result = self._query(query)
  File "/home/python/.virtualenvs/django_py3_11/lib/python3.5/site-packages/pymysql/cursors.py", line 328, in _query
    conn.query(q)
  File "/home/python/.virtualenvs/django_py3_11/lib/python3.5/site-packages/pymysql/connections.py", line 516, in query
    self._affected_rows = self._read_query_result(unbuffered=unbuffered)
  File "/home/python/.virtualenvs/django_py3_11/lib/python3.5/site-packages/pymysql/connections.py", line 727, in _read_query_result
    result.read()
  File "/home/python/.virtualenvs/django_py3_11/lib/python3.5/site-packages/pymysql/connections.py", line 1066, in read
    first_packet = self.connection._read_packet()
  File "/home/python/.virtualenvs/django_py3_11/lib/python3.5/site-packages/pymysql/connections.py", line 683, in _read_packet
    packet.check_error()
  File "/home/python/.virtualenvs/django_py3_11/lib/python3.5/site-packages/pymysql/protocol.py", line 220, in check_error
    err.raise_mysql_exception(self._data)
  File "/home/python/.virtualenvs/django_py3_11/lib/python3.5/site-packages/pymysql/err.py", line 109, in raise_mysql_exception
    raise errorclass(errno, errval)
django.db.utils.InternalError: (1054, "Unknown column 'tb_goods.desc_detail' in 'field list'")
ERROR 2019-01-06 09:22:29,877 basehttp 124 "GET /admin/goods/goods/ HTTP/1.1" 500 239877
INFO 2019-01-06 09:30:50,631 basehttp 124 "GET /admin/goods/ HTTP/1.1" 200 2189
INFO 2019-01-06 09:30:55,402 basehttp 124 "GET /admin/goods/goods/add/ HTTP/1.1" 200 12276
INFO 2019-01-06 09:30:55,855 basehttp 124 "GET /admin/jsi18n/ HTTP/1.1" 200 7682
INFO 2019-01-06 09:31:06,349 basehttp 124 "GET /static/ckeditor/ckeditor/skins/moono-lisa/dialog.css?t=I3I8 HTTP/1.1" 200 13570
INFO 2019-01-06 09:31:06,389 basehttp 124 "GET /static/ckeditor/ckeditor/plugins/image/dialogs/image.js?t=I3I8 HTTP/1.1" 200 21390
INFO 2019-01-06 09:31:06,561 basehttp 124 "GET /static/ckeditor/ckeditor/skins/moono-lisa/images/refresh.png HTTP/1.1" 200 757
INFO 2019-01-06 09:31:06,564 basehttp 124 "GET /static/ckeditor/ckeditor/skins/moono-lisa/images/lock.png HTTP/1.1" 200 506
INFO 2019-01-06 09:31:06,565 basehttp 124 "GET /static/ckeditor/ckeditor/skins/moono-lisa/images/close.png HTTP/1.1" 200 615
INFO 2019-01-06 09:32:24,512 basehttp 124 "GET /admin/goods/ HTTP/1.1" 200 2189
INFO 2019-01-06 18:22:17,107 basehttp 124 "GET /admin/ HTTP/1.1" 200 2989
INFO 2019-01-06 18:22:17,356 basehttp 124 "GET /admin/ HTTP/1.1" 200 2989
WARNING 2019-01-06 18:22:18,621 base 152 Not Found: /favicon.ico
WARNING 2019-01-06 18:22:18,623 basehttp 124 "GET /favicon.ico HTTP/1.1" 404 6846
ERROR 2019-01-06 18:22:22,701 exception 135 Internal Server Error: /admin/goods/goods/
Traceback (most recent call last):
  File "/home/python/.virtualenvs/django_py3_11/lib/python3.5/site-packages/django/db/backends/utils.py", line 64, in execute
    return self.cursor.execute(sql, params)
  File "/home/python/.virtualenvs/django_py3_11/lib/python3.5/site-packages/django/db/backends/mysql/base.py", line 101, in execute
    return self.cursor.execute(query, args)
  File "/home/python/.virtualenvs/django_py3_11/lib/python3.5/site-packages/pymysql/cursors.py", line 170, in execute
    result = self._query(query)
  File "/home/python/.virtualenvs/django_py3_11/lib/python3.5/site-packages/pymysql/cursors.py", line 328, in _query
    conn.query(q)
  File "/home/python/.virtualenvs/django_py3_11/lib/python3.5/site-packages/pymysql/connections.py", line 516, in query
    self._affected_rows = self._read_query_result(unbuffered=unbuffered)
  File "/home/python/.virtualenvs/django_py3_11/lib/python3.5/site-packages/pymysql/connections.py", line 727, in _read_query_result
    result.read()
  File "/home/python/.virtualenvs/django_py3_11/lib/python3.5/site-packages/pymysql/connections.py", line 1066, in read
    first_packet = self.connection._read_packet()
  File "/home/python/.virtualenvs/django_py3_11/lib/python3.5/site-packages/pymysql/connections.py", line 683, in _read_packet
    packet.check_error()
  File "/home/python/.virtualenvs/django_py3_11/lib/python3.5/site-packages/pymysql/protocol.py", line 220, in check_error
    err.raise_mysql_exception(self._data)
  File "/home/python/.virtualenvs/django_py3_11/lib/python3.5/site-packages/pymysql/err.py", line 109, in raise_mysql_exception
    raise errorclass(errno, errval)
pymysql.err.InternalError: (1054, "Unknown column 'tb_goods.desc_detail' in 'field list'")

The above exception was the direct cause of the following exception:

Traceback (most recent call last):
  File "/home/python/.virtualenvs/django_py3_11/lib/python3.5/site-packages/django/core/handlers/exception.py", line 41, in inner
    response = get_response(request)
  File "/home/python/.virtualenvs/django_py3_11/lib/python3.5/site-packages/django/core/handlers/base.py", line 187, in _get_response
    response = self.process_exception_by_middleware(e, request)
  File "/home/python/.virtualenvs/django_py3_11/lib/python3.5/site-packages/django/core/handlers/base.py", line 185, in _get_response
    response = wrapped_callback(request, *callback_args, **callback_kwargs)
  File "/home/python/.virtualenvs/django_py3_11/lib/python3.5/site-packages/django/contrib/admin/options.py", line 551, in wrapper
    return self.admin_site.admin_view(view)(*args, **kwargs)
  File "/home/python/.virtualenvs/django_py3_11/lib/python3.5/site-packages/django/utils/decorators.py", line 149, in _wrapped_view
    response = view_func(request, *args, **kwargs)
  File "/home/python/.virtualenvs/django_py3_11/lib/python3.5/site-packages/django/views/decorators/cache.py", line 57, in _wrapped_view_func
    response = view_func(request, *args, **kwargs)
  File "/home/python/.virtualenvs/django_py3_11/lib/python3.5/site-packages/django/contrib/admin/sites.py", line 224, in inner
    return view(request, *args, **kwargs)
  File "/home/python/.virtualenvs/django_py3_11/lib/python3.5/site-packages/django/utils/decorators.py", line 67, in _wrapper
    return bound_func(*args, **kwargs)
  File "/home/python/.virtualenvs/django_py3_11/lib/python3.5/site-packages/django/utils/decorators.py", line 149, in _wrapped_view
    response = view_func(request, *args, **kwargs)
  File "/home/python/.virtualenvs/django_py3_11/lib/python3.5/site-packages/django/utils/decorators.py", line 63, in bound_func
    return func.__get__(self, type(self))(*args2, **kwargs2)
  File "/home/python/.virtualenvs/django_py3_11/lib/python3.5/site-packages/django/contrib/admin/options.py", line 1662, in changelist_view
    selection_note=_('0 of %(cnt)s selected') % {'cnt': len(cl.result_list)},
  File "/home/python/.virtualenvs/django_py3_11/lib/python3.5/site-packages/django/db/models/query.py", line 232, in __len__
    self._fetch_all()
  File "/home/python/.virtualenvs/django_py3_11/lib/python3.5/site-packages/django/db/models/query.py", line 1118, in _fetch_all
    self._result_cache = list(self._iterable_class(self))
  File "/home/python/.virtualenvs/django_py3_11/lib/python3.5/site-packages/django/db/models/query.py", line 53, in __iter__
    results = compiler.execute_sql(chunked_fetch=self.chunked_fetch)
  File "/home/python/.virtualenvs/django_py3_11/lib/python3.5/site-packages/django/db/models/sql/compiler.py", line 899, in execute_sql
    raise original_exception
  File "/home/python/.virtualenvs/django_py3_11/lib/python3.5/site-packages/django/db/models/sql/compiler.py", line 889, in execute_sql
    cursor.execute(sql, params)
  File "/home/python/.virtualenvs/django_py3_11/lib/python3.5/site-packages/django/db/backends/utils.py", line 79, in execute
    return super(CursorDebugWrapper, self).execute(sql, params)
  File "/home/python/.virtualenvs/django_py3_11/lib/python3.5/site-packages/django/db/backends/utils.py", line 64, in execute
    return self.cursor.execute(sql, params)
  File "/home/python/.virtualenvs/django_py3_11/lib/python3.5/site-packages/django/db/utils.py", line 94, in __exit__
    six.reraise(dj_exc_type, dj_exc_value, traceback)
  File "/home/python/.virtualenvs/django_py3_11/lib/python3.5/site-packages/django/utils/six.py", line 685, in reraise
    raise value.with_traceback(tb)
  File "/home/python/.virtualenvs/django_py3_11/lib/python3.5/site-packages/django/db/backends/utils.py", line 64, in execute
    return self.cursor.execute(sql, params)
  File "/home/python/.virtualenvs/django_py3_11/lib/python3.5/site-packages/django/db/backends/mysql/base.py", line 101, in execute
    return self.cursor.execute(query, args)
  File "/home/python/.virtualenvs/django_py3_11/lib/python3.5/site-packages/pymysql/cursors.py", line 170, in execute
    result = self._query(query)
  File "/home/python/.virtualenvs/django_py3_11/lib/python3.5/site-packages/pymysql/cursors.py", line 328, in _query
    conn.query(q)
  File "/home/python/.virtualenvs/django_py3_11/lib/python3.5/site-packages/pymysql/connections.py", line 516, in query
    self._affected_rows = self._read_query_result(unbuffered=unbuffered)
  File "/home/python/.virtualenvs/django_py3_11/lib/python3.5/site-packages/pymysql/connections.py", line 727, in _read_query_result
    result.read()
  File "/home/python/.virtualenvs/django_py3_11/lib/python3.5/site-packages/pymysql/connections.py", line 1066, in read
    first_packet = self.connection._read_packet()
  File "/home/python/.virtualenvs/django_py3_11/lib/python3.5/site-packages/pymysql/connections.py", line 683, in _read_packet
    packet.check_error()
  File "/home/python/.virtualenvs/django_py3_11/lib/python3.5/site-packages/pymysql/protocol.py", line 220, in check_error
    err.raise_mysql_exception(self._data)
  File "/home/python/.virtualenvs/django_py3_11/lib/python3.5/site-packages/pymysql/err.py", line 109, in raise_mysql_exception
    raise errorclass(errno, errval)
django.db.utils.InternalError: (1054, "Unknown column 'tb_goods.desc_detail' in 'field list'")
ERROR 2019-01-06 18:22:24,135 basehttp 124 "GET /admin/goods/goods/ HTTP/1.1" 500 239857
INFO 2019-01-06 18:22:26,586 basehttp 124 "GET /admin/ HTTP/1.1" 200 2989
INFO 2019-01-06 18:22:29,297 basehttp 124 "GET /admin/goods/goods/add/ HTTP/1.1" 200 12276
INFO 2019-01-06 18:22:29,464 basehttp 124 "GET /static/ckeditor/ckeditor-init.js HTTP/1.1" 200 2039
INFO 2019-01-06 18:22:29,531 basehttp 124 "GET /admin/jsi18n/ HTTP/1.1" 200 7682
INFO 2019-01-06 18:22:29,589 basehttp 124 "GET /static/ckeditor/ckeditor/ckeditor.js HTTP/1.1" 200 690627
INFO 2019-01-06 18:22:30,490 basehttp 124 "GET /static/ckeditor/ckeditor/config.js?t=I3I8 HTTP/1.1" 200 338
INFO 2019-01-06 18:22:31,411 basehttp 124 "GET /static/ckeditor/ckeditor/lang/zh.js?t=I3I8 HTTP/1.1" 200 18641
INFO 2019-01-06 18:22:31,482 basehttp 124 "GET /static/ckeditor/ckeditor/skins/moono-lisa/editor.css?t=I3I8 HTTP/1.1" 200 46921
INFO 2019-01-06 18:22:31,552 basehttp 124 "GET /static/ckeditor/ckeditor/styles.js?t=I3I8 HTTP/1.1" 200 5583
INFO 2019-01-06 18:22:31,741 basehttp 124 "GET /static/ckeditor/ckeditor/plugins/tableselection/styles/tableselection.css HTTP/1.1" 200 1082
INFO 2019-01-06 18:22:31,745 basehttp 124 "GET /static/ckeditor/ckeditor/plugins/scayt/dialogs/dialog.css HTTP/1.1" 200 419
INFO 2019-01-06 18:22:31,746 basehttp 124 "GET /static/ckeditor/ckeditor/plugins/wsc/skins/moono-lisa/wsc.css HTTP/1.1" 200 1306
INFO 2019-01-06 18:22:31,756 basehttp 124 "GET /static/ckeditor/ckeditor/plugins/copyformatting/styles/copyformatting.css HTTP/1.1" 200 1513
INFO 2019-01-06 18:22:31,764 basehttp 124 "GET /static/ckeditor/ckeditor/plugins/scayt/skins/moono-lisa/scayt.css HTTP/1.1" 200 381
INFO 2019-01-06 18:22:31,906 basehttp 124 "GET /static/ckeditor/ckeditor/skins/moono-lisa/icons.png?t=95e5d83 HTTP/1.1" 200 12421
INFO 2019-01-06 18:22:31,942 basehttp 124 "GET /static/ckeditor/ckeditor/contents.css?t=I3I8 HTTP/1.1" 200 2954
INFO 2019-01-06 18:24:10,464 basehttp 124 "GET /admin/ HTTP/1.1" 200 2989
ERROR 2019-01-06 18:25:13,595 exception 135 Internal Server Error: /admin/goods/goods/
Traceback (most recent call last):
  File "/home/python/.virtualenvs/django_py3_11/lib/python3.5/site-packages/django/db/backends/utils.py", line 64, in execute
    return self.cursor.execute(sql, params)
  File "/home/python/.virtualenvs/django_py3_11/lib/python3.5/site-packages/django/db/backends/mysql/base.py", line 101, in execute
    return self.cursor.execute(query, args)
  File "/home/python/.virtualenvs/django_py3_11/lib/python3.5/site-packages/pymysql/cursors.py", line 170, in execute
    result = self._query(query)
  File "/home/python/.virtualenvs/django_py3_11/lib/python3.5/site-packages/pymysql/cursors.py", line 328, in _query
    conn.query(q)
  File "/home/python/.virtualenvs/django_py3_11/lib/python3.5/site-packages/pymysql/connections.py", line 516, in query
    self._affected_rows = self._read_query_result(unbuffered=unbuffered)
  File "/home/python/.virtualenvs/django_py3_11/lib/python3.5/site-packages/pymysql/connections.py", line 727, in _read_query_result
    result.read()
  File "/home/python/.virtualenvs/django_py3_11/lib/python3.5/site-packages/pymysql/connections.py", line 1066, in read
    first_packet = self.connection._read_packet()
  File "/home/python/.virtualenvs/django_py3_11/lib/python3.5/site-packages/pymysql/connections.py", line 683, in _read_packet
    packet.check_error()
  File "/home/python/.virtualenvs/django_py3_11/lib/python3.5/site-packages/pymysql/protocol.py", line 220, in check_error
    err.raise_mysql_exception(self._data)
  File "/home/python/.virtualenvs/django_py3_11/lib/python3.5/site-packages/pymysql/err.py", line 109, in raise_mysql_exception
    raise errorclass(errno, errval)
pymysql.err.InternalError: (1054, "Unknown column 'tb_goods.desc_detail' in 'field list'")

The above exception was the direct cause of the following exception:

Traceback (most recent call last):
  File "/home/python/.virtualenvs/django_py3_11/lib/python3.5/site-packages/django/core/handlers/exception.py", line 41, in inner
    response = get_response(request)
  File "/home/python/.virtualenvs/django_py3_11/lib/python3.5/site-packages/django/core/handlers/base.py", line 187, in _get_response
    response = self.process_exception_by_middleware(e, request)
  File "/home/python/.virtualenvs/django_py3_11/lib/python3.5/site-packages/django/core/handlers/base.py", line 185, in _get_response
    response = wrapped_callback(request, *callback_args, **callback_kwargs)
  File "/home/python/.virtualenvs/django_py3_11/lib/python3.5/site-packages/django/contrib/admin/options.py", line 551, in wrapper
    return self.admin_site.admin_view(view)(*args, **kwargs)
  File "/home/python/.virtualenvs/django_py3_11/lib/python3.5/site-packages/django/utils/decorators.py", line 149, in _wrapped_view
    response = view_func(request, *args, **kwargs)
  File "/home/python/.virtualenvs/django_py3_11/lib/python3.5/site-packages/django/views/decorators/cache.py", line 57, in _wrapped_view_func
    response = view_func(request, *args, **kwargs)
  File "/home/python/.virtualenvs/django_py3_11/lib/python3.5/site-packages/django/contrib/admin/sites.py", line 224, in inner
    return view(request, *args, **kwargs)
  File "/home/python/.virtualenvs/django_py3_11/lib/python3.5/site-packages/django/utils/decorators.py", line 67, in _wrapper
    return bound_func(*args, **kwargs)
  File "/home/python/.virtualenvs/django_py3_11/lib/python3.5/site-packages/django/utils/decorators.py", line 149, in _wrapped_view
    response = view_func(request, *args, **kwargs)
  File "/home/python/.virtualenvs/django_py3_11/lib/python3.5/site-packages/django/utils/decorators.py", line 63, in bound_func
    return func.__get__(self, type(self))(*args2, **kwargs2)
  File "/home/python/.virtualenvs/django_py3_11/lib/python3.5/site-packages/django/contrib/admin/options.py", line 1662, in changelist_view
    selection_note=_('0 of %(cnt)s selected') % {'cnt': len(cl.result_list)},
  File "/home/python/.virtualenvs/django_py3_11/lib/python3.5/site-packages/django/db/models/query.py", line 232, in __len__
    self._fetch_all()
  File "/home/python/.virtualenvs/django_py3_11/lib/python3.5/site-packages/django/db/models/query.py", line 1118, in _fetch_all
    self._result_cache = list(self._iterable_class(self))
  File "/home/python/.virtualenvs/django_py3_11/lib/python3.5/site-packages/django/db/models/query.py", line 53, in __iter__
    results = compiler.execute_sql(chunked_fetch=self.chunked_fetch)
  File "/home/python/.virtualenvs/django_py3_11/lib/python3.5/site-packages/django/db/models/sql/compiler.py", line 899, in execute_sql
    raise original_exception
  File "/home/python/.virtualenvs/django_py3_11/lib/python3.5/site-packages/django/db/models/sql/compiler.py", line 889, in execute_sql
    cursor.execute(sql, params)
  File "/home/python/.virtualenvs/django_py3_11/lib/python3.5/site-packages/django/db/backends/utils.py", line 79, in execute
    return super(CursorDebugWrapper, self).execute(sql, params)
  File "/home/python/.virtualenvs/django_py3_11/lib/python3.5/site-packages/django/db/backends/utils.py", line 64, in execute
    return self.cursor.execute(sql, params)
  File "/home/python/.virtualenvs/django_py3_11/lib/python3.5/site-packages/django/db/utils.py", line 94, in __exit__
    six.reraise(dj_exc_type, dj_exc_value, traceback)
  File "/home/python/.virtualenvs/django_py3_11/lib/python3.5/site-packages/django/utils/six.py", line 685, in reraise
    raise value.with_traceback(tb)
  File "/home/python/.virtualenvs/django_py3_11/lib/python3.5/site-packages/django/db/backends/utils.py", line 64, in execute
    return self.cursor.execute(sql, params)
  File "/home/python/.virtualenvs/django_py3_11/lib/python3.5/site-packages/django/db/backends/mysql/base.py", line 101, in execute
    return self.cursor.execute(query, args)
  File "/home/python/.virtualenvs/django_py3_11/lib/python3.5/site-packages/pymysql/cursors.py", line 170, in execute
    result = self._query(query)
  File "/home/python/.virtualenvs/django_py3_11/lib/python3.5/site-packages/pymysql/cursors.py", line 328, in _query
    conn.query(q)
  File "/home/python/.virtualenvs/django_py3_11/lib/python3.5/site-packages/pymysql/connections.py", line 516, in query
    self._affected_rows = self._read_query_result(unbuffered=unbuffered)
  File "/home/python/.virtualenvs/django_py3_11/lib/python3.5/site-packages/pymysql/connections.py", line 727, in _read_query_result
    result.read()
  File "/home/python/.virtualenvs/django_py3_11/lib/python3.5/site-packages/pymysql/connections.py", line 1066, in read
    first_packet = self.connection._read_packet()
  File "/home/python/.virtualenvs/django_py3_11/lib/python3.5/site-packages/pymysql/connections.py", line 683, in _read_packet
    packet.check_error()
  File "/home/python/.virtualenvs/django_py3_11/lib/python3.5/site-packages/pymysql/protocol.py", line 220, in check_error
    err.raise_mysql_exception(self._data)
  File "/home/python/.virtualenvs/django_py3_11/lib/python3.5/site-packages/pymysql/err.py", line 109, in raise_mysql_exception
    raise errorclass(errno, errval)
django.db.utils.InternalError: (1054, "Unknown column 'tb_goods.desc_detail' in 'field list'")
ERROR 2019-01-06 18:25:14,000 basehttp 124 "GET /admin/goods/goods/ HTTP/1.1" 500 239859
INFO 2019-01-06 18:33:25,074 basehttp 124 "GET /admin/goods/goods/ HTTP/1.1" 200 3040
INFO 2019-01-06 18:33:25,270 basehttp 124 "GET /admin/jsi18n/ HTTP/1.1" 200 7682
INFO 2019-01-06 18:33:32,562 basehttp 124 "GET /admin/goods/goods/add/ HTTP/1.1" 200 12276
INFO 2019-01-06 18:33:32,682 basehttp 124 "GET /admin/jsi18n/ HTTP/1.1" 200 7682
INFO 2019-01-06 18:33:33,723 basehttp 124 "GET /static/ckeditor/ckeditor/plugins/icons.png?t=I3I8 HTTP/1.1" 200 12421
INFO 2019-01-06 18:33:55,865 basehttp 124 "GET /static/ckeditor/ckeditor/skins/moono-lisa/dialog.css?t=I3I8 HTTP/1.1" 200 13570
INFO 2019-01-06 18:33:55,933 basehttp 124 "GET /static/ckeditor/ckeditor/plugins/image/dialogs/image.js?t=I3I8 HTTP/1.1" 200 21390
INFO 2019-01-06 18:33:56,247 basehttp 124 "GET /static/ckeditor/ckeditor/skins/moono-lisa/images/refresh.png HTTP/1.1" 200 757
INFO 2019-01-06 18:33:56,265 basehttp 124 "GET /static/ckeditor/ckeditor/skins/moono-lisa/images/close.png HTTP/1.1" 200 615
INFO 2019-01-06 18:33:56,268 basehttp 124 "GET /static/ckeditor/ckeditor/skins/moono-lisa/images/lock.png HTTP/1.1" 200 506
ERROR 2019-01-06 18:34:28,670 exception 135 Internal Server Error: /ckeditor/upload/
Traceback (most recent call last):
  File "/home/python/.virtualenvs/django_py3_11/lib/python3.5/site-packages/django/core/handlers/exception.py", line 41, in inner
    response = get_response(request)
  File "/home/python/.virtualenvs/django_py3_11/lib/python3.5/site-packages/django/core/handlers/base.py", line 187, in _get_response
    response = self.process_exception_by_middleware(e, request)
  File "/home/python/.virtualenvs/django_py3_11/lib/python3.5/site-packages/django/core/handlers/base.py", line 185, in _get_response
    response = wrapped_callback(request, *callback_args, **callback_kwargs)
  File "/home/python/.virtualenvs/django_py3_11/lib/python3.5/site-packages/django/contrib/auth/decorators.py", line 23, in _wrapped_view
    return view_func(request, *args, **kwargs)
  File "/home/python/.virtualenvs/django_py3_11/lib/python3.5/site-packages/django/views/decorators/csrf.py", line 58, in wrapped_view
    return view_func(*args, **kwargs)
  File "/home/python/.virtualenvs/django_py3_11/lib/python3.5/site-packages/django/views/generic/base.py", line 68, in view
    return self.dispatch(request, *args, **kwargs)
  File "/home/python/.virtualenvs/django_py3_11/lib/python3.5/site-packages/django/views/generic/base.py", line 88, in dispatch
    return handler(request, *args, **kwargs)
  File "/home/python/.virtualenvs/django_py3_11/lib/python3.5/site-packages/ckeditor_uploader/views.py", line 95, in post
    if (str(saved_path).split('.'))>1:
TypeError: unorderable types: list() > int()
ERROR 2019-01-06 18:34:28,976 basehttp 124 "POST /ckeditor/upload/ HTTP/1.1" 500 96801
INFO 2019-01-06 18:38:02,714 basehttp 124 "GET /admin/goods/goods/ HTTP/1.1" 200 3040
INFO 2019-01-06 18:38:04,269 basehttp 124 "GET /admin/ HTTP/1.1" 200 2989
INFO 2019-01-06 18:38:06,247 basehttp 124 "GET /admin/goods/goods/ HTTP/1.1" 200 3040
INFO 2019-01-06 18:38:06,396 basehttp 124 "GET /admin/jsi18n/ HTTP/1.1" 200 7682
INFO 2019-01-06 18:38:11,018 basehttp 124 "GET /admin/goods/goods/add/ HTTP/1.1" 200 12276
INFO 2019-01-06 18:38:11,172 basehttp 124 "GET /admin/jsi18n/ HTTP/1.1" 200 7682
ERROR 2019-01-06 18:39:25,079 exception 135 Internal Server Error: /ckeditor/upload/
Traceback (most recent call last):
  File "/home/python/.virtualenvs/django_py3_11/lib/python3.5/site-packages/django/core/handlers/exception.py", line 41, in inner
    response = get_response(request)
  File "/home/python/.virtualenvs/django_py3_11/lib/python3.5/site-packages/django/core/handlers/base.py", line 187, in _get_response
    response = self.process_exception_by_middleware(e, request)
  File "/home/python/.virtualenvs/django_py3_11/lib/python3.5/site-packages/django/core/handlers/base.py", line 185, in _get_response
    response = wrapped_callback(request, *callback_args, **callback_kwargs)
  File "/home/python/.virtualenvs/django_py3_11/lib/python3.5/site-packages/django/contrib/auth/decorators.py", line 23, in _wrapped_view
    return view_func(request, *args, **kwargs)
  File "/home/python/.virtualenvs/django_py3_11/lib/python3.5/site-packages/django/views/decorators/csrf.py", line 58, in wrapped_view
    return view_func(*args, **kwargs)
  File "/home/python/.virtualenvs/django_py3_11/lib/python3.5/site-packages/django/views/generic/base.py", line 68, in view
    return self.dispatch(request, *args, **kwargs)
  File "/home/python/.virtualenvs/django_py3_11/lib/python3.5/site-packages/django/views/generic/base.py", line 88, in dispatch
    return handler(request, *args, **kwargs)
  File "/home/python/.virtualenvs/django_py3_11/lib/python3.5/site-packages/ckeditor_uploader/views.py", line 95, in post
    if (str(saved_path).split('.'))>1:
TypeError: unorderable types: list() > int()
ERROR 2019-01-06 18:39:25,394 basehttp 124 "POST /ckeditor/upload/ HTTP/1.1" 500 96809
INFO 2019-01-06 18:43:21,055 basehttp 124 "GET /admin/goods/goods/add/ HTTP/1.1" 200 12276
INFO 2019-01-06 18:43:21,189 basehttp 124 "GET /admin/jsi18n/ HTTP/1.1" 200 7682
INFO 2019-01-06 18:43:33,758 basehttp 124 "POST /ckeditor/upload/ HTTP/1.1" 200 75
INFO 2019-01-06 18:43:33,785 basehttp 124 "GET /admin/goods/goods/add/2019/01/06/m1_hOesE1g.jpg HTTP/1.1" 301 0
INFO 2019-01-06 18:43:33,862 basehttp 124 "GET /admin/goods/goods/add/2019/01/06/m1_hOesE1g.jpg/ HTTP/1.1" 302 0
INFO 2019-01-06 18:43:33,925 basehttp 124 "GET /admin/goods/goods/add/2019/01/06/m1_hOesE1g.jpg/ HTTP/1.1" 302 0
INFO 2019-01-06 18:43:33,926 basehttp 124 "GET /admin/goods/goods/add/2019/01/06/m1_hOesE1g.jpg/change/ HTTP/1.1" 302 0
INFO 2019-01-06 18:43:34,018 basehttp 124 "GET /admin/goods/goods/add/2019/01/06/m1_hOesE1g.jpg/change/ HTTP/1.1" 302 0
INFO 2019-01-06 18:43:34,091 basehttp 124 "GET /admin/ HTTP/1.1" 200 3167
INFO 2019-01-06 18:43:34,294 basehttp 124 "GET /admin/ HTTP/1.1" 200 3298
INFO 2019-01-06 18:43:34,416 basehttp 124 "GET /static/ckeditor/ckeditor/skins/moono-lisa/images/lock-open.png HTTP/1.1" 200 511
INFO 2019-01-06 18:43:34,432 basehttp 124 "GET /static/ckeditor/ckeditor/plugins/image/images/noimage.png?t=I3I8 HTTP/1.1" 200 1610
INFO 2019-01-06 18:43:37,990 basehttp 124 "GET /admin/goods/goods/add/2019/01/06/m1_hOesE1g.jpg/ HTTP/1.1" 302 0
INFO 2019-01-06 18:43:38,056 basehttp 124 "GET /admin/goods/goods/add/2019/01/06/m1_hOesE1g.jpg/change/ HTTP/1.1" 302 0
INFO 2019-01-06 18:43:38,122 basehttp 124 "GET /admin/ HTTP/1.1" 200 3167
INFO 2019-01-06 18:44:09,642 basehttp 124 "POST /ckeditor/upload/ HTTP/1.1" 200 75
INFO 2019-01-06 18:44:09,658 basehttp 124 "GET /admin/goods/goods/add/2019/01/06/m1_AUlTGPq.jpg HTTP/1.1" 301 0
INFO 2019-01-06 18:44:09,896 basehttp 124 "GET /admin/goods/goods/add/2019/01/06/m1_AUlTGPq.jpg/ HTTP/1.1" 302 0
INFO 2019-01-06 18:44:09,920 basehttp 124 "GET /admin/goods/goods/add/2019/01/06/m1_AUlTGPq.jpg/ HTTP/1.1" 302 0
INFO 2019-01-06 18:44:09,928 basehttp 124 "GET /admin/goods/goods/add/2019/01/06/m1_AUlTGPq.jpg/change/ HTTP/1.1" 302 0
INFO 2019-01-06 18:44:09,976 basehttp 124 "GET /admin/goods/goods/add/2019/01/06/m1_AUlTGPq.jpg/change/ HTTP/1.1" 302 0
INFO 2019-01-06 18:44:09,977 basehttp 124 "GET /admin/ HTTP/1.1" 200 3167
INFO 2019-01-06 18:44:10,021 basehttp 124 "GET /admin/ HTTP/1.1" 200 3167
INFO 2019-01-06 18:44:40,500 basehttp 124 "GET /admin/goods/goods/add/2019/01/06/m1_AUlTGPq.jpg/ HTTP/1.1" 302 0
INFO 2019-01-06 18:44:40,549 basehttp 124 "GET /admin/goods/goods/add/2019/01/06/m1_AUlTGPq.jpg/change/ HTTP/1.1" 302 0
INFO 2019-01-06 18:44:40,612 basehttp 124 "GET /admin/ HTTP/1.1" 200 3167
INFO 2019-01-06 18:45:47,216 basehttp 124 "POST /ckeditor/upload/ HTTP/1.1" 200 75
INFO 2019-01-06 18:45:47,249 basehttp 124 "GET /admin/goods/goods/add/2019/01/06/m1_7l159wJ.jpg HTTP/1.1" 301 0
INFO 2019-01-06 18:45:47,335 basehttp 124 "GET /admin/goods/goods/add/2019/01/06/m1_7l159wJ.jpg/ HTTP/1.1" 302 0
INFO 2019-01-06 18:45:47,388 basehttp 124 "GET /admin/goods/goods/add/2019/01/06/m1_7l159wJ.jpg/ HTTP/1.1" 302 0
INFO 2019-01-06 18:45:47,389 basehttp 124 "GET /admin/goods/goods/add/2019/01/06/m1_7l159wJ.jpg/change/ HTTP/1.1" 302 0
INFO 2019-01-06 18:45:47,501 basehttp 124 "GET /admin/goods/goods/add/2019/01/06/m1_7l159wJ.jpg/change/ HTTP/1.1" 302 0
INFO 2019-01-06 18:45:47,505 basehttp 124 "GET /admin/ HTTP/1.1" 200 3167
INFO 2019-01-06 18:45:50,698 basehttp 124 "GET /admin/goods/goods/add/2019/01/06/m1_7l159wJ.jpg/ HTTP/1.1" 302 0
INFO 2019-01-06 18:45:50,733 basehttp 124 "GET /admin/goods/goods/add/2019/01/06/m1_7l159wJ.jpg/change/ HTTP/1.1" 302 0
INFO 2019-01-06 18:45:50,793 basehttp 124 "GET /admin/ HTTP/1.1" 200 3429
INFO 2019-01-06 18:46:19,559 basehttp 124 "POST /ckeditor/upload/ HTTP/1.1" 200 75
INFO 2019-01-06 18:46:19,588 basehttp 124 "GET /admin/goods/goods/add/2019/01/06/m1_OuwtkAk.jpg HTTP/1.1" 301 0
INFO 2019-01-06 18:46:19,676 basehttp 124 "GET /admin/goods/goods/add/2019/01/06/m1_OuwtkAk.jpg/ HTTP/1.1" 302 0
INFO 2019-01-06 18:46:19,725 basehttp 124 "GET /admin/goods/goods/add/2019/01/06/m1_OuwtkAk.jpg/ HTTP/1.1" 302 0
INFO 2019-01-06 18:46:19,742 basehttp 124 "GET /admin/goods/goods/add/2019/01/06/m1_OuwtkAk.jpg/change/ HTTP/1.1" 302 0
INFO 2019-01-06 18:46:19,854 basehttp 124 "GET /admin/ HTTP/1.1" 200 3167
INFO 2019-01-06 18:46:19,858 basehttp 124 "GET /admin/goods/goods/add/2019/01/06/m1_OuwtkAk.jpg/change/ HTTP/1.1" 302 0
INFO 2019-01-06 18:46:20,138 basehttp 124 "GET /admin/ HTTP/1.1" 200 2989
INFO 2019-01-07 15:40:46,542 basehttp 124 "GET /admin/ HTTP/1.1" 200 7507
WARNING 2019-01-07 15:40:47,413 base 152 Not Found: /favicon.ico
WARNING 2019-01-07 15:40:47,415 basehttp 124 "GET /favicon.ico HTTP/1.1" 404 6852
