INFO 2018-12-27 10:18:02,781 basehttp 124 "GET / HTTP/1.1" 200 1714
WARNING 2018-12-27 10:18:05,540 base 152 Not Found: /favicon.ico
WARNING 2018-12-27 10:18:05,545 basehttp 124 "GET /favicon.ico HTTP/1.1" 404 1967
WARNING 2018-12-27 19:54:37,002 base 152 Not Found: /sms_codes/
WARNING 2018-12-27 19:54:37,046 basehttp 124 "GET /sms_codes/?177775309063 HTTP/1.1" 404 2167
WARNING 2018-12-27 19:56:42,261 base 152 Not Found: /sms_codes/
WARNING 2018-12-27 19:56:42,265 basehttp 124 "GET /sms_codes/?177775309063 HTTP/1.1" 404 2079
WARNING 2018-12-27 19:59:33,236 base 152 Not Found: /sms_codes/177775309063/
WARNING 2018-12-27 19:59:33,239 basehttp 124 "GET /sms_codes/177775309063/ HTTP/1.1" 404 2105
WARNING 2018-12-27 20:00:50,285 base 152 Not Found: /sms_codes/177775309063/
WARNING 2018-12-27 20:00:50,288 basehttp 124 "GET /sms_codes/177775309063/ HTTP/1.1" 404 2105
WARNING 2018-12-27 20:02:10,983 base 152 Not Found: /sms_codes/177775309063/
WARNING 2018-12-27 20:02:10,993 basehttp 124 "GET /sms_codes/177775309063/ HTTP/1.1" 404 2193
WARNING 2018-12-27 20:03:24,685 base 152 Not Found: /sms_codes/177775309063/
WARNING 2018-12-27 20:03:24,687 basehttp 124 "GET /sms_codes/177775309063/ HTTP/1.1" 404 2193
WARNING 2018-12-27 20:03:57,076 base 152 Not Found: /sms_codes/177775309063/
WARNING 2018-12-27 20:03:57,079 basehttp 124 "GET /sms_codes/177775309063/ HTTP/1.1" 404 2086
WARNING 2018-12-27 20:11:56,770 base 152 Not Found: /sms_codes/177775309063/
WARNING 2018-12-27 20:11:56,772 basehttp 124 "GET /sms_codes/177775309063/ HTTP/1.1" 404 2193
WARNING 2018-12-27 20:15:54,874 base 152 Not Found: /sms_codes/177775309063/
WARNING 2018-12-27 20:15:54,892 basehttp 124 "GET /sms_codes/177775309063/ HTTP/1.1" 404 2193
WARNING 2018-12-27 20:16:19,687 base 152 Not Found: /sms_codes/177775309063/
WARNING 2018-12-27 20:16:19,689 basehttp 124 "GET /sms_codes/177775309063/ HTTP/1.1" 404 2192
WARNING 2018-12-27 20:16:48,660 base 152 Not Found: /sms_codes/177775309063/
WARNING 2018-12-27 20:16:48,663 basehttp 124 "GET /sms_codes/177775309063/ HTTP/1.1" 404 2191
WARNING 2018-12-27 20:16:49,900 base 152 Not Found: /sms_codes/177775309063/
WARNING 2018-12-27 20:16:49,900 basehttp 124 "GET /sms_codes/177775309063/ HTTP/1.1" 404 2191
WARNING 2018-12-27 20:17:27,923 base 152 Not Found: /sms_codes/177775309063/
WARNING 2018-12-27 20:17:27,924 basehttp 124 "GET /sms_codes/177775309063/ HTTP/1.1" 404 2192
ERROR 2018-12-27 20:17:57,058 exception 135 Internal Server Error: /sms_codes/17777530903/
Traceback (most recent call last):
  File "/home/python/.virtualenvs/django_py3_11/lib/python3.5/site-packages/rest_framework/views.py", line 480, in dispatch
    response = handler(request, *args, **kwargs)
  File "/home/python/Desktop/meiduo_test1/meiduo_test/meiduo_test/apps/verifications/views.py", line 33, in get
    redis_conn = get_redis_connection("verify_codes")  # StrictRedis 对象
  File "/home/python/.virtualenvs/django_py3_11/lib/python3.5/site-packages/django_redis/__init__.py", line 14, in get_redis_connection
    cache = caches[alias]
  File "/home/python/.virtualenvs/django_py3_11/lib/python3.5/site-packages/django/core/cache/__init__.py", line 77, in __getitem__
    "Could not find config for '%s' in settings.CACHES" % alias
django.core.cache.backends.base.InvalidCacheBackendError: Could not find config for 'verify_codes' in settings.CACHES

During handling of the above exception, another exception occurred:

Traceback (most recent call last):
  File "/home/python/.virtualenvs/django_py3_11/lib/python3.5/site-packages/rest_framework/settings.py", line 183, in import_from_string
    module = import_module(module_path)
  File "/home/python/.virtualenvs/django_py3_11/lib/python3.5/importlib/__init__.py", line 126, in import_module
    return _bootstrap._gcd_import(name[level:], package, level)
  File "<frozen importlib._bootstrap>", line 986, in _gcd_import
  File "<frozen importlib._bootstrap>", line 969, in _find_and_load
  File "<frozen importlib._bootstrap>", line 944, in _find_and_load_unlocked
  File "<frozen importlib._bootstrap>", line 222, in _call_with_frames_removed
  File "<frozen importlib._bootstrap>", line 986, in _gcd_import
  File "<frozen importlib._bootstrap>", line 969, in _find_and_load
  File "<frozen importlib._bootstrap>", line 944, in _find_and_load_unlocked
  File "<frozen importlib._bootstrap>", line 222, in _call_with_frames_removed
  File "<frozen importlib._bootstrap>", line 986, in _gcd_import
  File "<frozen importlib._bootstrap>", line 969, in _find_and_load
  File "<frozen importlib._bootstrap>", line 956, in _find_and_load_unlocked
ImportError: No module named 'meiduo_mall'

During handling of the above exception, another exception occurred:

Traceback (most recent call last):
  File "/home/python/.virtualenvs/django_py3_11/lib/python3.5/site-packages/django/core/handlers/exception.py", line 41, in inner
    response = get_response(request)
  File "/home/python/.virtualenvs/django_py3_11/lib/python3.5/site-packages/django/core/handlers/base.py", line 187, in _get_response
    response = self.process_exception_by_middleware(e, request)
  File "/home/python/.virtualenvs/django_py3_11/lib/python3.5/site-packages/django/core/handlers/base.py", line 185, in _get_response
    response = wrapped_callback(request, *callback_args, **callback_kwargs)
  File "/home/python/.virtualenvs/django_py3_11/lib/python3.5/site-packages/django/views/decorators/csrf.py", line 58, in wrapped_view
    return view_func(*args, **kwargs)
  File "/home/python/.virtualenvs/django_py3_11/lib/python3.5/site-packages/django/views/generic/base.py", line 68, in view
    return self.dispatch(request, *args, **kwargs)
  File "/home/python/.virtualenvs/django_py3_11/lib/python3.5/site-packages/rest_framework/views.py", line 483, in dispatch
    response = self.handle_exception(exc)
  File "/home/python/.virtualenvs/django_py3_11/lib/python3.5/site-packages/rest_framework/views.py", line 437, in handle_exception
    exception_handler = self.get_exception_handler()
  File "/home/python/.virtualenvs/django_py3_11/lib/python3.5/site-packages/rest_framework/views.py", line 288, in get_exception_handler
    return self.settings.EXCEPTION_HANDLER
  File "/home/python/.virtualenvs/django_py3_11/lib/python3.5/site-packages/rest_framework/settings.py", line 227, in __getattr__
    val = perform_import(val, attr)
  File "/home/python/.virtualenvs/django_py3_11/lib/python3.5/site-packages/rest_framework/settings.py", line 170, in perform_import
    return import_from_string(val, setting_name)
  File "/home/python/.virtualenvs/django_py3_11/lib/python3.5/site-packages/rest_framework/settings.py", line 187, in import_from_string
    raise ImportError(msg)
ImportError: Could not import 'meiduo_mall.utils.exceptions.exception_handler' for API setting 'EXCEPTION_HANDLER'. ImportError: No module named 'meiduo_mall'.
ERROR 2018-12-27 20:17:57,749 basehttp 124 "GET /sms_codes/17777530903/ HTTP/1.1" 500 128353
WARNING 2018-12-27 20:18:07,467 base 152 Not Found: /sms_codes/1777530903/
WARNING 2018-12-27 20:18:07,471 basehttp 124 "GET /sms_codes/1777530903/ HTTP/1.1" 404 2186
WARNING 2018-12-27 20:18:16,139 base 152 Not Found: /sms_codes/1777530903/
WARNING 2018-12-27 20:18:16,140 basehttp 124 "GET /sms_codes/1777530903/ HTTP/1.1" 404 2186
ERROR 2018-12-27 20:18:27,268 exception 135 Internal Server Error: /sms_codes/17775309063/
Traceback (most recent call last):
  File "/home/python/.virtualenvs/django_py3_11/lib/python3.5/site-packages/rest_framework/views.py", line 480, in dispatch
    response = handler(request, *args, **kwargs)
  File "/home/python/Desktop/meiduo_test1/meiduo_test/meiduo_test/apps/verifications/views.py", line 33, in get
    redis_conn = get_redis_connection("verify_codes")  # StrictRedis 对象
  File "/home/python/.virtualenvs/django_py3_11/lib/python3.5/site-packages/django_redis/__init__.py", line 14, in get_redis_connection
    cache = caches[alias]
  File "/home/python/.virtualenvs/django_py3_11/lib/python3.5/site-packages/django/core/cache/__init__.py", line 77, in __getitem__
    "Could not find config for '%s' in settings.CACHES" % alias
django.core.cache.backends.base.InvalidCacheBackendError: Could not find config for 'verify_codes' in settings.CACHES

During handling of the above exception, another exception occurred:

Traceback (most recent call last):
  File "/home/python/.virtualenvs/django_py3_11/lib/python3.5/site-packages/rest_framework/settings.py", line 183, in import_from_string
    module = import_module(module_path)
  File "/home/python/.virtualenvs/django_py3_11/lib/python3.5/importlib/__init__.py", line 126, in import_module
    return _bootstrap._gcd_import(name[level:], package, level)
  File "<frozen importlib._bootstrap>", line 986, in _gcd_import
  File "<frozen importlib._bootstrap>", line 969, in _find_and_load
  File "<frozen importlib._bootstrap>", line 944, in _find_and_load_unlocked
  File "<frozen importlib._bootstrap>", line 222, in _call_with_frames_removed
  File "<frozen importlib._bootstrap>", line 986, in _gcd_import
  File "<frozen importlib._bootstrap>", line 969, in _find_and_load
  File "<frozen importlib._bootstrap>", line 944, in _find_and_load_unlocked
  File "<frozen importlib._bootstrap>", line 222, in _call_with_frames_removed
  File "<frozen importlib._bootstrap>", line 986, in _gcd_import
  File "<frozen importlib._bootstrap>", line 969, in _find_and_load
  File "<frozen importlib._bootstrap>", line 956, in _find_and_load_unlocked
ImportError: No module named 'meiduo_mall'

During handling of the above exception, another exception occurred:

Traceback (most recent call last):
  File "/home/python/.virtualenvs/django_py3_11/lib/python3.5/site-packages/django/core/handlers/exception.py", line 41, in inner
    response = get_response(request)
  File "/home/python/.virtualenvs/django_py3_11/lib/python3.5/site-packages/django/core/handlers/base.py", line 187, in _get_response
    response = self.process_exception_by_middleware(e, request)
  File "/home/python/.virtualenvs/django_py3_11/lib/python3.5/site-packages/django/core/handlers/base.py", line 185, in _get_response
    response = wrapped_callback(request, *callback_args, **callback_kwargs)
  File "/home/python/.virtualenvs/django_py3_11/lib/python3.5/site-packages/django/views/decorators/csrf.py", line 58, in wrapped_view
    return view_func(*args, **kwargs)
  File "/home/python/.virtualenvs/django_py3_11/lib/python3.5/site-packages/django/views/generic/base.py", line 68, in view
    return self.dispatch(request, *args, **kwargs)
  File "/home/python/.virtualenvs/django_py3_11/lib/python3.5/site-packages/rest_framework/views.py", line 483, in dispatch
    response = self.handle_exception(exc)
  File "/home/python/.virtualenvs/django_py3_11/lib/python3.5/site-packages/rest_framework/views.py", line 437, in handle_exception
    exception_handler = self.get_exception_handler()
  File "/home/python/.virtualenvs/django_py3_11/lib/python3.5/site-packages/rest_framework/views.py", line 288, in get_exception_handler
    return self.settings.EXCEPTION_HANDLER
  File "/home/python/.virtualenvs/django_py3_11/lib/python3.5/site-packages/rest_framework/settings.py", line 227, in __getattr__
    val = perform_import(val, attr)
  File "/home/python/.virtualenvs/django_py3_11/lib/python3.5/site-packages/rest_framework/settings.py", line 170, in perform_import
    return import_from_string(val, setting_name)
  File "/home/python/.virtualenvs/django_py3_11/lib/python3.5/site-packages/rest_framework/settings.py", line 187, in import_from_string
    raise ImportError(msg)
ImportError: Could not import 'meiduo_mall.utils.exceptions.exception_handler' for API setting 'EXCEPTION_HANDLER'. ImportError: No module named 'meiduo_mall'.
ERROR 2018-12-27 20:18:27,408 basehttp 124 "GET /sms_codes/17775309063/ HTTP/1.1" 500 128353
ERROR 2018-12-27 20:24:19,808 exception 135 Internal Server Error: /sms_codes/17775309063/
Traceback (most recent call last):
  File "/home/python/.virtualenvs/django_py3_11/lib/python3.5/site-packages/rest_framework/views.py", line 480, in dispatch
    response = handler(request, *args, **kwargs)
  File "/home/python/Desktop/meiduo_test1/meiduo_test/meiduo_test/apps/verifications/views.py", line 33, in get
    redis_conn = get_redis_connection('verify_codes')  # StrictRedis 对象
  File "/home/python/.virtualenvs/django_py3_11/lib/python3.5/site-packages/django_redis/__init__.py", line 14, in get_redis_connection
    cache = caches[alias]
  File "/home/python/.virtualenvs/django_py3_11/lib/python3.5/site-packages/django/core/cache/__init__.py", line 77, in __getitem__
    "Could not find config for '%s' in settings.CACHES" % alias
django.core.cache.backends.base.InvalidCacheBackendError: Could not find config for 'verify_codes' in settings.CACHES

During handling of the above exception, another exception occurred:

Traceback (most recent call last):
  File "/home/python/.virtualenvs/django_py3_11/lib/python3.5/site-packages/rest_framework/settings.py", line 183, in import_from_string
    module = import_module(module_path)
  File "/home/python/.virtualenvs/django_py3_11/lib/python3.5/importlib/__init__.py", line 126, in import_module
    return _bootstrap._gcd_import(name[level:], package, level)
  File "<frozen importlib._bootstrap>", line 986, in _gcd_import
  File "<frozen importlib._bootstrap>", line 969, in _find_and_load
  File "<frozen importlib._bootstrap>", line 944, in _find_and_load_unlocked
  File "<frozen importlib._bootstrap>", line 222, in _call_with_frames_removed
  File "<frozen importlib._bootstrap>", line 986, in _gcd_import
  File "<frozen importlib._bootstrap>", line 969, in _find_and_load
  File "<frozen importlib._bootstrap>", line 944, in _find_and_load_unlocked
  File "<frozen importlib._bootstrap>", line 222, in _call_with_frames_removed
  File "<frozen importlib._bootstrap>", line 986, in _gcd_import
  File "<frozen importlib._bootstrap>", line 969, in _find_and_load
  File "<frozen importlib._bootstrap>", line 956, in _find_and_load_unlocked
ImportError: No module named 'meiduo_mall'

During handling of the above exception, another exception occurred:

Traceback (most recent call last):
  File "/home/python/.virtualenvs/django_py3_11/lib/python3.5/site-packages/django/core/handlers/exception.py", line 41, in inner
    response = get_response(request)
  File "/home/python/.virtualenvs/django_py3_11/lib/python3.5/site-packages/django/core/handlers/base.py", line 187, in _get_response
    response = self.process_exception_by_middleware(e, request)
  File "/home/python/.virtualenvs/django_py3_11/lib/python3.5/site-packages/django/core/handlers/base.py", line 185, in _get_response
    response = wrapped_callback(request, *callback_args, **callback_kwargs)
  File "/home/python/.virtualenvs/django_py3_11/lib/python3.5/site-packages/django/views/decorators/csrf.py", line 58, in wrapped_view
    return view_func(*args, **kwargs)
  File "/home/python/.virtualenvs/django_py3_11/lib/python3.5/site-packages/django/views/generic/base.py", line 68, in view
    return self.dispatch(request, *args, **kwargs)
  File "/home/python/.virtualenvs/django_py3_11/lib/python3.5/site-packages/rest_framework/views.py", line 483, in dispatch
    response = self.handle_exception(exc)
  File "/home/python/.virtualenvs/django_py3_11/lib/python3.5/site-packages/rest_framework/views.py", line 437, in handle_exception
    exception_handler = self.get_exception_handler()
  File "/home/python/.virtualenvs/django_py3_11/lib/python3.5/site-packages/rest_framework/views.py", line 288, in get_exception_handler
    return self.settings.EXCEPTION_HANDLER
  File "/home/python/.virtualenvs/django_py3_11/lib/python3.5/site-packages/rest_framework/settings.py", line 227, in __getattr__
    val = perform_import(val, attr)
  File "/home/python/.virtualenvs/django_py3_11/lib/python3.5/site-packages/rest_framework/settings.py", line 170, in perform_import
    return import_from_string(val, setting_name)
  File "/home/python/.virtualenvs/django_py3_11/lib/python3.5/site-packages/rest_framework/settings.py", line 187, in import_from_string
    raise ImportError(msg)
ImportError: Could not import 'meiduo_mall.utils.exceptions.exception_handler' for API setting 'EXCEPTION_HANDLER'. ImportError: No module named 'meiduo_mall'.
ERROR 2018-12-27 20:24:19,937 basehttp 124 "GET /sms_codes/17775309063/ HTTP/1.1" 500 128350
ERROR 2018-12-27 20:26:02,460 exception 135 Internal Server Error: /sms_codes/17775309063/
Traceback (most recent call last):
  File "/home/python/.virtualenvs/django_py3_11/lib/python3.5/site-packages/rest_framework/views.py", line 480, in dispatch
    response = handler(request, *args, **kwargs)
  File "/home/python/Desktop/meiduo_test1/meiduo_test/meiduo_test/apps/verifications/views.py", line 37, in get
    redis_conn = get_redis_connection('verify_codes')  # StrictRedis对象
  File "/home/python/.virtualenvs/django_py3_11/lib/python3.5/site-packages/django_redis/__init__.py", line 14, in get_redis_connection
    cache = caches[alias]
  File "/home/python/.virtualenvs/django_py3_11/lib/python3.5/site-packages/django/core/cache/__init__.py", line 77, in __getitem__
    "Could not find config for '%s' in settings.CACHES" % alias
django.core.cache.backends.base.InvalidCacheBackendError: Could not find config for 'verify_codes' in settings.CACHES

During handling of the above exception, another exception occurred:

Traceback (most recent call last):
  File "/home/python/.virtualenvs/django_py3_11/lib/python3.5/site-packages/rest_framework/settings.py", line 183, in import_from_string
    module = import_module(module_path)
  File "/home/python/.virtualenvs/django_py3_11/lib/python3.5/importlib/__init__.py", line 126, in import_module
    return _bootstrap._gcd_import(name[level:], package, level)
  File "<frozen importlib._bootstrap>", line 986, in _gcd_import
  File "<frozen importlib._bootstrap>", line 969, in _find_and_load
  File "<frozen importlib._bootstrap>", line 944, in _find_and_load_unlocked
  File "<frozen importlib._bootstrap>", line 222, in _call_with_frames_removed
  File "<frozen importlib._bootstrap>", line 986, in _gcd_import
  File "<frozen importlib._bootstrap>", line 969, in _find_and_load
  File "<frozen importlib._bootstrap>", line 944, in _find_and_load_unlocked
  File "<frozen importlib._bootstrap>", line 222, in _call_with_frames_removed
  File "<frozen importlib._bootstrap>", line 986, in _gcd_import
  File "<frozen importlib._bootstrap>", line 969, in _find_and_load
  File "<frozen importlib._bootstrap>", line 956, in _find_and_load_unlocked
ImportError: No module named 'meiduo_mall'

During handling of the above exception, another exception occurred:

Traceback (most recent call last):
  File "/home/python/.virtualenvs/django_py3_11/lib/python3.5/site-packages/django/core/handlers/exception.py", line 41, in inner
    response = get_response(request)
  File "/home/python/.virtualenvs/django_py3_11/lib/python3.5/site-packages/django/core/handlers/base.py", line 187, in _get_response
    response = self.process_exception_by_middleware(e, request)
  File "/home/python/.virtualenvs/django_py3_11/lib/python3.5/site-packages/django/core/handlers/base.py", line 185, in _get_response
    response = wrapped_callback(request, *callback_args, **callback_kwargs)
  File "/home/python/.virtualenvs/django_py3_11/lib/python3.5/site-packages/django/views/decorators/csrf.py", line 58, in wrapped_view
    return view_func(*args, **kwargs)
  File "/home/python/.virtualenvs/django_py3_11/lib/python3.5/site-packages/django/views/generic/base.py", line 68, in view
    return self.dispatch(request, *args, **kwargs)
  File "/home/python/.virtualenvs/django_py3_11/lib/python3.5/site-packages/rest_framework/views.py", line 483, in dispatch
    response = self.handle_exception(exc)
  File "/home/python/.virtualenvs/django_py3_11/lib/python3.5/site-packages/rest_framework/views.py", line 437, in handle_exception
    exception_handler = self.get_exception_handler()
  File "/home/python/.virtualenvs/django_py3_11/lib/python3.5/site-packages/rest_framework/views.py", line 288, in get_exception_handler
    return self.settings.EXCEPTION_HANDLER
  File "/home/python/.virtualenvs/django_py3_11/lib/python3.5/site-packages/rest_framework/settings.py", line 227, in __getattr__
    val = perform_import(val, attr)
  File "/home/python/.virtualenvs/django_py3_11/lib/python3.5/site-packages/rest_framework/settings.py", line 170, in perform_import
    return import_from_string(val, setting_name)
  File "/home/python/.virtualenvs/django_py3_11/lib/python3.5/site-packages/rest_framework/settings.py", line 187, in import_from_string
    raise ImportError(msg)
ImportError: Could not import 'meiduo_mall.utils.exceptions.exception_handler' for API setting 'EXCEPTION_HANDLER'. ImportError: No module named 'meiduo_mall'.
ERROR 2018-12-27 20:26:02,653 basehttp 124 "GET /sms_codes/17775309063/ HTTP/1.1" 500 128404
ERROR 2018-12-27 20:32:00,925 exception 135 Internal Server Error: /sms_codes/17775309063/
Traceback (most recent call last):
  File "/home/python/.virtualenvs/django_py3_11/lib/python3.5/site-packages/rest_framework/views.py", line 480, in dispatch
    response = handler(request, *args, **kwargs)
  File "/home/python/Desktop/meiduo_test1/meiduo_test/meiduo_test/apps/verifications/views.py", line 37, in get
    redis_conn = get_redis_connection('verify_codes')  # StrictRedis对象
  File "/home/python/.virtualenvs/django_py3_11/lib/python3.5/site-packages/django_redis/__init__.py", line 14, in get_redis_connection
    cache = caches[alias]
  File "/home/python/.virtualenvs/django_py3_11/lib/python3.5/site-packages/django/core/cache/__init__.py", line 77, in __getitem__
    "Could not find config for '%s' in settings.CACHES" % alias
django.core.cache.backends.base.InvalidCacheBackendError: Could not find config for 'verify_codes' in settings.CACHES

During handling of the above exception, another exception occurred:

Traceback (most recent call last):
  File "/home/python/.virtualenvs/django_py3_11/lib/python3.5/site-packages/rest_framework/settings.py", line 183, in import_from_string
    module = import_module(module_path)
  File "/home/python/.virtualenvs/django_py3_11/lib/python3.5/importlib/__init__.py", line 126, in import_module
    return _bootstrap._gcd_import(name[level:], package, level)
  File "<frozen importlib._bootstrap>", line 986, in _gcd_import
  File "<frozen importlib._bootstrap>", line 969, in _find_and_load
  File "<frozen importlib._bootstrap>", line 944, in _find_and_load_unlocked
  File "<frozen importlib._bootstrap>", line 222, in _call_with_frames_removed
  File "<frozen importlib._bootstrap>", line 986, in _gcd_import
  File "<frozen importlib._bootstrap>", line 969, in _find_and_load
  File "<frozen importlib._bootstrap>", line 944, in _find_and_load_unlocked
  File "<frozen importlib._bootstrap>", line 222, in _call_with_frames_removed
  File "<frozen importlib._bootstrap>", line 986, in _gcd_import
  File "<frozen importlib._bootstrap>", line 969, in _find_and_load
  File "<frozen importlib._bootstrap>", line 956, in _find_and_load_unlocked
ImportError: No module named 'meiduo_mall'

During handling of the above exception, another exception occurred:

Traceback (most recent call last):
  File "/home/python/.virtualenvs/django_py3_11/lib/python3.5/site-packages/django/core/handlers/exception.py", line 41, in inner
    response = get_response(request)
  File "/home/python/.virtualenvs/django_py3_11/lib/python3.5/site-packages/django/core/handlers/base.py", line 187, in _get_response
    response = self.process_exception_by_middleware(e, request)
  File "/home/python/.virtualenvs/django_py3_11/lib/python3.5/site-packages/django/core/handlers/base.py", line 185, in _get_response
    response = wrapped_callback(request, *callback_args, **callback_kwargs)
  File "/home/python/.virtualenvs/django_py3_11/lib/python3.5/site-packages/django/views/decorators/csrf.py", line 58, in wrapped_view
    return view_func(*args, **kwargs)
  File "/home/python/.virtualenvs/django_py3_11/lib/python3.5/site-packages/django/views/generic/base.py", line 68, in view
    return self.dispatch(request, *args, **kwargs)
  File "/home/python/.virtualenvs/django_py3_11/lib/python3.5/site-packages/rest_framework/views.py", line 483, in dispatch
    response = self.handle_exception(exc)
  File "/home/python/.virtualenvs/django_py3_11/lib/python3.5/site-packages/rest_framework/views.py", line 437, in handle_exception
    exception_handler = self.get_exception_handler()
  File "/home/python/.virtualenvs/django_py3_11/lib/python3.5/site-packages/rest_framework/views.py", line 288, in get_exception_handler
    return self.settings.EXCEPTION_HANDLER
  File "/home/python/.virtualenvs/django_py3_11/lib/python3.5/site-packages/rest_framework/settings.py", line 227, in __getattr__
    val = perform_import(val, attr)
  File "/home/python/.virtualenvs/django_py3_11/lib/python3.5/site-packages/rest_framework/settings.py", line 170, in perform_import
    return import_from_string(val, setting_name)
  File "/home/python/.virtualenvs/django_py3_11/lib/python3.5/site-packages/rest_framework/settings.py", line 187, in import_from_string
    raise ImportError(msg)
ImportError: Could not import 'meiduo_mall.utils.exceptions.exception_handler' for API setting 'EXCEPTION_HANDLER'. ImportError: No module named 'meiduo_mall'.
ERROR 2018-12-27 20:32:01,130 basehttp 124 "GET /sms_codes/17775309063/ HTTP/1.1" 500 128404
ERROR 2018-12-27 20:34:31,478 exception 135 Internal Server Error: /sms_codes/17775309063/
Traceback (most recent call last):
  File "/home/python/.virtualenvs/django_py3_11/lib/python3.5/site-packages/django/core/handlers/exception.py", line 41, in inner
    response = get_response(request)
  File "/home/python/.virtualenvs/django_py3_11/lib/python3.5/site-packages/django/core/handlers/base.py", line 187, in _get_response
    response = self.process_exception_by_middleware(e, request)
  File "/home/python/.virtualenvs/django_py3_11/lib/python3.5/site-packages/django/core/handlers/base.py", line 185, in _get_response
    response = wrapped_callback(request, *callback_args, **callback_kwargs)
  File "/home/python/.virtualenvs/django_py3_11/lib/python3.5/site-packages/django/views/decorators/csrf.py", line 58, in wrapped_view
    return view_func(*args, **kwargs)
  File "/home/python/.virtualenvs/django_py3_11/lib/python3.5/site-packages/django/views/generic/base.py", line 68, in view
    return self.dispatch(request, *args, **kwargs)
  File "/home/python/.virtualenvs/django_py3_11/lib/python3.5/site-packages/rest_framework/views.py", line 483, in dispatch
    response = self.handle_exception(exc)
  File "/home/python/.virtualenvs/django_py3_11/lib/python3.5/site-packages/rest_framework/views.py", line 443, in handle_exception
    self.raise_uncaught_exception(exc)
  File "/home/python/.virtualenvs/django_py3_11/lib/python3.5/site-packages/rest_framework/views.py", line 480, in dispatch
    response = handler(request, *args, **kwargs)
  File "/home/python/Desktop/meiduo_test1/meiduo_test/meiduo_test/apps/verifications/views.py", line 37, in get
    redis_conn = get_redis_connection('verify_codes')  # StrictRedis对象
  File "/home/python/.virtualenvs/django_py3_11/lib/python3.5/site-packages/django_redis/__init__.py", line 14, in get_redis_connection
    cache = caches[alias]
  File "/home/python/.virtualenvs/django_py3_11/lib/python3.5/site-packages/django/core/cache/__init__.py", line 77, in __getitem__
    "Could not find config for '%s' in settings.CACHES" % alias
django.core.cache.backends.base.InvalidCacheBackendError: Could not find config for 'verify_codes' in settings.CACHES
ERROR 2018-12-27 20:34:31,539 basehttp 124 "GET /sms_codes/17775309063/ HTTP/1.1" 500 17865
ERROR 2018-12-27 20:41:49,258 exceptions 28 [<verifications.views.SMSCodeView object at 0x7f1a3360bf98>] <class 'redis.exceptions.ConnectionError'>
ERROR 2018-12-27 20:41:49,261 basehttp 124 "GET /sms_codes/17775309063/ HTTP/1.1" 507 35
ERROR 2018-12-27 20:44:36,248 exceptions 28 [<verifications.views.SMSCodeView object at 0x7feefc587c50>] <class 'redis.exceptions.ConnectionError'>
ERROR 2018-12-27 20:44:51,348 basehttp 124 "GET /sms_codes/17775309063/ HTTP/1.1" 507 35
ERROR 2018-12-27 20:47:12,016 exceptions 28 [<verifications.views.SMSCodeView object at 0x7f5c9e713198>] <class 'redis.exceptions.ConnectionError'>
ERROR 2018-12-27 20:47:12,020 basehttp 124 "GET /sms_codes/17775309063/ HTTP/1.1" 507 35
ERROR 2018-12-27 20:52:39,658 exceptions 28 [<verifications.views.SMSCodeView object at 0x7f7d6c446f98>] <class 'redis.exceptions.ConnectionError'>
ERROR 2018-12-27 20:53:30,193 basehttp 124 "GET /sms_codes/17775309063/ HTTP/1.1" 507 35
ERROR 2018-12-27 20:55:31,169 exceptions 28 [<verifications.views.SMSCodeView object at 0x7f35f7902f98>] <class 'redis.exceptions.ConnectionError'>
ERROR 2018-12-27 20:55:31,170 basehttp 124 "GET /sms_codes/17775309063/ HTTP/1.1" 507 35
INFO 2018-12-27 20:58:33,709 basehttp 124 "GET /sms_codes/17775309063/ HTTP/1.1" 200 16
INFO 2018-12-27 21:24:47,940 basehttp 124 "GET /sms_codes/17775309063/ HTTP/1.1" 200 16
WARNING 2018-12-27 21:24:50,143 basehttp 124 "GET /sms_codes/17775309063/ HTTP/1.1" 400 38
WARNING 2018-12-27 21:45:48,479 base 152 Not Found: /register.html
WARNING 2018-12-27 21:45:48,632 basehttp 124 "GET /register.html HTTP/1.1" 404 2162
INFO 2018-12-27 21:47:29,970 basehttp 124 "GET /sms_codes/17775309063/ HTTP/1.1" 200 16
WARNING 2018-12-27 21:54:00,909 base 152 Not Found: /mobiles/17775309063/count/
WARNING 2018-12-27 21:54:00,910 basehttp 124 "GET /mobiles/17775309063/count/ HTTP/1.1" 404 2201
WARNING 2018-12-27 21:54:01,043 base 152 Not Found: /mobiles/17775309063/count/
WARNING 2018-12-27 21:54:01,048 basehttp 124 "GET /mobiles/17775309063/count/ HTTP/1.1" 404 2201
ERROR 2018-12-27 21:54:01,086 exceptions 28 [<verifications.views.SMSCodeView object at 0x7fa00d542588>] <class 'redis.exceptions.ConnectionError'>
ERROR 2018-12-27 21:54:01,087 basehttp 124 "GET /sms_codes/17775309063/ HTTP/1.1" 507 35
WARNING 2018-12-27 21:56:51,980 base 152 Not Found: /mobiles/17775309063/count/
WARNING 2018-12-27 21:56:51,984 basehttp 124 "GET /mobiles/17775309063/count/ HTTP/1.1" 404 2201
WARNING 2018-12-27 21:56:59,408 base 152 Not Found: /mobiles/17775309063/count/
WARNING 2018-12-27 21:56:59,410 basehttp 124 "GET /mobiles/17775309063/count/ HTTP/1.1" 404 2201
WARNING 2018-12-27 21:56:59,420 base 152 Not Found: /mobiles/17775309063/count/
WARNING 2018-12-27 21:56:59,421 basehttp 124 "GET /mobiles/17775309063/count/ HTTP/1.1" 404 2201
ERROR 2018-12-27 21:56:59,430 exceptions 28 [<verifications.views.SMSCodeView object at 0x7fa00d554828>] <class 'redis.exceptions.ConnectionError'>
ERROR 2018-12-27 21:56:59,431 basehttp 124 "GET /sms_codes/17775309063/ HTTP/1.1" 507 35
WARNING 2018-12-27 21:58:57,087 base 152 Not Found: /mobiles/17775309063/count/
WARNING 2018-12-27 21:58:57,091 base 152 Not Found: /mobiles/17775309063/count/
WARNING 2018-12-27 21:58:57,096 basehttp 124 "GET /mobiles/17775309063/count/ HTTP/1.1" 404 2201
WARNING 2018-12-27 21:58:57,097 basehttp 124 "GET /mobiles/17775309063/count/ HTTP/1.1" 404 2201
ERROR 2018-12-27 21:58:57,141 exceptions 28 [<verifications.views.SMSCodeView object at 0x7ff324469f28>] <class 'redis.exceptions.ConnectionError'>
ERROR 2018-12-27 21:58:57,142 basehttp 124 "GET /sms_codes/17775309063/ HTTP/1.1" 507 35
ERROR 2018-12-27 22:01:35,295 exceptions 28 [<verifications.views.SMSCodeView object at 0x7f53fca66f60>] <class 'redis.exceptions.ConnectionError'>
ERROR 2018-12-27 22:01:35,296 basehttp 124 "GET /sms_codes/17775309063/ HTTP/1.1" 507 35
ERROR 2018-12-27 22:02:07,284 exceptions 28 [<verifications.views.SMSCodeView object at 0x7f389ac7cf98>] <class 'redis.exceptions.ConnectionError'>
ERROR 2018-12-27 22:02:07,285 basehttp 124 "GET /sms_codes/17775309063/ HTTP/1.1" 507 35
INFO 2018-12-27 22:02:53,033 basehttp 124 "GET /sms_codes/17775309063/ HTTP/1.1" 200 16
ERROR 2018-12-27 22:03:51,357 exceptions 28 [<verifications.views.SMSCodeView object at 0x7f9fc9737390>] <class 'redis.exceptions.ConnectionError'>
ERROR 2018-12-27 22:03:51,358 basehttp 124 "GET /sms_codes/17775309063/ HTTP/1.1" 507 35
ERROR 2018-12-27 22:03:55,826 exceptions 28 [<verifications.views.SMSCodeView object at 0x7f9fc973e358>] <class 'redis.exceptions.ConnectionError'>
ERROR 2018-12-27 22:03:55,828 basehttp 124 "GET /sms_codes/17775309063/ HTTP/1.1" 507 35
ERROR 2018-12-27 22:03:56,836 exceptions 28 [<verifications.views.SMSCodeView object at 0x7f9fc9737048>] <class 'redis.exceptions.ConnectionError'>
ERROR 2018-12-27 22:03:56,837 basehttp 124 "GET /sms_codes/17775309063/ HTTP/1.1" 507 35
ERROR 2018-12-27 22:03:57,606 exceptions 28 [<verifications.views.SMSCodeView object at 0x7f9fc973ef28>] <class 'redis.exceptions.ConnectionError'>
ERROR 2018-12-27 22:03:57,608 basehttp 124 "GET /sms_codes/17775309063/ HTTP/1.1" 507 35
WARNING 2018-12-27 22:04:52,393 base 152 Not Found: /mobiles/17775309063/count/
WARNING 2018-12-27 22:04:52,395 basehttp 124 "GET /mobiles/17775309063/count/ HTTP/1.1" 404 2201
ERROR 2018-12-27 22:04:52,496 exceptions 28 [<verifications.views.SMSCodeView object at 0x7f9fc973e710>] <class 'redis.exceptions.ConnectionError'>
ERROR 2018-12-27 22:04:52,497 basehttp 124 "GET /sms_codes/17775309063/ HTTP/1.1" 507 35
WARNING 2018-12-27 22:04:52,512 base 152 Not Found: /mobiles/17775309063/count/
WARNING 2018-12-27 22:04:52,513 basehttp 124 "GET /mobiles/17775309063/count/ HTTP/1.1" 404 2201
ERROR 2018-12-27 22:07:17,056 exception 80 Invalid HTTP_HOST header: 'api.meiduo.site:8000'. You may need to add 'api.meiduo.site' to ALLOWED_HOSTS.
ERROR 2018-12-27 22:07:17,073 exception 80 Invalid HTTP_HOST header: 'api.meiduo.site:8000'. You may need to add 'api.meiduo.site' to ALLOWED_HOSTS.
ERROR 2018-12-27 22:07:17,091 exception 80 Invalid HTTP_HOST header: 'api.meiduo.site:8000'. You may need to add 'api.meiduo.site' to ALLOWED_HOSTS.
WARNING 2018-12-27 22:07:17,467 basehttp 124 "GET /mobiles/17775309063/count/ HTTP/1.1" 400 70842
WARNING 2018-12-27 22:07:17,471 basehttp 124 "GET /sms_codes/17775309063/ HTTP/1.1" 400 70798
WARNING 2018-12-27 22:07:17,517 basehttp 124 "GET /mobiles/17775309063/count/ HTTP/1.1" 400 70842
ERROR 2018-12-27 22:15:27,967 exception 80 Invalid HTTP_HOST header: 'api.meiduo.site:8000'. You may need to add 'api.meiduo.site' to ALLOWED_HOSTS.
ERROR 2018-12-27 22:15:28,034 exception 80 Invalid HTTP_HOST header: 'api.meiduo.site:8000'. You may need to add 'api.meiduo.site' to ALLOWED_HOSTS.
ERROR 2018-12-27 22:15:28,059 exception 80 Invalid HTTP_HOST header: 'api.meiduo.site:8000'. You may need to add 'api.meiduo.site' to ALLOWED_HOSTS.
WARNING 2018-12-27 22:15:28,283 basehttp 124 "GET /mobiles/17775309063/count/ HTTP/1.1" 400 70842
WARNING 2018-12-27 22:15:28,298 basehttp 124 "GET /sms_codes/17775309063/ HTTP/1.1" 400 70798
WARNING 2018-12-27 22:15:28,299 basehttp 124 "GET /mobiles/17775309063/count/ HTTP/1.1" 400 70842
ERROR 2018-12-27 22:21:04,824 exception 80 Invalid HTTP_HOST header: 'api.meiduo.site:8000'. You may need to add 'api.meiduo.site' to ALLOWED_HOSTS.
WARNING 2018-12-27 22:21:04,996 basehttp 124 "GET /sms_codes/17775309063/ HTTP/1.1" 400 70798
ERROR 2018-12-27 22:23:32,829 exceptions 28 [<verifications.views.SMSCodeView object at 0x7f95ce4b3e48>] <class 'redis.exceptions.ConnectionError'>
ERROR 2018-12-27 22:23:32,831 basehttp 124 "GET /sms_codes/17775309063/ HTTP/1.1" 507 35
ERROR 2018-12-27 22:24:50,477 exception 80 Invalid HTTP_HOST header: 'api.meiduo.site:8000'. You may need to add 'api.meiduo.site' to ALLOWED_HOSTS.
WARNING 2018-12-27 22:24:50,698 basehttp 124 "GET /sms_codes/17775309063/ HTTP/1.1" 400 70798
ERROR 2018-12-28 14:17:36,743 exception 80 Invalid HTTP_HOST header: 'api.meiduo.site:8000'. You may need to add 'api.meiduo.site' to ALLOWED_HOSTS.
WARNING 2018-12-28 14:17:37,107 basehttp 124 "GET /sms_codes/17775309063/ HTTP/1.1" 400 71144
ERROR 2018-12-28 14:21:01,358 exceptions 28 [<verifications.views.SMSCodeView object at 0x7f9f744e1eb8>] <class 'redis.exceptions.ConnectionError'>
ERROR 2018-12-28 14:21:01,386 basehttp 124 "GET /sms_codes/17775309063/ HTTP/1.1" 507 35
ERROR 2018-12-28 14:21:23,027 exceptions 28 [<verifications.views.SMSCodeView object at 0x7f9f744e4c50>] <class 'redis.exceptions.ConnectionError'>
ERROR 2018-12-28 14:21:23,029 basehttp 124 "GET /sms_codes/17775309063/ HTTP/1.1" 507 35
ERROR 2018-12-28 14:21:24,278 exceptions 28 [<verifications.views.SMSCodeView object at 0x7f9f744e1128>] <class 'redis.exceptions.ConnectionError'>
ERROR 2018-12-28 14:21:24,279 basehttp 124 "GET /sms_codes/17775309063/ HTTP/1.1" 507 35
ERROR 2018-12-28 14:21:25,165 exceptions 28 [<verifications.views.SMSCodeView object at 0x7f9f744ee470>] <class 'redis.exceptions.ConnectionError'>
ERROR 2018-12-28 14:21:25,200 basehttp 124 "GET /sms_codes/17775309063/ HTTP/1.1" 507 35
INFO 2018-12-28 14:21:40,987 basehttp 124 "GET /sms_codes/17775309063/ HTTP/1.1" 200 16
INFO 2018-12-28 14:23:00,764 basehttp 124 "GET /sms_codes/17775309063/ HTTP/1.1" 200 16
WARNING 2018-12-28 14:23:02,367 basehttp 124 "GET /sms_codes/17775309063/ HTTP/1.1" 400 38
ERROR 2018-12-28 14:23:24,972 exception 80 Invalid HTTP_HOST header: 'api.meiduo.site:8000'. You may need to add 'api.meiduo.site' to ALLOWED_HOSTS.
WARNING 2018-12-28 14:23:25,213 basehttp 124 "GET /sms_codes/17775309063/ HTTP/1.1" 400 70853
INFO 2018-12-28 16:05:56,773 basehttp 124 "GET /mobiles/17775309063/count/ HTTP/1.1" 200 34
INFO 2018-12-28 16:05:56,784 basehttp 124 "GET /mobiles/17775309063/count/ HTTP/1.1" 200 34
ERROR 2018-12-28 16:05:57,477 exception 135 Internal Server Error: /sms_codes/17775309063/
Traceback (most recent call last):
  File "/home/python/.virtualenvs/django_py3_11/lib/python3.5/site-packages/celery/local.py", line 319, in _get_current_object
    return object.__getattribute__(self, '__thing')
AttributeError: 'PromiseProxy' object has no attribute '__thing'

During handling of the above exception, another exception occurred:

Traceback (most recent call last):
  File "/home/python/.virtualenvs/django_py3_11/lib/python3.5/site-packages/kombu/utils/objects.py", line 42, in __get__
    return obj.__dict__[self.__name__]
KeyError: 'data'

During handling of the above exception, another exception occurred:

Traceback (most recent call last):
  File "/home/python/.virtualenvs/django_py3_11/lib/python3.5/site-packages/celery/loaders/base.py", line 144, in _smart_import
    return imp(path)
  File "/home/python/.virtualenvs/django_py3_11/lib/python3.5/site-packages/celery/loaders/base.py", line 104, in import_from_cwd
    package=package,
  File "/home/python/.virtualenvs/django_py3_11/lib/python3.5/site-packages/celery/utils/imports.py", line 104, in import_from_cwd
    return imp(module, package=package)
  File "/home/python/.virtualenvs/django_py3_11/lib/python3.5/site-packages/celery/loaders/base.py", line 98, in import_module
    return importlib.import_module(module, package=package)
  File "/home/python/.virtualenvs/django_py3_11/lib/python3.5/importlib/__init__.py", line 126, in import_module
    return _bootstrap._gcd_import(name[level:], package, level)
  File "<frozen importlib._bootstrap>", line 986, in _gcd_import
  File "<frozen importlib._bootstrap>", line 969, in _find_and_load
  File "<frozen importlib._bootstrap>", line 956, in _find_and_load_unlocked
ImportError: No module named 'celery_tasks_config'

During handling of the above exception, another exception occurred:

Traceback (most recent call last):
  File "/home/python/.virtualenvs/django_py3_11/lib/python3.5/site-packages/django/core/handlers/exception.py", line 41, in inner
    response = get_response(request)
  File "/home/python/.virtualenvs/django_py3_11/lib/python3.5/site-packages/django/core/handlers/base.py", line 187, in _get_response
    response = self.process_exception_by_middleware(e, request)
  File "/home/python/.virtualenvs/django_py3_11/lib/python3.5/site-packages/django/core/handlers/base.py", line 185, in _get_response
    response = wrapped_callback(request, *callback_args, **callback_kwargs)
  File "/home/python/.virtualenvs/django_py3_11/lib/python3.5/site-packages/django/views/decorators/csrf.py", line 58, in wrapped_view
    return view_func(*args, **kwargs)
  File "/home/python/.virtualenvs/django_py3_11/lib/python3.5/site-packages/django/views/generic/base.py", line 68, in view
    return self.dispatch(request, *args, **kwargs)
  File "/home/python/.virtualenvs/django_py3_11/lib/python3.5/site-packages/rest_framework/views.py", line 483, in dispatch
    response = self.handle_exception(exc)
  File "/home/python/.virtualenvs/django_py3_11/lib/python3.5/site-packages/rest_framework/views.py", line 443, in handle_exception
    self.raise_uncaught_exception(exc)
  File "/home/python/.virtualenvs/django_py3_11/lib/python3.5/site-packages/rest_framework/views.py", line 480, in dispatch
    response = handler(request, *args, **kwargs)
  File "/home/python/Desktop/meiduo_test1/meiduo_test/meiduo_test/apps/verifications/views.py", line 63, in get
    send_sms_code.delay(mobile, sms_code, expires)
  File "/home/python/.virtualenvs/django_py3_11/lib/python3.5/site-packages/celery/local.py", line 148, in __getattr__
    return getattr(self._get_current_object(), name)
  File "/home/python/.virtualenvs/django_py3_11/lib/python3.5/site-packages/celery/local.py", line 321, in _get_current_object
    return self.__evaluate__()
  File "/home/python/.virtualenvs/django_py3_11/lib/python3.5/site-packages/celery/local.py", line 351, in __evaluate__
    thing = Proxy._get_current_object(self)
  File "/home/python/.virtualenvs/django_py3_11/lib/python3.5/site-packages/celery/local.py", line 111, in _get_current_object
    return loc(*self.__args, **self.__kwargs)
  File "/home/python/.virtualenvs/django_py3_11/lib/python3.5/site-packages/celery/app/base.py", line 453, in _task_from_fun
    task.bind(self)  # connects task to this app
  File "/home/python/.virtualenvs/django_py3_11/lib/python3.5/site-packages/celery/app/task.py", line 319, in bind
    setattr(cls, attr_name, conf[config_name])
  File "/home/python/.virtualenvs/django_py3_11/lib/python3.5/site-packages/celery/utils/collections.py", line 432, in __getitem__
    return getitem(k)
  File "/home/python/.virtualenvs/django_py3_11/lib/python3.5/site-packages/celery/utils/collections.py", line 281, in __getitem__
    return mapping[_key]
  File "/home/python/.virtualenvs/django_py3_11/lib/python3.5/collections/__init__.py", line 982, in __getitem__
    if key in self.data:
  File "/home/python/.virtualenvs/django_py3_11/lib/python3.5/site-packages/kombu/utils/objects.py", line 44, in __get__
    value = obj.__dict__[self.__name__] = self.__get(obj)
  File "/home/python/.virtualenvs/django_py3_11/lib/python3.5/site-packages/celery/app/base.py", line 139, in data
    return self.callback()
  File "/home/python/.virtualenvs/django_py3_11/lib/python3.5/site-packages/celery/app/base.py", line 902, in _finalize_pending_conf
    conf = self._conf = self._load_config()
  File "/home/python/.virtualenvs/django_py3_11/lib/python3.5/site-packages/celery/app/base.py", line 912, in _load_config
    self.loader.config_from_object(self._config_source)
  File "/home/python/.virtualenvs/django_py3_11/lib/python3.5/site-packages/celery/loaders/base.py", line 126, in config_from_object
    obj = self._smart_import(obj, imp=self.import_from_cwd)
  File "/home/python/.virtualenvs/django_py3_11/lib/python3.5/site-packages/celery/loaders/base.py", line 147, in _smart_import
    return symbol_by_name(path, imp=imp)
  File "/home/python/.virtualenvs/django_py3_11/lib/python3.5/site-packages/kombu/utils/imports.py", line 56, in symbol_by_name
    module = imp(module_name, package=package, **kwargs)
  File "/home/python/.virtualenvs/django_py3_11/lib/python3.5/site-packages/celery/loaders/base.py", line 104, in import_from_cwd
    package=package,
  File "/home/python/.virtualenvs/django_py3_11/lib/python3.5/site-packages/celery/utils/imports.py", line 104, in import_from_cwd
    return imp(module, package=package)
  File "/home/python/.virtualenvs/django_py3_11/lib/python3.5/site-packages/celery/loaders/base.py", line 98, in import_module
    return importlib.import_module(module, package=package)
  File "/home/python/.virtualenvs/django_py3_11/lib/python3.5/importlib/__init__.py", line 126, in import_module
    return _bootstrap._gcd_import(name[level:], package, level)
  File "<frozen importlib._bootstrap>", line 986, in _gcd_import
  File "<frozen importlib._bootstrap>", line 969, in _find_and_load
  File "<frozen importlib._bootstrap>", line 956, in _find_and_load_unlocked
ImportError: No module named 'celery_tasks_config'
ERROR 2018-12-28 16:05:57,752 basehttp 124 "GET /sms_codes/17775309063/ HTTP/1.1" 500 22951
INFO 2018-12-28 16:14:01,185 basehttp 124 "GET /mobiles/17775309063/count/ HTTP/1.1" 200 34
INFO 2018-12-28 16:14:02,531 basehttp 124 "GET /sms_codes/17775309063/ HTTP/1.1" 200 16
INFO 2018-12-28 16:15:43,574 basehttp 124 "GET /mobiles/17775309063/count/ HTTP/1.1" 200 34
INFO 2018-12-28 16:15:43,683 basehttp 124 "GET /sms_codes/17775309063/ HTTP/1.1" 200 16
WARNING 2018-12-28 16:16:26,318 basehttp 124 "GET /sms_codes/17775309063/ HTTP/1.1" 400 38
INFO 2018-12-28 16:16:26,463 basehttp 124 "GET /mobiles/17775309063/count/ HTTP/1.1" 200 34
INFO 2018-12-28 16:16:26,466 basehttp 124 "GET /mobiles/17775309063/count/ HTTP/1.1" 200 34
INFO 2018-12-28 16:25:19,742 basehttp 124 "GET /sms_codes/17775309063/ HTTP/1.1" 200 16
